Workbook

Sheet Overview
A1: NVIDIA Corporation (NASDAQ: NVDA) — Financial Model & Valuation
A2: Built on Q2 FY2027 actuals (reported 26-Aug-2026) and company guidance for Q3 and FY2028. Data Center was 92.5% of Q2 revenue. Note on presentation: Data Center and Edge Computing are market-platform revenue disclosures introduced with Q1 FY2027, not GAAP reportable segments — those remain Compute & Networking and Graphics.
A4: SNAPSHOT — all price-derived figures computed, not pasted
A6: Live price ($, close 27-Aug-2026) | B6: 227.98 | C6: +8.74% on the print; verified two sources
A7: Shares outstanding (m) | B7: 24150 | C7: per data provider post-buyback
A8: Market capitalisation ($bn) | B8: =B6*B7/1000
A9: Diluted shares, Q2 FY2027 actual (m) | B9: 24285 | C9: H1 weighted average 24,338
A10: TTM revenue ($bn) | B10: 302.97 | C10: ties to Q3FY26+Q4FY26+Q1FY27+Q2FY27
A11: TTM operating income ($bn) | B11: 197.58
A12: TTM pretax income ($bn) | B12: 229.74 | C12: $32.2bn sits BELOW the operating line
A13: TTM net income ($bn) | B13: 192.88 | C13: reported, includes investment gains
A14: TTM reported EPS ($) | B14: 7.91
A15: TTM core EPS ($, operating only, taxed 16.05%) | B15: =B11*(1-0.1605)/B9*1000
A16: Trailing P/E on reported EPS (x) | B16: =B6/B14
A17: Trailing P/E on core EPS (x) | B17: =B6/B15
A18: Book value per share ($) | B18: 9.5
A19: Price / book (x) | B19: =B6/B18
A20: TTM free cash flow ($bn) | B20: 127.01 | C20: ROSE from $119.08bn; the MARGIN fell 46.97% -> 41.92%
A21: Return on invested capital (%) | B21: 92.03
A22: Beta, 5-year (%) | B22: 2.21 | C22: model uses a forward beta of 1.50 — see DCF sheet
A23: Dividend per share ($/yr) | B23: 1
A24: Dividend yield (%) | B24: =B23/B6*100
A25: US 10-yr Treasury (%, 26-Aug-2026) | B25: 4.66 | C25: Fed H.15; rating hurdle anchor
A27: NET CASH — treasury liquidity only
A28: Cash and cash equivalents ($m) | B28: 22443
A29: Marketable debt securities ($m) | B29: 34143
A30: Less: short-term debt ($m) | B30: -1000
A31: Less: long-term debt ($m) | B31: -32366
A32: NET CASH ($m) | B32: =SUM(B28:B31)
A33: Marketable EQUITY securities of $42,783m are deliberately EXCLUDED. They are stakes in AI counterparties, several of which Nvidia is helping to finance; they are marked through the income statement and are correlated with the operating business rather than diversifying it. Counting them as treasury cash while arguing elsewhere that they are not diversification would be incoherent, and would add $1.77 a share to fair value. Data providers that report roughly $99bn of 'cash' are including them.
A35: Q2 FISCAL 2027 RESULTS (quarter ended 26-Jul-2026, reported 26-Aug-2026)
A36: Metric | B36: Q2 FY27 | C36: Q1 FY27 | D36: Q2 FY26 | E36: Y/Y
A37: Revenue ($m) | B37: 96221 | C37: 81615 | D37: 46743 | E37: +106%
A38: Data Center ($m) | B38: 89000 | C38: 75200 | D38: 41000 | E38: +117%
A39: Edge Computing ($m) | B39: 7200 | C39: 6400 | D39: 5700 | E39: +26%
A40: GAAP gross margin (%) | B40: 75 | C40: 74.9 | D40: 72.4 | E40: +2.6 pts
A41: GAAP operating expenses ($m) | B41: 8408 | C41: 7621 | D41: 5413 | E41: +55%
A42: GAAP operating income ($m) | B42: 63734 | C42: 53536 | D42: 28440 | E42: +124%
A43: Other income, net ($m) | B43: 7773 | C43: 16367 | D43: 2766
A44: of which equity-securities gains ($m) | B44: 7771 | C44: 15936 | D44: 2247 | E44: non-operating
...

Sheet Income Statement
A1: NVIDIA — Income Statement & Forecast ($ millions, fiscal years ending late January)
A2: FY2022–FY2026 reported. FY2027E = Q1 actual + Q2 actual + Q3 company guidance + our Q4 estimate. FY2028E–FY2031E are our forecasts.
A4: ($m) | B4: FY2022A | C4: FY2023A | D4: FY2024A | E4: FY2025A | F4: FY2026A | G4: FY2027E | H4: FY2028E | I4: FY2029E | J4: FY2030E | K4: FY2031E
A5: Revenue | B5: 26914 | C5: 26974 | D5: 60922 | E5: 130497 | F5: 215900 | G5: 403600 | H5: 573112 | I5: 710659 | J5: 824364 | K5: 906801
A6: growth (%) | C6: =C5/B5-1 | D6: =D5/C5-1 | E6: =E5/D5-1 | F6: =F5/E5-1 | G6: =G5/F5-1 | H6: =H5/G5-1 | I6: =I5/H5-1 | J6: =J5/I5-1 | K6: =K5/J5-1
A7: Gross margin (%) | B7: 0.6483 | C7: 0.5693 | D7: 0.7272 | E7: 0.75 | F7: 0.748 | G7: 0.7427 | H7: 0.735 | I7: 0.73 | J7: 0.725 | K7: 0.72
A8: Gross profit | B8: =B5*B7 | C8: =C5*C7 | D8: =D5*D7 | E8: =E5*E7 | F8: =F5*F7 | G8: =G5*G7 | H8: =H5*H7 | I8: =I5*I7 | ... K8: =K5*K7
A9: opex as % of revenue | B9: 0.2763 | C9: 0.4127 | D9: 0.1863 | E9: 0.125 | F9: 0.1029 | G9: 0.087 | H9: 0.092 | I9: 0.098 | J9: 0.104 | K9: 0.11
A10: Operating expenses | B10: =B5*B9 | C10: =C5*C9 | D10: =D5*D9 | E10: =E5*E9 | F10: =F5*F9 | G10: =G5*G9 | H10: =H5*H9 | I10: =I5*I9 | ... K10: =K5*K9
A11: Operating income | B11: =B8-B10 | C11: =C8-C10 | D11: =D8-D10 | E11: =E8-E10 | F11: =F8-F10 | G11: =G8-G10 | H11: =H8-H10 | I11: =I8-I10 | ... K11: =K8-K10
A12: operating margin (%) | B12: =B11/B5 | C12: =C11/C5 | D12: =D11/D5 | E12: =E11/E5 | F12: =F11/F5 | G12: =G11/G5 | H12: =H11/H5 | I12: =I11/I5 | ... K12: =K11/K5
A13: Net income (core, ex investment gains) | B13: =B11*(1-B14) | C13: =C11*(1-C14) | D13: =D11*(1-D14) | E13: =E11*(1-E14) | F13: =F11*(1-F14) | G13: =G11*(1-G14) | H13: =H11*(1-H14) | I13: =I11*(1-I14) | ... K13: =K11*(1-K14)
A14: tax rate (%) | B14: 0.1605 | C14: 0.1605 | D14: 0.1605 | E14: 0.1605 | F14: 0.1605 | G14: 0.1605 | H14: 0.1605 | I14: 0.1605 | J14: 0.1605 | K14: 0.1605
A15: Diluted shares (m) | B15: 25350 | C15: 24940 | D15: 24690 | E15: 24800 | F15: 24500 | G15: 24338 | H15: 23957 | I15: 23634 | J15: 23315 | K15: 23000
A16: Core EPS ($) | B16: =B13/B15 | C16: =C13/C15 | D16: =D13/D15 | E16: =E13/E15 | F16: =F13/F15 | G16: =G13/G15 | H16: =H13/H15 | I16: =I13/I15 | ... K16: =K13/K15
A17: Core EPS strips non-operating investment gains and taxes operating income at 16.05%, the TTM effective rate and inside company FY2027 guidance of 16–18%. Reported EPS is higher: TTM reported EPS was $7.91 against core EPS of $6.80, because $32.2bn of TTM pretax income sat below the operating line. We value the operating business and treat the investment book separately.
A18: CHECK — reported operating income ($m) | B18: 10041 | C18: 4224 | D18: 32972 | E18: 81453 | F18: 139300
A19: modelled less reported | B19: =B11-B18 | C19: =C11-C18 | D19: =D11-D18 | E19: =E11-E18 | F19: =F11-F18
A21: WHAT Q2 CHANGED, AND WHY THE FORECAST STILL DECELERATES
A22: Q2 forced two revisions in opposite directions. Revenue: the $96.2bn print beat the $91.0bn guide by 5.7% and Q3 is guided to $108.0bn, so FY2027E rises to $403.6bn, +87%. Margin and cash conversion: gross margin is guided DOWN to 74.0% in Q3 from 75.0% delivered — the first guided step-down of this cycle — and TTM free cash flow margin has fallen from 46.97% to 41.92% while revenue grew 19.5%. Growth is consuming working capital.
A23: On FY2028 we revised UP and want to be explicit about why. Our pre-print forecast of +35% did not survive its own arithmetic: it required roughly 4% sequential quarterly growth against the 18% delivered in Q2 and the 12% implied by Q3 guidance. Building the quarters explicitly, sequential decay from 8% to 4% gives +38% and decay from 10% to 6% gives +44%; we use +42%, just below the roughly 44% analysts carried into the print. Nvidia itself then guided FY2028 revenue growth to about 70% on the 26 August call — its first year-ahead forecast — and we are well below that. At 70% our own model returns $251 and an ACCUMULATE.
A24: The deceleration we forecast sits in FY2029-FY2031 (+24%, +16%, +10%) and has a physical mechanism rather than an assertion. Gartner projected in November 2024 that 40% of EXISTING AI data centres would be power-constrained by 2027 — a forecast now nearly two years old. Roughly 2,060 GW of generation and storage sat in US interconnection queues at end-2025, down about 10% and falling for a second year, which cuts against us; federal environmental review for the minority of transmission lines requiring it has averaged 4.3 years. Capital is not the binding constraint — Nvidia itself secured land, power and shell capacity from SB Energy in Ohio and arranged a $500bn third-party financing platform. Electricity is. Our FY2029E of $711bn sits 27% below what consensus implies.
A25: Share counts to FY2026 are reported. FY2027E uses the actual H1 weighted-average diluted count of 24,338m; FY2028E onward assume a 1.44% annual reduction, the pace implied by $19.7bn of quarterly buyback at the current price against $99.0bn remaining on the authorisation.

Sheet DCF
A1: NVIDIA — Free Cash Flow to the Firm ($ millions)
A3: DISCOUNT RATE
A4: Risk-free rate — US 10-yr Treasury, 24-Aug-2026 | B4: 0.0466 | C4: Fed H.15, 26-Aug-2026 (was using a stale 24-Aug 4.72%)
A5: Beta used | B5: 1.5 | C5: 5-year realised beta is 2.21; see note
A6: Equity risk premium | B6: 0.045 | C6: Damodaran-range mature-market ERP
A7: Cost of equity | B7: =B4+B5*B6 | C7: risk-free + beta x equity risk premium
A8: Debt weight | B8: 0 | C8: net cash is treasury only — see Overview
A9: WACC used | B9: =B7 | C9: equals cost of equity (no debt weight)
A10: Terminal growth | B10: 0.04 | C10: 4.0%; CBO-implied long-run US nominal GDP is ~3.8-4.0%. 4.5% would flatter this DCF.
A12: Beta note: Nvidia's realised 5-year beta is 2.21, inflated by the AI re-rating itself. Using it raw would give a 14.67% cost of equity and a much lower value. We use 1.50 — a forward-looking semiconductor beta — because a 2.21 beta plus a below-consensus revenue forecast would stack two bearish assumptions on top of each other. The sensitivity grid shows what the raw beta does.
A14: FREE CASH FLOW BUILD
B15: FY2027E | C15: FY2028E | D15: FY2029E | E15: FY2030E | F15: FY2031E
A16: Revenue | B16: ='Income Statement'!G5 | C16: ='Income Statement'!H5 | D16: ='Income Statement'!I5 | E16: ='Income Statement'!J5 | F16: ='Income Statement'!K5
A17: FCF margin (%) | B17: 0.42 | C17: 0.41 | D17: 0.4 | E17: 0.39 | F17: 0.38
A18: Free cash flow | B18: =B16*B17 | C18: =C16*C17 | D18: =D16*D17 | E18: =E16*E17 | F18: =F16*F17
A19: Discount factor | B19: =1/(1+$B$9)^1 | C19: =1/(1+$B$9)^2 | D19: =1/(1+$B$9)^3 | E19: =1/(1+$B$9)^4 | F19: =1/(1+$B$9)^5
A20: PV of FCF | B20: =B18*B19 | C20: =C18*C19 | D20: =D18*D19 | E20: =E18*E19 | F20: =F18*F19
A22: Sum of PV, explicit period | B22: =SUM(B20:F20)
A23: Terminal value (Gordon on FY2031E FCF) | B23: =F18*(1+B10)/(B9-B10)
A24: PV of terminal value | B24: =B23*F19
A25: terminal share of enterprise value | B25: =B24/(B22+B24)
A26: Enterprise value | B26: =B22+B24
A27: Add: net cash | B27: =Overview!B32
A28: Equity value | B28: =B26+B27
A29: Shares outstanding (m) | B29: =Overview!B7
A30: DCF VALUE PER SHARE ($) | B30: =B28/B29
A32: FCF margins are anchored to the 41.92% actually delivered over the trailing twelve months. Note the trailing FCF dollar figure ROSE, from $119.08bn to $127.01bn; it is the margin that fell, because revenue grew faster. Terminal value is roughly three quarters of enterprise value, which is why this method carries 40% weight rather than the majority — and why the rating is a duration call rather than a multiple call.

Sheet Valuation Summary
A1: NVIDIA — Multi-Method Valuation
A2: Three methods, weighted 40/35/25, on Q2 FY2027 actuals and Q3 guidance. The relative methods are struck on FY2028E and discounted back two years at the cost of equity, so all three are stated in today's money and are directly comparable.
A4: KEY INPUTS
A5: Live price ($, close 27-Aug-2026, post-print) | B5: =Overview!B6
A6: Shares outstanding (m) | B6: =Overview!B7
A7: Diluted shares (m) | B7: 24338
A8: Net cash ($m) | B8: =Overview!B32
A9: Risk-free rate (US 10-yr, 24-Aug-2026) | B9: =DCF!B4
A10: Cost of equity | B10: =DCF!B7
A11: Terminal growth | B11: =DCF!B10
A12: Dividend yield | B12: =Overview!B24/100
A14: METHOD 1 — FCFF DISCOUNTED CASH FLOW (40% weight)
A15: Five-year explicit forecast, Gordon terminal, treasury-only net cash of $23.2bn added. Full build on the DCF sheet.
A16: DCF value per share ($) | B16: =DCF!B30
A18: METHOD 2 — FORWARD P/E ON FY2028E, DISCOUNTED BACK (35% weight)
A19: FY2028E core EPS ($) | B19: ='Income Statement'!H16
A20: Target multiple (x) | B20: 22 | C20: 22x for a business growing 10-16% in the outer years with operating margins in the low sixties. Nvidia trades on 19.1x forward today.
A21: Implied FY2028 price ($) | B21: =B19*B20
A22: Discounted two years to today ($) | B22: =B21/(1+B10)^2
A24: METHOD 3 — EV/EBITDA ON FY2028E, DISCOUNTED BACK (25% weight)
A25: FY2028E revenue ($m) | B25: ='Income Statement'!H5
A26: EBITDA margin (%) | B26: 0.66
A27: FY2028E EBITDA ($m) | B27: =B25*B26
A28: Target EV/EBITDA (x) | B28: 18
A29: Implied FY2028 equity value ($m) | B29: =B27*B28+B8
A30: Implied FY2028 price ($) | B30: =B29/'Income Statement'!H15 | C30: uses the FY2028E share count, consistent with the EPS in Method 2
A31: Discounted two years to today ($) | B31: =B30/(1+B10)^2
A33: BLENDED VALUATION & RATING
A34: Method | B34: Value/share ($) | C34: vs price | D34: Weight
A35: FCFF DCF | B35: =B16 | C35: =B35/$B$5-1 | D35: 0.4
A36: Forward P/E on FY2028E | B36: =B22 | C36: =B36/$B$5-1 | D36: 0.35
A37: EV/EBITDA on FY2028E | B37: =B31 | C37: =B37/$B$5-1 | D37: 0.25
A39: Blended fair value ($) | B39: =SUMPRODUCT(B35:B37,D35:D37)
A40: Upside / (downside) | B40: =B39/B5-1
A41: Add: dividend yield | B41: =B12
A42: Total expected return | B42: =B40+B41
A43: Cost of equity (BUY hurdle) | B43: =B10
A44: ACCUMULATE hurdle (RF + 2pp) | B44: =B9+0.02
A45: RATING | B45: =IF(B42>B43,"BUY",IF(B42>B44,"ACCUMULATE",IF(B42>0,"HOLD","REDUCE")))
A47: Rating bands are anchored to the US 10-year Treasury at 4.66% (26-Aug-2026, Fed H.15): BUY above the cost of equity, ACCUMULATE above risk-free plus two points, HOLD between zero and that hurdle, REDUCE below zero. Struck on the 27-Aug close of $227.98, up 8.74% on the print.
...

Sheet Peer Comps
A1: NVIDIA — Peer Comparison and Street View
A2: All rows at the 27-Aug-2026 close, the session after Nvidia's Q2 FY2027 report. The whole complex rallied on the print. Source: StockAnalysis / S&P Global Market Intelligence.
A4: Company | B4: Ticker | C4: Market cap ($bn) | D4: Price ($) | E4: Trailing P/E (x) | F4: TTM revenue ($bn) | G4: Comment
A5: NVIDIA | B5: NVDA | C5: 5506 | D5: 227.98 | E5: 28.83 | F5: 302.97 | G5: subject; +8.74% on the print; forward P/E 19.1x
A6: Broadcom | B6: AVGO | C6: 1770 | D6: 371.54 | E6: 59.18 | F6: 75.47 | G6: +4.49%; custom accelerators, the closest structural threat
A7: Taiwan Semiconductor | B7: TSM | C7: 1970 | D7: 427.3 | E7: 28.31 | F7: 139.57 | G7: +2.30%; manufactures for Nvidia; the only comparably priced name
A8: Advanced Micro Devices | B8: AMD | C8: 778 | D8: 476.67 | E8: 122.75 | F8: 41.31 | G8: −0.89%; earnings still small relative to the multiple
A9: Marvell | B9: MRVL | C9: 212 | D9: 241.45 | E9: 81.12 | F9: 9.45 | G9: −1.49%; custom silicon for hyperscalers
A10: Intel | B10: INTC | C10: 484 | D10: 92.09 | E10: n/m | F10: 57.03 | G10: +4.36%; loss-making; not meaningful
A12: Peer average trailing P/E, excluding Nvidia and Intel | B12: =AVERAGE(E6:E9)
A13: Nvidia premium / (discount) to that average | B13: =E5/B12-1
A15: THE STRONGEST ARGUMENT AGAINST OUR RATING
A16: Nvidia at 28.8 times trailing earnings remains among the cheapest AI-exposed names in this table. Broadcom is at 59.2x, Marvell at 81.1x, AMD at 122.8x; only TSMC, the foundry that manufactures for Nvidia, is comparable at 28.3x. The average of the four excluding Nvidia and loss-making Intel is 72.8x, so Nvidia trades at a 60% discount to its own peer group while growing faster and earning higher margins than any of them. Forward P/E is 19.1x, ROIC 92%, net margin 63.7%, with $23bn of net treasury cash. Sixty-one analysts cover it, the consensus is Strong Buy and the average target sits well above the market. On every conventional screen this is a cheap stock and our REDUCE is the outlier.
A18: OUR ANSWER
A19: Two responses. First, a price/earnings ratio is a fraction and Nvidia's denominator is now $193bn of annual profit. AMD at 122.8x is expensive on $41bn of revenue and a far smaller earnings base; that multiple says almost nothing about whether Nvidia's $193bn can compound. Second, these are not independent observations — Broadcom, AMD, Marvell and TSMC are priced off the same AI capital-expenditure cycle. Benchmarking Nvidia against them asks whether it is cheap relative to other bets on an identical outcome. Nvidia is cheap if AI capex compounds and expensive if it does not, and so is every name on that list. The peer group is one trade, not five.
A21: STREET DISPERSION
A22: Analysts covering | C22: 61
A23: Consensus rating | C23: Strong Buy
A24: Average target ($) | C24: 320.77
A25: Implied upside from the $227.98 close | C25: =C24/227.98-1
A26: Consensus 3-yr revenue CAGR (%) | C26: 55.4
A27: Consensus 3-yr EPS CAGR (%) | C27: 58.73
A28: Our blended fair value ($) | C28: ='Valuation Summary'!B39
A30: Our implied FY2029E revenue ($bn) | C30: 711
A31: We sit far below the Street. Our FY2029E of $711bn against a consensus 3-year revenue CAGR of 55.4%, and against the company's own ~70% FY2028 guidance. Peer prices are the 27-Aug-2026 close; Marvell reported after that close and fell in after-hours, so its multiple here is already stale.
