Workbook

Sheet Overview
A1: Sun Pharmaceutical Industries (NSE: SUNPHARMA) — Pro-Forma Model & Valuation
A2: This model values Sun Pharma AS IT WILL BE, not as it is. On 27 April 2026 Sun agreed to acquire Organon & Co. for US$11.75bn enterprise value, all cash at $14.00 per share. Organon shareholders approved on 23 July 2026 and the deal closes in early calendar 2027 — inside FY2027E. Sun syndicated over US$10bn of debt across eleven banks on 30 June 2026. A standalone valuation of this company is now obsolete.
A4: SNAPSHOT
A6: Live price (₹, close 04-Sep-2026) | B6: 1899 | C6: −0.89% on the day; the note is struck at this close and dated 07-Sep-2026, before the Monday open
A7: Shares outstanding (cr) | B7: 239.93 | C7: derived from market cap ÷ price
A8: Market capitalisation (₹ cr) | B8: =B6*B7
A9: 52-week range (₹) | B9: 1,547 / 2,048 | C9: Screener basis; Investing.com shows 1,548 / 2,046.90
A10: FY2026 EPS (₹) | B10: 47.84
A11: TTM EPS (₹) | B11: 50.41
A12: Trailing P/E, computed (x) | B12: =B6/B11 | C12: Screener prints 36.4x on a different earnings base
A13: Book value per share (₹) | B13: 348
A14: TTM revenue (₹ cr) | B14: 59911
A15: TTM net profit (₹ cr) | B15: 12117
A16: FY2026 free cash flow (₹ cr) | B16: 8906 | C16: fell 26% from ₹12,005 cr in FY2025
A17: Return on capital employed (%) | B17: 20.53
A18: Dividend yield (%) | B18: 0.84
A19: Promoter holding (%, Jun-2026) | B19: 54.48 | C19: FII 14.54% from 17.96% Mar-25; DII 22.06%
A20: India 10-yr G-sec (%, 04-Sep-2026) | B20: 6.95 | C20: 6.95% on 3-Sep, 6.96% on 4-Sep; we hold 6.95%
A22: THE ORGANON ACQUISITION — the reason this model is pro-forma
A23: Announced | B23: 31-Aug-2026 US / 27-Apr-2026 signing
A24: Enterprise value (US$bn) | B24: 11.75
A25: = ₹ cr at 88.5 | B25: 103988
A26: Consideration | B26: $14.00 per share, all cash
A27: Organon net debt assumed/refinanced (US$bn) | B27: 8.07
A28: Implied equity consideration (US$bn) | B28: 3.68
A29: Sun debt syndication (US$bn) | B29: over 10.0 — 11 banks, ~$1bn each, closed 30-Jun-2026
A30: Acquisition debt (₹ cr, at 88.5) | B30: 88500
A31: Stockholder approval | B31: 23-Jul-2026
A32: Expected close | B32: early calendar 2027 — Q4 FY2027
A33: Organon FY2026E revenue (US$bn) | B33: 6.2
A34: Organon FY2026E adjusted EBITDA (US$bn) | B34: 1.9
A35: Organon EBITDA margin (%) | B35: 30.6
A36: Organon revenue trend | B36: −3% in 2025, guided FLAT for 2026 — a no-growth asset
A37: ACQUISITION MULTIPLE (x EV/EBITDA) | B37: 6.2
A38: Sun's own EV/EBITDA (x) | B38: 23.9
A39: Combined revenue per the release (US$bn) | B39: 12.4
A40: The balance sheet inverts. Sun stands today with roughly ₹20,096 cr of NET CASH — investments of ₹24,723 cr against borrowings of ₹4,627 cr. On completion it carries roughly ₹88,500 cr of acquisition debt, about 2.4 times combined EBITDA gross, 2.3 times net. Any valuation that adds Sun's net cash to equity value, or calls the company 'almost debt-free', is describing a company that will not exist by the middle of the forecast period.
A42: Q1 FY2027 — READ THE ADJUSTED LINE
A43: Metric | B43: Q1 FY27 | C43: Q1 FY26 | D43: Y/Y
A44: Revenue (₹ cr, screener series) | B44: 15300 | C44: 13851 | D44: +10.5%
...

Sheet Pro-Forma P&L
A1: Sun Pharma — Pro-Forma Income Statement (₹ crore, fiscal years ending March)
A2: Sun standalone anchored to company guidance of high single-digit FY2027 growth. Organon consolidated from Q4 FY2027 (one quarter), full from FY2028E.
A4: (₹ cr) | B4: FY2027E | C4: FY2028E | D4: FY2029E | E4: FY2030E | F4: FY2031E
A5: SUN STANDALONE
A6: Revenue | B6: 63724 | C6: 69778 | D6: 75919 | E6: 82296 | F6: 88880
A7: growth (%) | C7: =C6/B6-1 | D7: =D6/C6-1 | E7: =E6/D6-1 | F7: =F6/E6-1
A8: Operating margin (%) | B8: 0.289 | C8: 0.287 | D8: 0.285 | E8: 0.283 | F8: 0.281
A9: EBITDA | B9: =B6*B8 | C9: =C6*C8 | D9: =D6*D8 | E9: =E6*E8 | F9: =F6*F8
A10: ORGANON
A11: Revenue (100%) | B11: 54870 | C11: 54321 | D11: 53778 | E11: 53240 | F11: 52708
A12: Consolidation fraction | B12: 0.25 | C12: 1 | D12: 1 | E12: 1 | F12: 1
A13: Revenue consolidated | B13: =B11*B12 | C13: =C11*C12 | D13: =D11*D12 | E13: =E11*E12 | F13: =F11*F12
A14: Operating margin (%) | B14: 0.306 | C14: 0.303 | D14: 0.3 | E14: 0.297 | F14: 0.294
A15: EBITDA consolidated | B15: =B13*B14 | C15: =C13*C14 | D15: =D13*D14 | E15: =E13*E14 | F15: =F13*F14
A16: SYNERGIES — 50% of the US$350m management guides
A17: Run-rate synergies at 50% delivery (₹ cr) | B17: 1548.75 | G17: US$350m guided over 2-4 years, haircut 50%. Zero is a corner, not a central estimate.
A18: Phasing | B18: 0 | C18: 0.25 | D18: 0.6 | E18: 1 | F18: 1
A19: Synergies realised (₹ cr) | B19: =$B$17*B18 | C19: =$B$17*C18 | D19: =$B$17*D18 | E19: =$B$17*E18 | F19: =$B$17*F18
A20: COMBINED
A21: Revenue | B21: =B6+B13 | C21: =C6+C13 | D21: =D6+D13 | E21: =E6+E13 | F21: =F6+F13
A22: EBITDA | B22: =B9+B15+B19 | C22: =C9+C15+C19 | D22: =D9+D15+D19 | E22: =E9+E15+E19 | F22: =F9+F15+F19
A23: less: D&A | B23: =B6*0.050+B13*0.077 | C23: =C6*0.050+C13*0.077 | D23: =D6*0.050+D13*0.077 | E23: =E6*0.050+E13*0.077 | F23: =F6*0.050+F13*0.077
A24: EBIT | B24: =B22-B23 | C24: =C22-C23 | D24: =D22-D23 | E24: =E22-E23 | F24: =F22-F23
A25: Other income (₹ cr) | B25: 2000 | C25: =(Overview!$B$59-Overview!$B$63)*0.081*1.03^0 | D25: =(Overview!$B$59-Overview!$B$63)*0.081*1.03^1 | E25: =(Overview!$B$59-Overview!$B$63)*0.081*1.03^2 | F25: =(Overview!$B$59-Overview!$B$63)*0.081*1.03^3 | G25: CORRECTED. The published model grew other income to ₹2,400cr while deducting the ₹15,488cr of treasury that produces it. Post-completion the surviving book is ₹9,235cr; at the same ~8.1% yield that is ~₹750cr, not ₹2,100cr.
A26: less: interest on acquisition debt | B26: =88500*0.065*B12 | C26: =88500*0.065*C12 | D26: =88500*0.065*D12 | E26: =88500*0.065*E12 | F26: =88500*0.065*F12
A27: Profit before tax | B27: =B24+B25-350-B26 | C27: =C24+C25-350-C26 | D27: =D24+D25-350-D26 | E27: =E24+E25-350-E26 | F27: =F24+F25-350-F26
A28: tax rate (%) | B28: 0.26 | C28: 0.26 | D28: 0.26 | E28: 0.26 | F28: 0.26
A29: Net profit | B29: =B27*(1-B28) | C29: =C27*(1-C28) | D29: =D27*(1-D28) | E29: =E27*(1-E28) | F29: =F27*(1-F28)
A30: Shares (cr) | B30: 239.93 | C30: 239.93 | D30: 239.93 | E30: 239.93 | F30: 239.93
A31: PRO-FORMA EPS (₹) | B31: =B29/B30 | C31: =C29/C30 | D31: =D29/D30 | E31: =E29/E30 | F31: =F29/F30
A32: memo: Sun standalone EPS (₹) | B32: 51.97 | C32: 57.07 | D32: 61.53 | E32: 66.04 | F32: 70.57
A33: memo: accretion (%) | B33: =B31/B32-1 | C33: =C31/C32-1 | D33: =D31/D32-1 | E33: =E31/E32-1 | F33: =F31/F32-1
A35: Two corrections since the first published version, both found by adversarial review. (1) SYNERGIES: management guides US$350m of cost synergies over 2-4 years and the published model carried none. Zero is a corner, not a central estimate; we now carry 50% of the guide, phased. (2) OTHER INCOME: the model drained the treasury book to fund the deal and kept the income from it. Both are now internally consistent. The first raises fair value, the second lowers it, and they very nearly cancel.
A37: What it does not do is create value on our numbers. Standalone FY2028E EPS of ₹57.07 at a 34x standalone multiple is ₹1,940. Pro-forma EPS of ₹73.55 at the 26x a levered consolidator deserves is ₹1,912. The deal delivers 29% more earnings at a materially lower deserved multiple, and the two very nearly cancel. It changes what the company IS — top-25 global, biosimilars, 2.4x levered gross — without changing what it is worth. The interesting question is therefore not whether the deal is good. It is whether the price was already full before it.

Sheet Valuation
A1: Sun Pharma — Pro-Forma Valuation
A2: Three methods weighted 30/40/30 on the COMBINED entity, with acquisition debt deducted. Cash flows and multiples are discounted by the actual time to each fiscal year end from the 4 September 2026 valuation date, not by whole years.
A4: COST OF EQUITY — corrected
A5: Risk-free — India 10-yr G-sec, 03-Sep-2026 | B5: 0.0695 | C5: eased from ~6.98% on 1-Sep
A6: Beta | B6: 0.9 | C6: published betas are 0.09-0.27 vs the Nifty — see the note below
A7: Equity risk premium | B7: 0.065 | C7: Damodaran India total 7.31% (Jul-26); Incwert recommends 7.00% (range 6.5-7.5%). 6.0% in the first version was below BOTH — corrected to the bottom of Incwert's range.
A8: COST OF EQUITY | B8: =B5+B6*B7 | C8: risk-free + beta x ERP
A10: On beta: Yahoo reports a five-year monthly beta of 0.09-0.12 for Sun against the Nifty and Investing.com 0.27. We do not use those. A beta near zero implies a business uncorrelated with the Indian market, which is an artefact of a large-cap defensive measured against a concentrated local index, and it would produce a cost of equity barely above the government bond. We use 0.90, reflecting a global pharmaceutical business about to take on 2.4x leverage, and we disclose the published figures so a reader can disagree. On the ERP, Damodaran's July 2026 India total is 7.31% and the Incwert India study 5.5-5.9%; we use 6.0%, inside that range and above the 5.4% an earlier draft of this note used.
A12: KEY INPUTS
A13: Live price (₹) | B13: =Overview!B6
A14: Shares outstanding (cr) | B14: =Overview!B7
A15: Acquisition debt (₹ cr) | B15: 88500
A16: FY2028E combined EBITDA (₹ cr) | B16: ='Pro-Forma P&L'!C22
A17: FY2028E pro-forma EPS (₹) | B17: ='Pro-Forma P&L'!C31
A18: Years to FY2028 year end | B18: 1.564 | C18: 07-Sep-2026 to 31-Mar-2028
A19: Dividend yield | B19: =Overview!B18/100
A21: METHOD 1 — FCFF DCF ON THE COMBINED ENTITY (30% weight)
A22: DCF value per share (₹) | B22: ='DCF Build'!B36 | C22: built out on the DCF Build sheet — FCFF at WACC 11.51%, exit 13x FY2031E EBITDA, acquisition debt deducted
A24: METHOD 2 — P/E ON PRO-FORMA FY2028E (40% weight)
A25: Target multiple (x) | B25: 26 | C25: 26x. Below the 34x a debt-free Indian pharma leader commands and well above the ~13x forward earnings Teva trades on — 2.4x levered gross, and 45% of combined EBITDA is a no-growth asset. Derived from the EBITDA mix below; this single number carries the rating.
A26: Value at FY2028 (₹) | B26: =B25*B17
A27: Discounted to today (₹) | B27: =B26/(1+B8)^B18
A29: METHOD 3 — EV/EBITDA, SUM-OF-THE-PARTS (30% weight)
A30: Sun's own business — multiple (x) | B30: 20 | C30: vs 23.9x standalone today
A31: Organon — multiple (x) | B31: 7 | C31: vs the 6.2x Sun is paying
A32: Blended on FY2028E EBITDA (x) | B32: =(B30*'Pro-Forma P&L'!C9+B31*'Pro-Forma P&L'!C15)/'Pro-Forma P&L'!C22 | C32: weighted by each business's EBITDA
A33: Implied EV at FY2028 (₹ cr) | B33: =B32*B16
A34: less: net debt at FY2028 (₹ cr) | B34: =-(Overview!B64-('DCF Build'!C22-'Pro-Forma P&L'!C26*(1-'Pro-Forma P&L'!C28)-'Pro-Forma P&L'!C29*0.33)) | C34: CORRECTED — an EV built on FY2028 EBITDA must carry FY2028 net debt, not completion-date debt. The company deleverages in between.
A35: Equity value at FY2028 (₹) | B35: =(B33+B34)/B14
A36: Discounted to today (₹) | B36: =B35/(1+B8)^B18
A38: BLENDED VALUATION & RATING
A39: Method | B39: Value/share (₹) | C39: vs price | D39: Weight
A40: FCFF DCF, combined | B40: =B22 | C40: =B40/$B$13-1 | D40: 0.3
A41: P/E on pro-forma FY2028E | B41: =B27 | C41: =B41/$B$13-1 | D41: 0.4
A42: EV/EBITDA sum-of-the-parts | B42: =B36 | C42: =B42/$B$13-1 | D42: 0.3
A44: BLENDED FAIR VALUE — today's money (₹) | B44: =SUMPRODUCT(B40:B42,D40:D42)
A45: Upside / (downside) | B45: =B44/B13-1
A46: Add: dividend yield | B46: =B19
A47: TOTAL EXPECTED RETURN | B47: =B45+B46
A48: Cost of equity (BUY hurdle) | B48: =B8
...

Sheet DCF Build
A1: Sun Pharma — Method 1: FCFF DCF on the combined entity, built out
A2: An earlier version of this model carried the DCF as a single typed number with no visible workings, and discounted free cash flow to the FIRM at the cost of EQUITY. Both are corrected here. FCFF is unlevered, so it is discounted at WACC; every line is a formula.
A4: DISCOUNT RATE
A5: Cost of equity (from Valuation sheet) | B5: =Valuation!B8 | D5: 6.95% G-sec + 0.90 beta x 6.5% ERP
A6: Pre-tax cost of debt | B6: 0.065 | D6: the rate on the acquisition syndication
A7: Tax rate | B7: 0.26
A8: After-tax cost of debt | B8: =B6*(1-B7)
A9: Market value of equity (₹ cr) | B9: =Overview!B6*Overview!B7 | D9: at the 03-Sep close
A10: Acquisition debt (₹ cr) | B10: =Valuation!B15
A11: Debt weight | B11: =B10/(B9+B10)
A12: WACC | B12: =(1-B11)*B5+B11*B8 | D12: the rate an unlevered cash-flow stream must be discounted at
A14: FREE CASH FLOW TO THE FIRM (₹ crore)
A15: (₹ cr) | B15: FY2027E | C15: FY2028E | D15: FY2029E | E15: FY2030E | F15: FY2031E
A16: EBIT | B16: ='Pro-Forma P&L'!B24 | C16: ='Pro-Forma P&L'!C24 | D16: ='Pro-Forma P&L'!D24 | E16: ='Pro-Forma P&L'!E24 | F16: ='Pro-Forma P&L'!F24
A17: less: tax at 26% | B17: =-B16*$B$7 | C17: =-C16*$B$7 | D17: =-D16*$B$7 | E17: =-E16*$B$7 | F17: =-F16*$B$7
A18: NOPAT | B18: =B16+B17 | C18: =C16+C17 | D18: =D16+D17 | E18: =E16+E17 | F18: =F16+F17
A19: add back: D&A | B19: ='Pro-Forma P&L'!B23 | C19: ='Pro-Forma P&L'!C23 | D19: ='Pro-Forma P&L'!D23 | E19: ='Pro-Forma P&L'!E23 | F19: ='Pro-Forma P&L'!F23
A20: less: capex | B20: =-('Pro-Forma P&L'!B6*0.055+'Pro-Forma P&L'!B13*0.025) | C20: =-('Pro-Forma P&L'!C6*0.055+'Pro-Forma P&L'!C13*0.025) | D20: =-('Pro-Forma P&L'!D6*0.055+'Pro-Forma P&L'!D13*0.025) | E20: =-('Pro-Forma P&L'!E6*0.055+'Pro-Forma P&L'!E13*0.025) | F20: =-('Pro-Forma P&L'!F6*0.055+'Pro-Forma P&L'!F13*0.025) | H20: Sun 5.5% of revenue, Organon 2.5% — the acquired business is asset-light
A21: less: increase in working capital | B21: =-MAX(0,'Pro-Forma P&L'!B6-58462)*0.15 | C21: =-MAX(0,'Pro-Forma P&L'!C6-'Pro-Forma P&L'!B6)*0.15 | D21: =-(MAX(0,'Pro-Forma P&L'!D6-'Pro-Forma P&L'!C6)+MAX(0,'Pro-Forma P&L'!D13-'Pro-Forma P&L'!C13))*0.15 | E21: =-(MAX(0,'Pro-Forma P&L'!E6-'Pro-Forma P&L'!D6)+MAX(0,'Pro-Forma P&L'!E13-'Pro-Forma P&L'!D13))*0.15 | F21: =-(MAX(0,'Pro-Forma P&L'!F6-'Pro-Forma P&L'!E6)+MAX(0,'Pro-Forma P&L'!F13-'Pro-Forma P&L'!E13))*0.15 | H21: 15% of ORGANIC revenue growth. Organon's working capital arrives inside the US$11.75bn EV, so the consolidation step-up is not charged again
A22: FREE CASH FLOW TO THE FIRM | B22: =B18+B19+B20+B21 | C22: =C18+C19+C20+C21 | D22: =D18+D19+D20+D21 | E22: =E18+E19+E20+E21 | F22: =F18+F19+F20+F21
A23: Years from 04-Sep-2026 | B23: 0.56947296 | C23: 1.5715264 | D23: 2.5708419 | E23: 3.5701574 | F23: 4.569473 | H23: fractional-year discounting to each fiscal year end
A24: Discount factor at WACC | B24: =1/(1+$B$12)^B23 | C24: =1/(1+$B$12)^C23 | D24: =1/(1+$B$12)^D23 | E24: =1/(1+$B$12)^E23 | F24: =1/(1+$B$12)^F23
A25: PV of FCFF | B25: =B22*B24 | C25: =C22*C24 | D25: =D22*D24 | E25: =E22*E24 | F25: =F22*F24
A27: VALUE
A28: PV of explicit-period FCFF (₹ cr) | B28: =SUM(B25:F25)
A29: Exit multiple on FY2031E EBITDA (x) | B29: =B49 | D29: vs 23.9x Sun trades on today and 6.9-8.4x for Viatris/Organon — see Peers sheet
A30: Terminal value at FY2031 (₹ cr) | B30: =B29*'Pro-Forma P&L'!F22
A31: PV of terminal value (₹ cr) | B31: =B30/(1+$B$12)^F23
A32: ENTERPRISE VALUE (₹ cr) | B32: =B28+B31
A33: Terminal share of EV | B33: =B31/B32 | D33: high — which is why this method carries the smallest weight
A34: less: acquisition debt (₹ cr) | B34: =-Valuation!B15
A35: Equity value (₹ cr) | B35: =B32+B34
A36: METHOD 1 — VALUE PER SHARE (₹) | B36: =B35/Overview!B7
A38: Sanity check against the company. Sun guides combined free cash flow of about US$2.5bn — roughly ₹22,100 crore. Our FY2028E FCFF, the first full combined year, is ₹22,890 crore, a 3.5% variance against a figure we did not fit to. That is the strongest external validation in this model.
A40: Company-guided combined free cash flow (US$bn) | B40: 2.5
A41: = ₹ cr at 88.5 | B41: =B40*8850
A42: Our FY2028E FCFF (₹ cr) | B42: =C22
A43: Variance vs the company's own figure | B43: =B42/B41-1 | D43: we did not fit to this — it is an independent check on the cash-flow build
A45: EXIT MULTIPLE — the two anchors that bracket our 13.0x
A46: Our own SOTP applied to the FY2031 EBITDA mix (x) | B46: =(Valuation!B30*'Pro-Forma P&L'!F9+Valuation!B31*'Pro-Forma P&L'!F15)/('Pro-Forma P&L'!F9+'Pro-Forma P&L'!F15) | D46: 20x Sun + 7x Organon on the FY2031 mix — the model's own logic says this
...

Sheet Peers & Street
A1: Sun Pharma — Peers and the Street
A2: Peer rows at the 04-Sep-2026 close (Screener/C-MOTS). Broker targets are individually sourced and dated; see the note on vendor disagreement below.
A4: Company | B4: CMP (₹) | C4: Trailing P/E (x) | D4: Mkt cap (₹ cr) | E4: Qtr sales var (%) | F4: Qtr profit var (%) | G4: ROCE (%)
A5: Sun Pharma | B5: 1899 | C5: 37.671097 | D5: =Overview!B8 | E5: 10.46 | F5: 5.95 | G5: 20.53
A6: Divi's Laboratories | B6: 9250 | C6: 82.42 | D6: 245558 | E6: 27.8 | F6: 65.5 | G6: 21.97
A7: Torrent Pharmaceuticals | B7: 4905.5 | C7: 83.63 | D7: 186589 | E7: 54.85 | F7: 5.79 | G7: 15.19
A8: Zydus Lifesciences | B8: 1143 | C8: 23.42 | D8: 114015 | E8: 21.96 | F8: -35.09 | G8: 21.14
A9: Cipla | B9: 1394.7 | C9: 31.48 | D9: 112672 | E9: 2.33 | F9: -39.19 | G9: 15.49
A10: Laurus Labs | B10: 1868.5 | C10: 92.34 | D10: 100957 | E10: 29.1 | F10: 125.49 | G10: 17.76
A11: Mankind Pharma | B11: 2368.8 | C11: 45.88 | D11: 97842 | E11: 12.89 | F11: 29.6 | G11: 13.53
A13: Note on the sector median. An earlier draft printed a 34.13x median across 158 listed Indian pharmaceutical companies. Screener's industry page returns 218 companies and its peer API serves a wrong-industry set for this ticker, so we could not reproduce that figure and have dropped it. The peers above are individually verified; the median is not.
A15: BROKER TARGETS — individually sourced
A16: House | B16: Target (₹) | C16: Rating | D16: Date | E16: vs price
A17: Motilal Oswal | B17: 2310 | C17: Buy | D17: 01-Aug-2026 | E17: =B17/Overview!B6-1 | F17: 38x 12-month-forward earnings; note dated 1-Aug (SUNP-20260801-MOFSL), republished 4-Aug. Flags Organon on track to close 4QFY27.
A18: Bernstein | B18: 2235 | C18: Outperform | D18: 02-Sep-2026 | E18: =B18/Overview!B6-1 | F18: MFN reaction note; sizes Sun's innovative business at US$1.2-1.3bn
A19: HSBC | B19: 2120 | C19: Buy | D19: 02-Sep-2026 | E19: =B19/Overview!B6-1 | F19: MFN reaction note; says tariff concerns removed for the next two years
A21: CONSENSUS — the vendors do not agree, and that matters
A22: Vendor | B22: Analysts | C22: Average (₹) | D22: High (₹) | E22: Low (₹) | F22: Implied vs ₹1,899
A23: Investing.com | B23: 33 | C23: 2167 | D23: 2400 | E23: 1830 | F23: =C23/Overview!B6-1
A24: TradingView | B24: 35 | C24: 2059 | D24: 2450 | E24: 1625 | F24: =C24/Overview!B6-1 | G24: TradingView NSE:SUNPHARMA forecast page, live 06-Sep-2026 — CORRECTED from 39/₹1,923/₹1,525
A26: CORRECTED. The two polls differ by about 5% on the average, not 13%: Investing.com ₹2,167 implies +13.1%, TradingView ₹2,059 implies +7.5%. The first version of this note said TradingView implied 'essentially none', which was wrong, and it said a third set — 34 analysts, ₹2,055 average, ₹1,650 low — 'could not be reproduced from any vendor'. That was also wrong: it is a stale Investing.com snapshot that the vendor still serves alongside the live one. Both corrections make us MORE of an outlier against consensus, not less.
A28: THE STRONGEST ARGUMENT AGAINST THIS RATING
A29: Every documented broker is materially above us and every one of them has seen the Organon deal. Motilal Oswal is at ₹2,310 on 38x forward earnings, Bernstein at ₹2,235, HSBC at ₹2,120. All three published after the deal was signed and two of them after the MFN agreement. They are not missing the leverage; they are underwriting the accretion and paying a higher multiple for it than we will. On the deal itself the arithmetic favours them: Sun is buying US$1.9bn of EBITDA at 6.2 times with paper that trades at 23.9 times, and the earnings accretion is roughly a third. If the combined entity deserves anything close to the multiple Sun commands today, we are wrong by a wide margin.
A31: OUR ANSWER
A32: We do not dispute the accretion — our own model shows FY2028E earnings per share rising about 29% to ₹73.55. We dispute what a levered consolidator of a declining asset deserves to trade on. Organon's revenue fell 3% in 2025 and is guided flat for 2026; Sun is paying 6.2 times for it precisely because it does not grow. After completion, roughly 46% of combined EBITDA comes from that no-growth business and net debt sits near 2.4 times EBITDA, against a company that today carries net cash. A 34x multiple describes the Sun that existed before April 2026. Our 26x describes what is arriving. The whole disagreement sits in that one number — and if the market keeps paying 34x through the transition, the shares are worth what they cost today.
A34: THE COMPARATOR SET THAT ACTUALLY MATCHES WHAT SUN IS BECOMING
A35: The Indian peers above are the wrong comparator for the post-deal company and we should say so plainly. None of them is levered, and none of them carries half its EBITDA in a declining Western asset. The right reference set is the listed levered pharma consolidators — the companies Sun will structurally resemble from FY2028. Their multiples are far below anything in the Indian table.
A37: Levered / Western comparator | B37: EV/EBITDA (x) | C37: Forward EV/EBITDA (x) | D37: Forward P/E (x) | E37: What it is | F37: Source / date
A38: Viatris (VTRS) | B38: 8.2 | C38: 6.9 | E38: Mylan+Upjohn merger; levered, declining base | F38: valueinvesting.io, 03-Sep-2026
A39: Organon (OGN) standalone | B39: 8.4 | E39: the asset Sun is buying, as the market prices it — 8.4x current, 6.0x LTM | F39: GuruFocus 03-Aug-2026; LTM 6.0x
A40: Teva (TEVA) | B40: 13.1 | D40: 13.05 | E40: post-Actavis; the cautionary precedent | F40: stockanalysis.com, 03-Sep-2026 (EV $55.9bn / TTM EBITDA $4.27bn). GuruFocus shows 32.98x on a GAAP basis — vendors disagree sharply.
A41: — comparator range — | B41: 6.0-13.1 | C41: 6.9 (Viatris) | D41: 13.1
A42: Sun Pharma today | B42: 23.9 | D42: 36.4 | E42: debt-free, Indian, growing | F42: Screener, 03-Sep-2026
A43: OUR pro-forma assumption | B43: 14.0 blended | D43: 26.0 | E43: 20x Sun's business + 7x Organon | F43: this model
A45: This cuts against us as much as for us, and both directions belong in the note. Our 7x for Organon sits squarely inside the 6.0-8.4x the market pays for Organon and Viatris — that assumption is well supported. But our 26x on the COMBINED entity is generous against this set, not conservative: Teva, the closest structural analogue, trades on about 15x forward earnings. A reader who thinks the market will eventually price post-deal Sun as a levered global consolidator rather than as an Indian pharma leader should regard our bear case of ₹1,231 as the base case, not the tail.
A47: The defence of 26x. Sun keeps roughly 54% of combined EBITDA in a growing Indian and innovative franchise; leverage at 2.3x net (2.4x on gross acquisition debt) is a fraction of what Teva carried after Actavis; and an NSE-listed company is priced by domestic flows against domestic alternatives, not against Nasdaq generics. The honest range is 13x to 34x, and 26x is where we have put it — derived from the EBITDA mix on the Valuation sheet, not asserted. That single number carries the rating.
A49: PRECEDENT — what other buyers have paid, and what happened after
A50: Transaction | B50: EV/EBITDA paid | C50: Note
A51: Sun / Organon (Apr-2026) | B51: 6.2x | C51: US$11.75bn EV, all cash, $14.00/sh, 24% premium; net debt/EBITDA guided 2.3x
A52: Mankind / Bharat Serums & Vaccines | B52: over 20x | C52: Indian precedent — Sun paid roughly a third of this
...
