Workbook

Sheet Income Statement
A1: Apple Inc. - Income Statement (USD Millions)
A2: Fiscal Year Ending September | B2: FY 2021 | C2: FY 2022 | D2: FY 2023 | E2: FY 2024 | F2: FY 2025 (A)
A4: Revenue
A5: Products Revenue | B5: 297392 | C5: 316199 | D5: 298085 | E5: 301035 | F5: 307003
A6: Services Revenue | B6: 68425 | C6: 78129 | D6: 85200 | E6: 90000 | F6: 109158
A7: Total Net Sales | B7: =B5+B6 | C7: =C5+C6 | D7: =D5+D6 | E7: =E5+E6 | F7: =F5+F6
A9: Cost of Sales
A10: Products Cost | B10: 192266 | C10: 201471 | D10: 189282 | E10: 189899 | F10: 193671
A11: Services Cost | B11: 20715 | C11: 22084 | D11: 24855 | E11: 20451 | F11: 27290
A12: Total Cost of Sales | B12: =B10+B11 | C12: =C10+C11 | D12: =D10+D11 | E12: =E10+E11 | F12: =F10+F11
A14: Gross Profit | B14: =B7-B12 | C14: =C7-C12 | D14: =D7-D12 | E14: =E7-E12 | F14: =F7-F12
A15: Gross Margin % | B15: =B14/B7*100% | C15: =C14/C7*100% | D15: =D14/D7*100% | E15: =E14/E7*100% | F15: =F14/F7*100%
A17: Operating Expenses
A18: Research & Development | B18: 21914 | C18: 26251 | D18: 29915 | E18: 31370 | F18: 34550
A19: Selling, General & Administrative | B19: 21973 | C19: 25094 | D19: 24932 | E19: 26097 | F19: 27601
A20: Total Operating Expenses | B20: =B18+B19 | C20: =C18+C19 | D20: =D18+D19 | E20: =E18+E19 | F20: =F18+F19
A22: Operating Income | B22: 108949 | C22: 119437 | D22: 114301 | E22: 123218 | F22: 133049
A23: Operating Margin % | B23: =B22/B7 | C23: =C22/C7 | D23: =D22/D7 | E23: =E22/E7 | F23: =F22/F7
A25: Other Income (Expense)
A26: Interest Income | B26: 2843 | C26: 2825 | D26: 3750 | E26: 3492 | F26: 3400
A27: Interest Expense | B27: -2645 | C27: -2931 | D27: -3933 | E27: -3803 | F27: -3300
A28: Other Income, net | B28: 258 | C28: 228 | D28: 382 | E28: 269 | F28: 200
A29: Total Other Income (Expense) | B29: =B26+B27+B28 | C29: =C26+C27+C28 | D29: =D26+D27+D28 | E29: =E26+E27+E28 | F29: =F26+F27+F28
A31: Income Before Tax | B31: 109207 | C31: 119437 | D31: 114500 | E31: 123176 | F31: 133349
A32: Provision for Income Taxes | B32: 14527 | C32: 19300 | D32: 16741 | E32: 29440 | F32: 21339
A33: Effective Tax Rate % | B33: =B32/B31 | C33: =C32/C31 | D33: =D32/D31 | E33: =E32/E31 | F33: =F32/F31
A35: Net Income | B35: =B31-B32 | C35: =C31-C32 | D35: =D31-D32 | E35: =E31-E32 | F35: =F31-F32
A36: Net Income Margin % | B36: =B35/B7 | C36: =C35/C7 | D36: =D35/D7 | E36: =E35/E7 | F36: =F35/F7
A38: Shares Outstanding (Diluted, Millions) | B38: 16865 | C38: 16325 | D38: 15812 | E38: 15204 | F38: 15016
A39: Earnings Per Share (Diluted) | B39: =B35/B38 | C39: =C35/C38 | D39: =D35/D38 | E39: =E35/E38 | F39: =F35/F38

Sheet Balance Sheet
A1: Apple Inc. - Balance Sheet (USD Millions)
A2: Fiscal Year Ending September | B2: FY 2021 | C2: FY 2022 | D2: FY 2023 | E2: FY 2024 | F2: FY 2025 (A)
A4: ASSETS
A5: Current Assets
A6: Cash and Cash Equivalents | B6: 34940 | C6: 23646 | D6: 29965 | E6: 29943 | F6: 35934
A7: Marketable Securities | B7: 27699 | C7: 24658 | D7: 31590 | E7: 35228 | F7: 18763
A8: Accounts Receivable, net | B8: 26278 | C8: 28184 | D8: 29508 | E8: 33410 | F8: 35000
A9: Inventories | B9: 6580 | C9: 4946 | D9: 6331 | E9: 6511 | F9: 6269
A10: Vendor Non-Trade Receivables | B10: 25228 | C10: 32748 | D10: 31477 | E10: 32833 | F10: 34000
A11: Other Current Assets | B11: 14111 | C11: 21223 | D11: 14695 | E11: 15269 | F11: 16000
A12: Total Current Assets | B12: =SUM(B6:B11) | C12: =SUM(C6:C11) | D12: =SUM(D6:D11) | E12: =SUM(E6:E11) | F12: =SUM(F6:F11)
A14: Non-Current Assets
A15: Marketable Securities (Long-term) | B15: 127877 | C15: 120805 | D15: 100544 | E15: 91477 | F15: 77723
A16: Property, Plant & Equipment, net | B16: 39440 | C16: 42117 | D16: 43715 | E16: 45680 | F16: 47500
A17: Other Non-Current Assets | B17: 48849 | C17: 54428 | D17: 64758 | E17: 74629 | F17: 80000
A18: Total Non-Current Assets | B18: =SUM(B15:B17) | C18: =SUM(C15:C17) | D18: =SUM(D15:D17) | E18: =SUM(E15:E17) | F18: =SUM(F15:F17)
A20: Total Assets | B20: =B12+B18 | C20: =C12+C18 | D20: =D12+D18 | E20: =E12+E18 | F20: =F12+F18
A22: LIABILITIES & SHAREHOLDERS' EQUITY
A23: Current Liabilities
A24: Accounts Payable | B24: 54763 | C24: 64115 | D24: 62611 | E24: 68960 | F24: 70000
A25: Other Current Liabilities | B25: 47493 | C25: 60845 | D25: 58829 | E25: 78304 | F25: 80000
A26: Deferred Revenue | B26: 7612 | C26: 7912 | D26: 8061 | E26: 8249 | F26: 8976
A27: Commercial Paper | B27: 6000 | C27: 9982 | D27: 5985 | E27: 9967 | F27: 8000
A28: Current Portion of Long-Term Debt | B28: 9613 | C28: 11128 | D28: 9822 | E28: 10912 | F28: 12400
A29: Total Current Liabilities | B29: =SUM(B24:B28) | C29: =SUM(C24:C28) | D29: =SUM(D24:D28) | E29: =SUM(E24:E28) | F29: =SUM(F24:F28)
A31: Non-Current Liabilities
A32: Long-Term Debt | B32: 109106 | C32: 98959 | D32: 95281 | E32: 85750 | F32: 78900
A33: Other Non-Current Liabilities | B33: 53325 | C33: 49142 | D33: 49848 | E33: 45888 | F33: 44500
A34: Total Non-Current Liabilities | B34: =B32+B33 | C34: =C32+C33 | D34: =D32+D33 | E34: =E32+E33 | F34: =F32+F33
A36: Total Liabilities | B36: =B29+B34 | C36: =C29+C34 | D36: =D29+D34 | E36: =E29+E34 | F36: =F29+F34
A38: Shareholders' Equity
A39: Common Stock & Additional Paid-In Capital | B39: 57365 | C39: 64849 | D39: 73812 | E39: 83276 | F39: 88711
A40: Retained Earnings | B40: 5562 | C40: -3068 | D40: -214 | E40: -19154 | F40: -14302
A41: Accumulated Other Comprehensive Income (Loss) | B41: 163 | C41: -11109 | D41: -11452 | E41: -7172 | F41: -7892
A42: Total Shareholders' Equity | B42: =SUM(B39:B41) | C42: =SUM(C39:C41) | D42: =SUM(D39:D41) | E42: =SUM(E39:E41) | F42: =SUM(F39:F41)
A44: Total Liabilities & Shareholders' Equity | B44: =B36+B42 | C44: =C36+C42 | D44: =D36+D42 | E44: =E36+E42 | F44: =F36+F42
A46: Check (Should be 0) | B46: =B20-B44 | C46: =C20-C44 | D46: =D20-D44 | E46: =E20-E44 | F46: =F20-F44

Sheet Cash Flow Statement
A1: Apple Inc. - Cash Flow Statement (USD Millions)
A2: Fiscal Year Ending September | B2: FY 2021 | C2: FY 2022 | D2: FY 2023 | E2: FY 2024 | F2: FY 2025 (A)
A4: OPERATING ACTIVITIES
A5: Net Income | B5: 94680 | C5: 99803 | D5: 96995 | E5: 93736 | F5: 112010
A6: Adjustments to reconcile net income:
A7: Depreciation & Amortization | B7: 11284 | C7: 11104 | D7: 11519 | E7: 11445 | F7: 11500
A8: Share-Based Compensation | B8: 7906 | C8: 9038 | D8: 10833 | E8: 11688 | F8: 12500
A9: Deferred Income Tax | B9: -4774 | C9: 895 | D9: 5694 | E9: -6500 | F9: 500
A10: Other | B10: -147 | C10: 1006 | D10: -5167 | E10: 1200 | F10: 0
A11: Changes in Operating Assets and Liabilities:
A12: Accounts Receivable | B12: -10125 | C12: -1823 | D12: -1688 | E12: -5577 | F12: -3000
A13: Inventories | B13: 2642 | C13: 1484 | D13: -1618 | E13: -1330 | F13: 242
A14: Vendor Non-Trade Receivables | B14: 3903 | C14: -7520 | D14: 1271 | E14: -1356 | F14: -1500
A15: Other Assets | B15: -9519 | C15: -6499 | D15: 6228 | E15: -2769 | F15: -2000
A16: Accounts Payable | B16: 12326 | C16: 9448 | D16: -1889 | E16: 6799 | F16: 5000
A17: Other Liabilities | B17: 4128 | C17: 7475 | D17: -5632 | E17: 8769 | F17: 10000
A18: Cash from Operating Activities | B18: 104038 | C18: 122151 | D18: 110543 | E18: 118254 | F18: =SUM(F5:F17)
A20: INVESTING ACTIVITIES
A21: Purchase of Marketable Securities | B21: -109689 | C21: -76923 | D21: -29513 | E21: -29042 | F21: -35000
A22: Proceeds from Maturities of Securities | B22: 59023 | C22: 29917 | D22: 45099 | E22: 53461 | F22: 50000
A23: Proceeds from Sales of Securities | B23: 47460 | C23: 37446 | D23: 27169 | E23: 8628 | F23: 15000
A24: Payments for Acquisition of PP&E | B24: -11085 | C24: -10708 | D24: -10959 | E24: -9447 | F24: -10000
A25: Other Investing Activities | B25: -385 | C25: -2086 | D25: -1337 | E25: -1817 | F25: -1000
A26: Cash from Investing Activities | B26: =SUM(B21:B25) | C26: =SUM(C21:C25) | D26: =SUM(D21:D25) | E26: =SUM(E21:E25) | F26: =SUM(F21:F25)
A28: FINANCING ACTIVITIES
A29: Proceeds from Issuance of Common Stock | B29: 1105 | C29: 0 | D29: 0 | E29: 0 | F29: 0
A30: Payments for Taxes on Stock Awards | B30: -6556 | C30: -6223 | D30: -6584 | E30: -6556 | F30: -7000
A31: Payments for Dividends | B31: -14467 | C31: -14841 | D31: -15025 | E31: -15234 | F31: -15500
A32: Repurchases of Common Stock | B32: -85971 | C32: -89402 | D32: -77550 | E32: -94949 | F32: -100000
A33: Proceeds from Issuance of Debt | B33: 20393 | C33: 5465 | D33: 5228 | E33: 0 | F33: 5000
A34: Repayments of Debt | B34: -8750 | C34: -9543 | D34: -11151 | E34: -11445 | F34: -10000
A35: Commercial Paper, net | B35: 1022 | C35: 3955 | D35: -4025 | E35: 3982 | F35: 0
A36: Other Financing Activities | B36: 0 | C36: 0 | D36: 0 | E36: 0 | F36: 0
A37: Cash from Financing Activities | B37: =SUM(B29:B36) | C37: =SUM(C29:C36) | D37: =SUM(D29:D36) | E37: =SUM(E29:E36) | F37: =SUM(F29:F36)
A39: Net Change in Cash | B39: =B18+B26+B37 | C39: =C18+C26+C37 | D39: =D18+D26+D37 | E39: =E18+E26+E37 | F39: =F18+F26+F37
A40: Cash at Beginning of Period | B40: 38016 | C40: =B41 | D40: =C41 | E40: =D41 | F40: =E41
A41: Cash at End of Period | B41: 34940 | C41: 23646 | D41: 29965 | E41: 29943 | F41: 28162
A43: Supplemental Disclosures
A44: Cash Paid for Income Taxes | B44: 25385 | C44: 19573 | D44: 18679 | E44: 24250 | F44: 31000
A45: Cash Paid for Interest | B45: 2687 | C45: 2865 | D45: 3803 | E45: 3803 | F45: 3500
...

Sheet Key Ratios
A1: Apple Inc. - Key Financial Ratios
A2: Fiscal Year Ending September | B2: FY 2021 | C2: FY 2022 | D2: FY 2023 | E2: FY 2024 | F2: FY 2025 (A)
A4: PROFITABILITY RATIOS
A5: Gross Margin % | B5: ='Income Statement'!B14/'Income Statement'!B7 | C5: ='Income Statement'!C14/'Income Statement'!C7 | D5: ='Income Statement'!D14/'Income Statement'!D7 | E5: ='Income Statement'!E14/'Income Statement'!E7 | F5: ='Income Statement'!F14/'Income Statement'!F7
A6: Operating Margin % | B6: ='Income Statement'!B22/'Income Statement'!B7 | C6: ='Income Statement'!C22/'Income Statement'!C7 | D6: ='Income Statement'!D22/'Income Statement'!D7 | E6: ='Income Statement'!E22/'Income Statement'!E7 | F6: ='Income Statement'!F22/'Income Statement'!F7
A7: Net Margin % | B7: ='Income Statement'!B35/'Income Statement'!B7 | C7: ='Income Statement'!C35/'Income Statement'!C7 | D7: ='Income Statement'!D35/'Income Statement'!D7 | E7: ='Income Statement'!E35/'Income Statement'!E7 | F7: ='Income Statement'!F35/'Income Statement'!F7
A8: EBITDA Margin % | B8: 0.3366 | C8: 0.331 | D8: 0.3283 | E8: 0.3444 | F8: 0.3319
A9: Return on Assets (ROA) % | B9: ='Income Statement'!B35/'Balance Sheet'!B20 | C9: ='Income Statement'!C35/'Balance Sheet'!C20 | D9: ='Income Statement'!D35/'Balance Sheet'!D20 | E9: ='Income Statement'!E35/'Balance Sheet'!E20 | F9: ='Income Statement'!F35/'Balance Sheet'!F20
A10: Return on Equity (ROE) % | B10: ='Income Statement'!B35/'Balance Sheet'!B42 | C10: ='Income Statement'!C35/'Balance Sheet'!C42 | D10: ='Income Statement'!D35/'Balance Sheet'!D42 | E10: ='Income Statement'!E35/'Balance Sheet'!E42 | F10: ='Income Statement'!F35/'Balance Sheet'!F42
A12: LIQUIDITY RATIOS
A13: Current Ratio | B13: ='Balance Sheet'!B12/'Balance Sheet'!B29 | C13: ='Balance Sheet'!C12/'Balance Sheet'!C29 | D13: ='Balance Sheet'!D12/'Balance Sheet'!D29 | E13: ='Balance Sheet'!E12/'Balance Sheet'!E29 | F13: ='Balance Sheet'!F12/'Balance Sheet'!F29
A14: Quick Ratio | B14: 0.98 | C14: 0.83 | D14: 0.94 | E14: 0.83 | F14: 0.84
A15: Cash Ratio | B15: =('Balance Sheet'!B6+'Balance Sheet'!B7)/'Balance Sheet'!B29 | C15: =('Balance Sheet'!C6+'Balance Sheet'!C7)/'Balance Sheet'!C29 | D15: =('Balance Sheet'!D6+'Balance Sheet'!D7)/'Balance Sheet'!D29 | E15: =('Balance Sheet'!E6+'Balance Sheet'!E7)/'Balance Sheet'!E29 | F15: =('Balance Sheet'!F6+'Balance Sheet'!F7)/'Balance Sheet'!F29
A17: LEVERAGE RATIOS
A18: Debt to Equity | B18: 1.88 | C18: 2.17 | D18: 1.69 | E18: 1.7 | F18: 1.38
A19: Debt to Assets | B19: 0.34 | C19: 0.31 | D19: 0.3 | E19: 0.26 | F19: 0.25
A20: Interest Coverage Ratio | B20: 41.2 | C20: 40.75 | D20: 29.06 | E20: 32.4 | F20: 36.18
A22: EFFICIENCY RATIOS
A23: Asset Turnover | B23: ='Income Statement'!B7/'Balance Sheet'!B20 | C23: ='Income Statement'!C7/'Balance Sheet'!C20 | D23: ='Income Statement'!D7/'Balance Sheet'!D20 | E23: ='Income Statement'!E7/'Balance Sheet'!E20 | F23: ='Income Statement'!F7/'Balance Sheet'!F20
A24: Inventory Turnover | B24: ='Income Statement'!B12/'Balance Sheet'!B9 | C24: ='Income Statement'!C12/'Balance Sheet'!C9 | D24: ='Income Statement'!D12/'Balance Sheet'!D9 | E24: ='Income Statement'!E12/'Balance Sheet'!E9 | F24: ='Income Statement'!F12/'Balance Sheet'!F9
A25: Days Inventory Outstanding | B25: =365/B24 | C25: =365/C24 | D25: =365/D24 | E25: =365/E24 | F25: =365/F24
A26: Days Sales Outstanding | B26: =365*'Balance Sheet'!B8/'Income Statement'!B7 | C26: =365*'Balance Sheet'!C8/'Income Statement'!C7 | D26: =365*'Balance Sheet'!D8/'Income Statement'!D7 | E26: =365*'Balance Sheet'!E8/'Income Statement'!E7 | F26: =365*'Balance Sheet'!F8/'Income Statement'!F7
A28: PER SHARE DATA
A29: EPS (Diluted) | B29: ='Income Statement'!B35/'Income Statement'!B38 | C29: ='Income Statement'!C35/'Income Statement'!C38 | D29: ='Income Statement'!D35/'Income Statement'!D38 | E29: ='Income Statement'!E35/'Income Statement'!E38 | F29: ='Income Statement'!F35/'Income Statement'!F38
A30: Book Value Per Share | B30: ='Balance Sheet'!B42/'Income Statement'!B38 | C30: ='Balance Sheet'!C42/'Income Statement'!C38 | D30: ='Balance Sheet'!D42/'Income Statement'!D38 | E30: ='Balance Sheet'!E42/'Income Statement'!E38 | F30: ='Balance Sheet'!F42/'Income Statement'!F38
A31: Free Cash Flow Per Share | B31: ='Cash Flow Statement'!B48/'Income Statement'!B38 | C31: ='Cash Flow Statement'!C48/'Income Statement'!C38 | D31: ='Cash Flow Statement'!D48/'Income Statement'!D38 | E31: ='Cash Flow Statement'!E48/'Income Statement'!E38 | F31: ='Cash Flow Statement'!F48/'Income Statement'!F38
A32: Dividend Per Share | B32: 0.85 | C32: 0.91 | D32: 0.95 | E32: 0.99 | F32: 1.04
A34: VALUATION METRICS (For DCF Model)
A35: Revenue Growth % | B35: 0.3326 | C35: ='Income Statement'!C7/'Income Statement'!B7-1 | D35: ='Income Statement'!D7/'Income Statement'!C7-1 | E35: ='Income Statement'!E7/'Income Statement'!D7-1 | F35: ='Income Statement'!F7/'Income Statement'!E7-1
A36: EBITDA | B36: 123141 | C36: 130541 | D36: 125820 | E36: 134663 | F36: 138123
A37: EBIT | B37: ='Income Statement'!B22 | C37: ='Income Statement'!C22 | D37: ='Income Statement'!D22 | E37: ='Income Statement'!E22 | F37: ='Income Statement'!F22
A38: Tax Rate % | B38: 0.133 | C38: 0.1616 | D38: 0.1462 | E38: 0.239 | F38: 0.1154
A39: Capital Expenditures | B39: =-'Cash Flow Statement'!B24 | C39: =-'Cash Flow Statement'!C24 | D39: =-'Cash Flow Statement'!D24 | E39: =-'Cash Flow Statement'!E24 | F39: =-'Cash Flow Statement'!F24
A40: Depreciation & Amortization | B40: ='Cash Flow Statement'!B7 | C40: ='Cash Flow Statement'!C7 | D40: ='Cash Flow Statement'!D7 | E40: ='Cash Flow Statement'!E7 | F40: ='Cash Flow Statement'!F7
A41: Change in Net Working Capital | B41: 847 | C41: -632 | D41: 2242 | E41: -3261 | F41: 8742
A42: Unlevered Free Cash Flow | B42: ='Cash Flow Statement'!B48 | C42: ='Cash Flow Statement'!C48 | D42: ='Cash Flow Statement'!D48 | E42: ='Cash Flow Statement'!E48 | F42: ='Cash Flow Statement'!F48

Sheet Valuation Summary
A1: Apple Inc. — Multi-Method Valuation Summary
A2: All figures USD; per-share in USD. Live price $333.26 (21-Jul-2026), 14,690M diluted shares, net cash $33.1B.
A4: KEY INPUTS
A5: Live share price ($) | B5: 333.26
A6: Diluted shares (M) | B6: 14690
A7: Net cash (cash − debt, $M) | B7: ='DCF Model'!B81-'DCF Model'!B82
A8: FY26E revenue ($M) | B8: ='DCF Model'!D9
A9: FY26E EBIT ($M) | B9: ='DCF Model'!D20
A10: FY26E D&A ($M) | B10: ='DCF Model'!D30
A11: FY26E EBITDA ($M) | B11: ='DCF Model'!D20+'DCF Model'!D30
A12: FY26E EPS ($) | B12: 9.3
A13: FY26E Services revenue ($M) | B13: 123350
A14: FY26E Products revenue ($M) | B14: ='DCF Model'!D9-B13
A16: VALUATION METHODS
A17: Method | B17: Assumption | C17: Implied value/share ($) | D17: vs price | E17: Weight
A18: DCF (intrinsic, conservative floor) | B18: WACC 9.85%, g 3.5% | C18: ='DCF Model'!B86 | D18: =C18/B5-1 | E18: 0.1
A19: Justified P/E (relative) | B19: 38x × FY26E EPS | C19: =38*B12 | D19: =C19/B5-1 | E19: 0.4
A20: EV/EBITDA (relative) | B20: 28x × FY26E EBITDA | C20: =(28*B11+B7)/B6 | D20: =C20/B5-1 | E20: 0.3
A21: Sum-of-the-parts (Services + Products) | B21: Services 13x rev + Products 5.5x rev | C21: =(13*B13+5.5*B14+B7)/B6 | D21: =C21/B5-1 | E21: 0.2
A22: (Reference) current market multiple | B22: 40x TTM EPS | C22: =B5
A24: BLENDED VALUATION & RATING
A25: Blended fair value ($) = Σ weight × method | B25: =SUMPRODUCT(C18:C21,E18:E21)
A26: Upside / (downside) vs $333.26 | B26: =B25/B5-1
A27: Rating | B27: =IF(B26>0.10,"BUY",IF(B26>-0.10,"HOLD","REDUCE"))
A28: Note: DCF structurally under-prices a 40x quality compounder (Services 26% of revenue at ~75% GM); we weight relative + SOTP methods higher. Even so, every method except a premium P/E sits below spot — no margin of safety. DDM n/a (buyback-led capital return, ~0.4% yield). Street: Buy, median target ~$310 (below spot).

Sheet DCF Model
A1: Apple Inc. - DCF Valuation Model
A2: All figures in USD Millions except per share data
A3: Base Case Assumptions (refreshed 21 Jul 2026 — FY2025 10-K actuals + H1 FY2026)
A4: AI upgrade supercycle: H1 FY26 revenue +16.4% YoY; growth normalizes FY27 onward
A5: Services ~26% of revenue growing mid-teens; operating margin drifts to 33%
A7: SECTION 1: REVENUE PROJECTIONS
B8: FY2024 (A) | C8: FY2025 (A) | D8: FY2026 (E) | E8: FY2027 (F) | F8: FY2028 (F) | G8: FY2029 (F) | H8: FY2030 (F)
A9: Revenue | B9: 391035 | C9: 416161 | D9: 477000 | E9: 515160 | F9: 551221 | G9: 584294 | H9: 613509
A10: Revenue Growth % | B10: 0.0202 | C10: 0.0643 | D10: 0.1462 | E10: 0.08 | F10: 0.07 | G10: 0.06 | H10: 0.05
A12: SECTION 2: OPERATING MARGINS
B13: FY2024 (A) | C13: FY2025 (A) | D13: FY2026 (E) | E13: FY2027 (F) | F13: FY2028 (F) | G13: FY2029 (F) | H13: FY2030 (F)
A14: Gross Margin % | B14: 0.4621 | C14: 0.4691 | D14: 0.472 | E14: 0.472 | F14: 0.471 | G14: 0.47 | H14: 0.47
A15: Operating Margin % | B15: 0.3151 | C15: 0.3197 | D15: 0.325 | E15: 0.327 | F15: 0.33 | G15: 0.33 | H15: 0.33
A17: SECTION 3: CALCULATE EBIT
B18: FY2024 (A) | C18: FY2025 (A) | D18: FY2026 (E) | E18: FY2027 (F) | F18: FY2028 (F) | G18: FY2029 (F) | H18: FY2030 (F)
A19: Revenue | B19: =B9 | C19: =C9 | D19: =D9 | E19: =E9 | F19: =F9 | G19: =G9 | H19: =H9
A20: EBIT | B20: =B19*B15 | C20: =C19*C15 | D20: =D19*D15 | E20: =E19*E15 | F20: =F19*F15 | G20: =G19*G15 | H20: =H19*H15
A22: SECTION 4: TAX AND NOPAT
B23: FY2024 (A) | C23: FY2025 (A) | D23: FY2026 (E) | E23: FY2027 (F) | F23: FY2028 (F) | G23: FY2029 (F) | H23: FY2030 (F)
A24: Tax Rate % | B24: 0.239 | C24: 0.16 | D24: 0.16 | E24: 0.16 | F24: 0.16 | G24: 0.16 | H24: 0.16
A25: Taxes on EBIT | B25: =B20*B24 | C25: =C20*C24 | D25: =D20*D24 | E25: =E20*E24 | F25: =F20*F24 | G25: =G20*G24 | H25: =H20*H24
A26: NOPAT (EBIT - Taxes) | B26: =B20-B25 | C26: =C20-C25 | D26: =D20-D25 | E26: =E20-E25 | F26: =F20-F25 | G26: =G20-G25 | H26: =H20-H25
A28: SECTION 5: ADD BACK D&A
B29: FY2024 (A) | C29: FY2025 (A) | D29: FY2026 (E) | E29: FY2027 (F) | F29: FY2028 (F) | G29: FY2029 (F) | H29: FY2030 (F)
A30: Depreciation & Amortization | B30: 11445 | C30: 11500 | D30: 12500 | E30: 13000 | F30: 13600 | G30: 14200 | H30: 14900
A32: SECTION 6: CAPEX AND NWC
B33: FY2024 (A) | C33: FY2025 (A) | D33: FY2026 (E) | E33: FY2027 (F) | F33: FY2028 (F) | G33: FY2029 (F) | H33: FY2030 (F)
A34: Capital Expenditures (Capex) | B34: 9447 | C34: 10000 | D34: 14000 | E34: 15000 | F34: 15800 | G34: 16500 | H34: 17200
A35: Change in Net Working Capital | B35: -3261 | C35: 8742 | D35: 1500 | E35: 1300 | F35: 1200 | G35: 1100 | H35: 1000
A37: SECTION 7: UNLEVERED FCF
B38: FY2024 (A) | C38: FY2025 (A) | D38: FY2026 (E) | E38: FY2027 (F) | F38: FY2028 (F) | G38: FY2029 (F) | H38: FY2030 (F)
A39: NOPAT | B39: =B26 | C39: =C26 | D39: =D26 | E39: =E26 | F39: =F26 | G39: =G26 | H39: =H26
A40: Add: Depreciation & Amortization | B40: =B30 | C40: =C30 | D40: =D30 | E40: =E30 | F40: =F30 | G40: =G30 | H40: =H30
A41: Less: Capital Expenditures | B41: =-B34 | C41: =-C34 | D41: =-D34 | E41: =-E34 | F41: =-F34 | G41: =-G34 | H41: =-H34
A42: Less: Change in NWC | B42: =-B35 | C42: =-C35 | D42: =-D35 | E42: =-E35 | F42: =-F35 | G42: =-G35 | H42: =-H35
A43: Unlevered Free Cash Flow | B43: =B39+B40+B41+B42 | C43: =C39+C40+C41+C42 | D43: =D39+D40+D41+D42 | E43: =E39+E40+E41+E42 | F43: =F39+F40+F41+F42 | G43: =G39+G40+G41+G42 | H43: =H39+H40+H41+H42
A45: SECTION 8: WACC ASSUMPTIONS
A46: Risk-Free Rate | B46: 0.045 | C46: 10-Year US Treasury
A47: Market Risk Premium | B47: 0.05 | C47: Equity risk premium
A48: Beta | B48: 1.1 | C48: Apple beta vs S&P 500
...

Sheet PE Ratio Analysis
A1: Apple Inc. - PE Ratio Analysis
A3: HISTORICAL PE RATIOS
A4: Fiscal Year | B4: FY 2021 | C4: FY 2022 | D4: FY 2023 | E4: FY 2024 | F4: FY 2025 (A)
A5: Net Income (USD Millions) | B5: 94680 | C5: 99803 | D5: 96995 | E5: 93736 | F5: 112010
A6: Diluted Shares Outstanding (Millions) | B6: 16865 | C6: 16325 | D6: 15812 | E6: 15204 | F6: 15016
A7: Diluted EPS | B7: 5.61 | C7: 6.11 | D7: 6.13 | E7: 6.16 | F7: 7.46
A9: Average Stock Price (estimate) | B9: 140 | C9: 150 | D9: 175 | E9: 220 | F9: 235
A10: PE Ratio | B10: 24.96 | C10: 24.55 | D10: 28.55 | E10: 35.71 | F10: 31.5
A12: PEER COMPARISON (Jul 2026)
A13: Company | B13: Market Cap | C13: Net Income | D13: EPS | E13: Stock Price | F13: PE Ratio
A14: Apple (AAPL) | B14: 4810000 | C14: 122580 | D14: 8.27 | E14: 327.44 | F14: =E14/D14
A15: Microsoft (MSFT) | B15: 2930000 | C15: 133182 | D15: 17.9 | E15: 393.8 | F15: =E15/D15
A16: Alphabet (GOOGL) | B16: 4350000 | C16: 153764 | D16: 12.73 | E16: 360 | F16: =E16/D16
A17: Amazon (AMZN) | B17: 2690000 | C17: 96071 | D17: 8.94 | E17: 250.42 | F17: =E17/D17
A18: Meta (META) | B18: n/a | C18: n/a | D18: n/a | E18: n/a | F18: 23.55
A20: Sector Average PE | B20: =AVERAGE(F15:F18)
A21: Apple Premium / Discount to Sector | B21: =F14/B20-1
A23: FORWARD PE ANALYSIS
B24: FY 2026 (E) | C24: FY 2027 (F) | D24: FY 2028 (F) | E24: FY 2029 (F)
A25: Projected EPS | B25: 9 | C25: 9.9 | D25: 10.8 | E25: 11.7
A26: Current Stock Price | B26: 327.44 | C26: 327.44 | D26: 327.44 | E26: 327.44
A27: Forward PE Ratio | B27: =B26/B25 | C27: =C26/C25 | D27: =D26/D25 | E27: =E26/E25
A29: VALUATION USING PE MULTIPLE
A30: Method | B30: EPS | C30: Target PE | D30: Implied Price | E30: Upside %
A31: Historical Average PE | B31: 9 | C31: 29 | D31: =B31*C31 | E31: =D31/327.44-1
A32: Sector Average PE | B32: 9 | C32: 25.5 | D32: =B32*C32 | E32: =D32/327.44-1
A33: High Growth Scenario (PE 35x) | B33: 9 | C33: 35 | D33: =B33*C33 | E33: =D33/327.44-1
A34: Conservative Scenario (PE 25x) | B34: 9 | C34: 25 | D34: =B34*C34 | E34: =D34/327.44-1
A36: PEG RATIO ANALYSIS
B37: Value
A38: Current PE Ratio | B38: 39.6
A39: Expected EPS Growth Rate (Next 3Y) | B39: 0.12
A40: PEG Ratio | B40: =B38/(B39*100)
A41: Interpretation: <1 = Undervalued, 1-2 = Fair, >2 = Overvalued
A43: KEY OBSERVATIONS
A44: 1. Apple's PE has ranged from 24.5x to 35.7x over last 5 years
A45: 2. Premium valuation reflects strong brand and ecosystem
A46: 3. Recent buybacks have reduced share count 11.4% since FY2021
A47: 4. Services revenue growth commands higher multiple
A48: 5. Compare to sector average for relative valuation
