Workbook

Sheet Overview
A1: Costco Wholesale Corporation (NASDAQ: COST) — Financial Model
A2: Debjit Mukherjee · IB Independent · valuation date 16 October 2026 (refresh of the 1-Oct note) (NASDAQ close). Blue = hard-coded input · black = same-sheet formula · green = cross-sheet link.
A4: MARKET DATA
A5: Valuation date | B5: 16-Oct-2026 | D5: NASDAQ close; refreshed from the 1-Oct-2026 valuation (FY2026 results 24-Sep; September sales 7-Oct)
A6: Live price ($) | B6: 989.11 | D6: Close 16-Oct-2026: stockanalysis.com history and digrin agree ($989.11); 1-Oct close was $914.94
A7: Shares outstanding (m) | B7: ='Balance Sheet'!F31/1000 | D7: Balance sheet 30-Aug-2026: 443,266,000 issued and outstanding — NOT derived from market cap ÷ price
A8: Market capitalisation ($m) | B8: =B6*B7
A9: Market cap per S&P Global (stockanalysis), $m | B9: 438300 | D9: cross-check only; stockanalysis 16-Oct-2026 (443.13m shares on the vendor basis)
A10: Check: share count implied by vendor market cap ÷ price, less balance-sheet count (m) | B10: =ROUND(B9/B6-B7,1) | D10: within ±0.1m = the two sources agree
A11: Quarterly dividend ($) | B11: 1.47 | D11: 8-K 14-Oct-2026: $1.47 declared, record 30-Oct, payable 13-Nov-2026
A12: Annual regular dividend ($) | B12: =4*B11
A13: Dividend yield (regular only) | B13: =B12/B6 | D13: specials excluded — irregular, last $15.00 in January 2024
A14: 52-week high ($) | B14: 1096.5 | D14: May 2026 (stockanalysis / Google Finance)
A15: 52-week low ($) | B15: 844.06
A16: Beta (5-year monthly) | B16: 0.87 | D16: stockanalysis 16-Oct-2026 displays 0.87; unchanged from 1-Oct
A17: Risk-free — US 10-yr Treasury, 16-Oct-2026 | B17: 0.0509 | D17: US Treasury daily par yield curve: 5.09% on 16-Oct-2026 (FRED DGS10 5.10% on 15-Oct); 5.24% on 1-Oct-2026
A18: Equity risk premium | B18: 0.045 | D18: Damodaran implied ERP 1-Jan-2026: 4.23%; set at 4.5% (prudent; desk standard for US names)
A19: Trailing P/E on recurring FY2026 EPS (x) | B19: =B6/'Income Statement'!F27
A20: Earnings yield on recurring FY2026 EPS | B20: ='Income Statement'!F27/B6
A21: Earnings yield less 10-yr Treasury (pp) | B21: =B20-B17 | D21: negative: the bond out-yields the stock's earnings by this much
A22: Price change from 52-week high | B22: =B6/B14-1
A23: FY2027 capex guidance ($m) | B23: 7500 | D23: CFO Gary Millerchip, Q4 FY2026 call, 24-Sep-2026
A25: MEMBERSHIP — fiscal year end, Q4 FY2026 call (24-Sep-2026)
A26: Paid members (m) | B26: 84.1 | D26: +3.8% year on year
A27: Paid member growth | B27: 0.038
A28: Executive members (m) | B28: 42.3 | D28: +9.4%; record penetration
A29: Executive share of paid members | B29: =B28/B26
A30: Renewal rate — US & Canada | B30: 0.923 | D30: +10bp on the quarter
A31: Renewal rate — worldwide | B31: 0.898
A32: Q4 membership fee growth, reported | B32: 0.073
A33: Q4 membership fee growth ex fee increase and FX | B33: 0.068 | D33: Q4 was the LAST quarter with a benefit from the Sep-2024 US/Canada fee increase
A34: Warehouses at year end | B34: 939 | D34: 28 opened in FY2026 incl. 3 relocations; 33 planned for FY2027 incl. 5 relocations
A35: FY2026 comparable sales — headline | B35: 0.084
A36: FY2026 comparable sales — ex gasoline and FX | B36: 0.066 | D36: Q4: 9.4% headline, 6.7% adjusted; gas price inflation added ~3pp to Q4
A38: OUTPUT — linked from the Valuation sheet
A39: RATING | B39: =Valuation!B44
A40: Blended fair value ($) | B40: =Valuation!B40
A41: Upside / (downside) | B41: =Valuation!B41
A42: Total expected return | B42: =Valuation!B43
A43: Cost of equity (BUY hurdle) | B43: =Valuation!B7
...

Sheet Income Statement
A1: Costco Wholesale (COST) — Income Statement, FY2022–FY2026
A2: Source: Costco Q4/FY results releases, investor.costco.com (FY2023 incl. FY2022 comparatives; FY2024; FY2026 incl. FY2025). $m except per share.
A3: $ millions | B3: FY2022 | C3: FY2023 | D3: FY2024 | E3: FY2025 | F3: FY2026
A4: Net sales | B4: 222730 | C4: 237710 | D4: 249625 | E4: 269912 | F4: 297247
A5: Membership fees | B5: 4224 | C5: 4580 | D5: 4828 | E5: 5323 | F5: 5907
A6: Total revenue | B6: =B4+B5 | C6: =C4+C5 | D6: =D4+D5 | E6: =E4+E5 | F6: =F4+F5
A7: Merchandise costs | B7: 199382 | C7: 212586 | D7: 222358 | E7: 239886 | F7: 264279
A8: Selling, general and administrative | B8: 19779 | C8: 21590 | D8: 22810 | E8: 24966 | F8: 27190
A9: Operating income | B9: =B6-B7-B8 | C9: =C6-C7-C8 | D9: =D6-D7-D8 | E9: =E6-E7-E8 | F9: =F6-F7-F8
A10: Interest expense | B10: -158 | C10: -160 | D10: -169 | E10: -154 | F10: -145
A11: Interest income and other, net | B11: 205 | C11: 533 | D11: 624 | E11: 589 | F11: 711
A12: Income before income taxes | B12: =B9+B10+B11 | C12: =C9+C10+C11 | D12: =D9+D10+D11 | E12: =E9+E10+E11 | F12: =F9+F10+F11
A13: Provision for income taxes | B13: 1925 | C13: 2195 | D13: 2373 | E13: 2719 | F13: 3025
A14: Net income attributable to noncontrolling interests | B14: -71 | C14: 0 | D14: 0 | E14: 0 | F14: 0
A15: NET INCOME ATTRIBUTABLE TO COSTCO | B15: =B12-B13+B14 | C15: =C12-C13+C14 | D15: =D12-D13+D14 | E15: =E12-E13+E14 | F15: =F12-F13+F14
A16: Diluted shares (000s) | B16: 444757 | C16: 444452 | D16: 444759 | E16: 444803 | F16: 444427
A17: Diluted EPS, computed ($) | B17: =B15/B16*1000 | C17: =C15/C16*1000 | D17: =D15/D16*1000 | E17: =E15/E16*1000 | F17: =F15/F16*1000
A18: Reported diluted EPS ($) | B18: 13.14 | C18: 14.16 | D18: 16.56 | E18: 18.21 | F18: 20.76
A19: Check: computed less reported EPS (must be within ±$0.01) | B19: =ROUND(B17-B18,2) | C19: =ROUND(C17-C18,2) | D19: =ROUND(D17-D18,2) | E19: =ROUND(E17-E18,2) | F19: =ROUND(F17-F18,2)
A20: Weeks in fiscal year | B20: 52 | C20: 53 | D20: 52 | E20: 52 | F20: 52
A22: FY2026 EPS EX TARIFF REFUND — the only item removed (see note below)
A23: Non-recurring IEEPA tariff refund benefit, $ per diluted share (company-disclosed, Q4 FY2026) | F23: 0.15
A24: Q4 FY2026 effective tax rate (CFO, Q4 call) | F24: 0.252
A25: Implied pre-tax benefit ($m) = EPS × diluted shares ÷ (1 − tax) | F25: =F23*F16/1000/(1-F24)
A26: Recurring operating income ($m) | F26: =F9-F25
A27: Recurring diluted EPS ($) | F27: =F18-F23
A28: Recurring EPS growth vs FY2025 | F28: =F27/E18-1
A29: FY2023 had 53 weeks, so growth into and out of FY2023 is distorted by roughly 2%. Every Q4 is 16 weeks.
A30: Only the tariff refund ($0.15) is removed; stock-comp tax benefits ($0.16 Q1 FY26, $0.22 Q1 FY25) recur each Q1 and stay in both years.
A31: Q4 FY2026 (16 weeks to 30-Aug-2026) vs Q4 FY2025
B32: Q4 FY2026 | C32: Q4 FY2025 | D32: Change
A33: Net sales | B33: 93873 | C33: 84432 | D33: =B33/C33-1
A34: Membership fees | B34: 1850 | C34: 1724 | D34: =B34/C34-1
A35: Operating income | B35: 3801 | C35: 3341 | D35: =B35/C35-1
A36: Net income | B36: 2998 | C36: 2610 | D36: =B36/C36-1
A37: Diluted EPS ($) | B37: 6.75 | C37: 5.87 | D37: =B37/C37-1
A38: Q4 diluted EPS ex tariff benefit ($) | B38: =B37-F23 | C38: =C37 | D38: =B38/C38-1

Sheet Balance Sheet
A1: Costco — Balance Sheet, fiscal year ends FY2022–FY2026
A2: Source: Costco Q4/FY results releases, investor.costco.com (FY2023 incl. FY2022 comparatives; FY2024; FY2026 incl. FY2025). $m except per share.
A3: $ millions | B3: FY2022 | C3: FY2023 | D3: FY2024 | E3: FY2025 | F3: FY2026
A4: Cash and cash equivalents | B4: 10203 | C4: 13700 | D4: 9906 | E4: 14161 | F4: 20207
A5: Short-term investments | B5: 846 | C5: 1534 | D5: 1238 | E5: 1123 | F5: 1094
A6: Receivables, net | B6: 2241 | C6: 2285 | D6: 2721 | E6: 3203 | F6: 3959
A7: Merchandise inventories | B7: 17907 | C7: 16651 | D7: 18647 | E7: 18116 | F7: 19324
A8: Other current assets | B8: 1499 | C8: 1709 | D8: 1734 | E8: 1777 | F8: 1998
A9: Total current assets | B9: =SUM(B4:B8) | C9: =SUM(C4:C8) | D9: =SUM(D4:D8) | E9: =SUM(E4:E8) | F9: =SUM(F4:F8)
A10: Property and equipment, net | B10: 24646 | C10: 26684 | D10: 29032 | E10: 31909 | F10: 35633
A11: Operating lease right-of-use assets | B11: 2774 | C11: 2713 | D11: 2617 | E11: 2725 | F11: 2697
A12: Other long-term assets | B12: 4050 | C12: 3718 | D12: 3936 | E12: 4085 | F12: 4133
A13: TOTAL ASSETS | B13: =B9+B10+B11+B12 | C13: =C9+C10+C11+C12 | D13: =D9+D10+D11+D12 | E13: =E9+E10+E11+E12 | F13: =F9+F10+F11+F12
A14: Total assets as reported | B14: 64166 | C14: 68994 | D14: 69831 | E14: 77099 | F14: 89045
A15: Check: computed less reported total assets (must be 0) | B15: =B13-B14 | C15: =C13-C14 | D15: =D13-D14 | E15: =E13-E14 | F15: =F13-F14
A17: Accounts payable | B17: 17848 | C17: 17483 | D17: 19421 | E17: 19783 | F17: 22591
A18: Accrued salaries and benefits | B18: 4381 | C18: 4278 | D18: 4794 | E18: 5205 | F18: 5641
A19: Accrued member rewards | B19: 1911 | C19: 2150 | D19: 2435 | E19: 2677 | F19: 3037
A20: Deferred membership fees | B20: 2174 | C20: 2337 | D20: 2501 | E20: 2854 | F20: 3006
A21: Current portion of long-term debt | B21: 73 | C21: 1081 | D21: 103 | E21: 75 | F21: 2248
A22: Other current liabilities | B22: 5611 | C22: 6254 | D22: 6210 | E22: 6514 | F22: 7429
A23: Total current liabilities | B23: =SUM(B17:B22) | C23: =SUM(C17:C22) | D23: =SUM(D17:D22) | E23: =SUM(E17:E22) | F23: =SUM(F17:F22)
A24: Long-term debt, excluding current portion | B24: 6484 | C24: 5377 | D24: 5794 | E24: 5713 | F24: 3914
A25: Long-term operating lease liabilities | B25: 2482 | C25: 2426 | D25: 2375 | E25: 2460 | F25: 2414
A26: Other long-term liabilities | B26: 2555 | C26: 2550 | D26: 2576 | E26: 2654 | F26: 2962
A27: TOTAL LIABILITIES | B27: =B23+B24+B25+B26 | C27: =C23+C24+C25+C26 | D27: =D23+D24+D25+D26 | E27: =E23+E24+E25+E26 | F27: =F23+F24+F25+F26
A28: Total equity (incl. noncontrolling interests) | B28: 20647 | C28: 25058 | D28: 23622 | E28: 29164 | F28: 35803
A29: of which noncontrolling interests | B29: 5 | C29: 0 | D29: 0 | E29: 0 | F29: 0
A30: Check: assets less liabilities less equity (must be 0) | B30: =B13-B27-B28 | C30: =C13-C27-C28 | D30: =D13-D27-D28 | E30: =E13-E27-E28 | F30: =F13-F27-F28
A31: Shares issued and outstanding at year end (000s) | B31: 442664 | C31: 442793 | D31: 443126 | E31: 443237 | F31: 443266
A33: DERIVED
A34: Total debt (current + long-term) | B34: =B21+B24 | C34: =C21+C24 | D34: =D21+D24 | E34: =E21+E24 | F34: =F21+F24
A35: Cash + short-term investments | B35: =B4+B5 | C35: =C4+C5 | D35: =D4+D5 | E35: =E4+E5 | F35: =F4+F5
A36: Net cash (excl. leases) | B36: =B35-B34 | C36: =C35-C34 | D36: =D35-D34 | E36: =E35-E34 | F36: =F35-F34
A37: Operating net working capital (excl. cash, investments, debt) | B37: =B6+B7+B8-(B23-B21) | C37: =C6+C7+C8-(C23-C21) | D37: =D6+D7+D8-(D23-D21) | E37: =E6+E7+E8-(E23-E21) | F37: =F6+F7+F8-(F23-F21)
A38: Costco stockholders' equity | B38: =B28-B29 | C38: =C28-C29 | D38: =D28-D29 | E38: =E28-E29 | F38: =F28-F29
A39: Invested capital = equity + debt − cash − investments | B39: =B38+B34-B35 | C39: =C38+C34-C35 | D39: =D38+D34-D35 | E39: =E38+E34-E35 | F39: =F38+F34-F35

Sheet Cash Flow
A1: Costco — Cash Flow, FY2022–FY2026
A2: Source: Costco Q4/FY results releases, investor.costco.com (FY2023 incl. FY2022 comparatives; FY2024; FY2026 incl. FY2025). $m except per share.
A3: $ millions | B3: FY2022 | C3: FY2023 | D3: FY2024 | E3: FY2025 | F3: FY2026
A4: Net income including noncontrolling interests | B4: 5915 | C4: 6292 | D4: 7367 | E4: 8099 | F4: 9226
A5: Depreciation and amortization | B5: 1900 | C5: 2077 | D5: 2237 | E5: 2426 | F5: 2674
A6: Stock-based compensation | B6: 724 | C6: 774 | D6: 818 | E6: 860 | F6: 924
A7: Changes in working capital | B7: -1563 | C7: 1018 | D7: 611 | E7: 1764 | F7: 2328
A8: Net cash provided by operating activities | B8: 7392 | C8: 11068 | D8: 11339 | E8: 13335 | F8: 15825
A9: Additions to property and equipment | B9: -3891 | C9: -4323 | D9: -4710 | E9: -5498 | F9: -6435
A10: Cash dividend payments (incl. special) | B10: -1498 | C10: -1251 | D10: -9041 | E10: -2183 | F10: -2458
A11: Repurchases of common stock | B11: -439 | C11: -676 | D11: -700 | E11: -903 | F11: -848
A12: Other operating items (residual) | B12: =B8-B4-B5-B6-B7 | C12: =C8-C4-C5-C6-C7 | D12: =D8-D4-D5-D6-D7 | E12: =E8-E4-E5-E6-E7 | F12: =F8-F4-F5-F6-F7
A13: FREE CASH FLOW = operating cash flow + capex | B13: =B8+B9 | C13: =C8+C9 | D13: =D8+D9 | E13: =E8+E9 | F13: =F8+F9
A14: Cash returned to shareholders | B14: =-(B10+B11) | C14: =-(C10+C11) | D14: =-(D10+D11) | E14: =-(E10+E11) | F14: =-(F10+F11)
A16: FY2024 dividends include the $15.00 special paid January 2024 (~$6.7bn). FY2022 net income includes $71m of noncontrolling interest.
A18: Change in cash and equivalents, balance sheet ($m) | B18: ='Balance Sheet'!B4-B19 | C18: ='Balance Sheet'!C4-'Balance Sheet'!B4 | D18: ='Balance Sheet'!D4-'Balance Sheet'!C4 | E18: ='Balance Sheet'!E4-'Balance Sheet'!D4 | F18: ='Balance Sheet'!F4-'Balance Sheet'!E4
A19: Cash and equivalents at the start of FY2022 ($m) | B19: 11258
A20: Other investing, financing and FX flows = change in cash − FCF + cash returned ($m) | B20: =B18-B13+B14 | C20: =C18-C13+C14 | D20: =D18-D13+D14 | E20: =E18-E13+E14 | F20: =F18-F13+F14
A21: Net cash used in investing activities, reported ($m) | B21: -3915 | C21: -4972 | D21: -4409 | E21: -5311 | F21: -6386
A22: Net cash used in financing activities, reported ($m) | B22: -4283 | C22: -2614 | D22: -10764 | E22: -3775 | F22: -3355
A23: Effect of exchange rates on cash, reported ($m) | B23: -249 | C23: 15 | D23: 40 | E23: 6 | F23: -38
A24: Check: operating + investing + financing + FX less change in cash (must be 0) | B24: =B8+B21+B22+B23-B18 | C24: =C8+C21+C22+C23-C18 | D24: =D8+D21+D22+D23-D18 | E24: =E8+E21+E22+E23-E18 | F24: =F8+F21+F22+F23-F18

Sheet Key Ratios
A1: Costco — Key Ratios, FY2022–FY2026
A2: Every ratio is a formula on the statement sheets.
B3: FY2022 | C3: FY2023 | D3: FY2024 | E3: FY2025 | F3: FY2026
A4: GROWTH
A5: Net sales growth | C5: ='Income Statement'!C4/'Income Statement'!B4-1 | D5: ='Income Statement'!D4/'Income Statement'!C4-1 | E5: ='Income Statement'!E4/'Income Statement'!D4-1 | F5: ='Income Statement'!F4/'Income Statement'!E4-1
A6: Membership fee growth | C6: ='Income Statement'!C5/'Income Statement'!B5-1 | D6: ='Income Statement'!D5/'Income Statement'!C5-1 | E6: ='Income Statement'!E5/'Income Statement'!D5-1 | F6: ='Income Statement'!F5/'Income Statement'!E5-1
A7: Diluted EPS growth (reported) | C7: ='Income Statement'!C18/'Income Statement'!B18-1 | D7: ='Income Statement'!D18/'Income Statement'!C18-1 | E7: ='Income Statement'!E18/'Income Statement'!D18-1 | F7: ='Income Statement'!F18/'Income Statement'!E18-1
A8: THE TWO BUSINESSES — a membership club wrapped round a near-cost retailer
A9: Gross margin on net sales | B9: =1-'Income Statement'!B7/'Income Statement'!B4 | C9: =1-'Income Statement'!C7/'Income Statement'!C4 | D9: =1-'Income Statement'!D7/'Income Statement'!D4 | E9: =1-'Income Statement'!E7/'Income Statement'!E4 | F9: =1-'Income Statement'!F7/'Income Statement'!F4
A10: SG&A as % of net sales | B10: ='Income Statement'!B8/'Income Statement'!B4 | C10: ='Income Statement'!C8/'Income Statement'!C4 | D10: ='Income Statement'!D8/'Income Statement'!D4 | E10: ='Income Statement'!E8/'Income Statement'!E4 | F10: ='Income Statement'!F8/'Income Statement'!F4
A11: Operating margin on total revenue | B11: ='Income Statement'!B9/'Income Statement'!B6 | C11: ='Income Statement'!C9/'Income Statement'!C6 | D11: ='Income Statement'!D9/'Income Statement'!D6 | E11: ='Income Statement'!E9/'Income Statement'!E6 | F11: ='Income Statement'!F9/'Income Statement'!F6
A12: Membership fees as % of operating income | B12: ='Income Statement'!B5/'Income Statement'!B9 | C12: ='Income Statement'!C5/'Income Statement'!C9 | D12: ='Income Statement'!D5/'Income Statement'!D9 | E12: ='Income Statement'!E5/'Income Statement'!E9 | F12: ='Income Statement'!F5/'Income Statement'!F9
A13: Merchandise operating profit = operating income − fees ($m) | B13: ='Income Statement'!B9-'Income Statement'!B5 | C13: ='Income Statement'!C9-'Income Statement'!C5 | D13: ='Income Statement'!D9-'Income Statement'!D5 | E13: ='Income Statement'!E9-'Income Statement'!E5 | F13: ='Income Statement'!F9-'Income Statement'!F5
A14: Merchandise operating margin on net sales | B14: =('Income Statement'!B9-'Income Statement'!B5)/'Income Statement'!B4 | C14: =('Income Statement'!C9-'Income Statement'!C5)/'Income Statement'!C4 | D14: =('Income Statement'!D9-'Income Statement'!D5)/'Income Statement'!D4 | E14: =('Income Statement'!E9-'Income Statement'!E5)/'Income Statement'!E4 | F14: =('Income Statement'!F9-'Income Statement'!F5)/'Income Statement'!F4
A15: Net margin on total revenue | B15: ='Income Statement'!B15/'Income Statement'!B6 | C15: ='Income Statement'!C15/'Income Statement'!C6 | D15: ='Income Statement'!D15/'Income Statement'!D6 | E15: ='Income Statement'!E15/'Income Statement'!E6 | F15: ='Income Statement'!F15/'Income Statement'!F6
A16: Effective tax rate | B16: ='Income Statement'!B13/'Income Statement'!B12 | C16: ='Income Statement'!C13/'Income Statement'!C12 | D16: ='Income Statement'!D13/'Income Statement'!D12 | E16: ='Income Statement'!E13/'Income Statement'!E12 | F16: ='Income Statement'!F13/'Income Statement'!F12
A17: RETURNS AND CASH
A18: Return on average Costco equity | C18: ='Income Statement'!C15/AVERAGE('Balance Sheet'!C38,'Balance Sheet'!B38) | D18: ='Income Statement'!D15/AVERAGE('Balance Sheet'!D38,'Balance Sheet'!C38) | E18: ='Income Statement'!E15/AVERAGE('Balance Sheet'!E38,'Balance Sheet'!D38) | F18: ='Income Statement'!F15/AVERAGE('Balance Sheet'!F38,'Balance Sheet'!E38)
A19: Return on invested capital (after-tax op. income ÷ year-end invested capital) | B19: ='Income Statement'!B9*(1-'Income Statement'!B13/'Income Statement'!B12)/'Balance Sheet'!B39 | C19: ='Income Statement'!C9*(1-'Income Statement'!C13/'Income Statement'!C12)/'Balance Sheet'!C39 | D19: ='Income Statement'!D9*(1-'Income Statement'!D13/'Income Statement'!D12)/'Balance Sheet'!D39 | E19: ='Income Statement'!E9*(1-'Income Statement'!E13/'Income Statement'!E12)/'Balance Sheet'!E39 | F19: ='Income Statement'!F9*(1-'Income Statement'!F13/'Income Statement'!F12)/'Balance Sheet'!F39
A20: Free cash flow ($m) | B20: ='Cash Flow'!B13 | C20: ='Cash Flow'!C13 | D20: ='Cash Flow'!D13 | E20: ='Cash Flow'!E13 | F20: ='Cash Flow'!F13
A21: Free cash flow ÷ net income | B21: ='Cash Flow'!B13/'Income Statement'!B15 | C21: ='Cash Flow'!C13/'Income Statement'!C15 | D21: ='Cash Flow'!D13/'Income Statement'!D15 | E21: ='Cash Flow'!E13/'Income Statement'!E15 | F21: ='Cash Flow'!F13/'Income Statement'!F15
A22: Capex as % of net sales | B22: =-'Cash Flow'!B9/'Income Statement'!B4 | C22: =-'Cash Flow'!C9/'Income Statement'!C4 | D22: =-'Cash Flow'!D9/'Income Statement'!D4 | E22: =-'Cash Flow'!E9/'Income Statement'!E4 | F22: =-'Cash Flow'!F9/'Income Statement'!F4
A23: D&A as % of net sales | B23: ='Cash Flow'!B5/'Income Statement'!B4 | C23: ='Cash Flow'!C5/'Income Statement'!C4 | D23: ='Cash Flow'!D5/'Income Statement'!D4 | E23: ='Cash Flow'!E5/'Income Statement'!E4 | F23: ='Cash Flow'!F5/'Income Statement'!F4
A24: Operating net working capital as % of net sales (negative = suppliers fund it) | B24: ='Balance Sheet'!B37/'Income Statement'!B4 | C24: ='Balance Sheet'!C37/'Income Statement'!C4 | D24: ='Balance Sheet'!D37/'Income Statement'!D4 | E24: ='Balance Sheet'!E37/'Income Statement'!E4 | F24: ='Balance Sheet'!F37/'Income Statement'!F4
A25: Dividend payout incl. specials (÷ net income) | B25: =-'Cash Flow'!B10/'Income Statement'!B15 | C25: =-'Cash Flow'!C10/'Income Statement'!C15 | D25: =-'Cash Flow'!D10/'Income Statement'!D15 | E25: =-'Cash Flow'!E10/'Income Statement'!E15 | F25: =-'Cash Flow'!F10/'Income Statement'!F15
A26: Net cash ($m) | B26: ='Balance Sheet'!B36 | C26: ='Balance Sheet'!C36 | D26: ='Balance Sheet'!D36 | E26: ='Balance Sheet'!E36 | F26: ='Balance Sheet'!F36
A27: Diluted share count drift vs FY2022 | B27: ='Income Statement'!B16/'Income Statement'!B16-1 | C27: ='Income Statement'!C16/'Income Statement'!B16-1 | D27: ='Income Statement'!D16/'Income Statement'!B16-1 | E27: ='Income Statement'!E16/'Income Statement'!B16-1 | F27: ='Income Statement'!F16/'Income Statement'!B16-1
A28: Operating income growth | C28: ='Income Statement'!C9/'Income Statement'!B9-1 | D28: ='Income Statement'!D9/'Income Statement'!C9-1 | E28: ='Income Statement'!E9/'Income Statement'!D9-1 | F28: ='Income Statement'!F9/'Income Statement'!E9-1

Sheet Forecast
A1: Forecast FY2027E–FY2036E — Costco modelled as two businesses: membership fees + a near-cost merchandise operation
A2: Blue = driver. FY2026A column is RECURRING (tariff-refund benefit removed). Every FY2027E+ line is a formula on its drivers.
B3: FY2026A | C3: FY2027E | D3: FY2028E | E3: FY2029E | F3: FY2030E | G3: FY2031E | H3: FY2032E | I3: FY2033E | J3: FY2034E | K3: FY2035E | L3: FY2036E
A4: Net sales growth | B4: ='Key Ratios'!F5 | C4: 0.08 | D4: 0.075 | E4: 0.07 | F4: 0.065 | G4: 0.06 | H4: 0.055 | I4: 0.0525 | J4: 0.05 | K4: 0.0475 | L4: 0.045
A5: Net sales ($m) | B5: ='Income Statement'!F4 | C5: =B5*(1+C4) | D5: =C5*(1+D4) | E5: =D5*(1+E4) | F5: =E5*(1+F4) | G5: =F5*(1+G4) | H5: =G5*(1+H4) | I5: =H5*(1+I4) | J5: =I5*(1+J4) | ... L5: =K5*(1+L4)
A6: Membership fee growth | B6: ='Key Ratios'!F6 | C6: 0.065 | D6: 0.065 | E6: 0.065 | F6: 0.065 | G6: 0.09 | H6: 0.06 | I6: 0.06 | J6: 0.055 | K6: 0.055 | L6: 0.05
A7: Membership fees ($m) | B7: ='Income Statement'!F5 | C7: =B7*(1+C6) | D7: =C7*(1+D6) | E7: =D7*(1+E6) | F7: =E7*(1+F6) | G7: =F7*(1+G6) | H7: =G7*(1+H6) | I7: =H7*(1+I6) | J7: =I7*(1+J6) | ... L7: =K7*(1+L6)
A8: Total revenue ($m) | B8: =B5+B7 | C8: =C5+C7 | D8: =D5+D7 | E8: =E5+E7 | F8: =F5+F7 | G8: =G5+G7 | H8: =H5+H7 | I8: =I5+I7 | ... L8: =L5+L7
A9: Merchandise margin step (pp per year) | C9: 0.0006 | D9: 0.0006 | E9: 0.0006 | F9: 0.0006 | G9: 0.0006 | H9: 0.0003 | I9: 0.0003 | J9: 0.0003 | K9: 0.0003 | L9: 0.0003
A10: Merchandise operating margin on net sales | B10: =('Income Statement'!F26-'Income Statement'!F5)/'Income Statement'!F4 | C10: =B10+C9 | D10: =C10+D9 | E10: =D10+E9 | F10: =E10+F9 | G10: =F10+G9 | H10: =G10+H9 | I10: =H10+I9 | J10: =I10+J9 | ... L10: =K10+L9
A11: Merchandise operating profit ($m) | B11: =B5*B10 | C11: =C5*C10 | D11: =D5*D10 | E11: =E5*E10 | F11: =F5*F10 | G11: =G5*G10 | H11: =H5*H10 | I11: =I5*I10 | ... L11: =L5*L10
A12: Operating income ($m) | B12: =B11+B7 | C12: =C11+C7 | D12: =D11+D7 | E12: =E11+E7 | F12: =F11+F7 | G12: =G11+G7 | H12: =H11+H7 | I12: =I11+I7 | ... L12: =L11+L7
A13: Operating margin on total revenue | B13: =B12/B8 | C13: =C12/C8 | D13: =D12/D8 | E13: =E12/E8 | F13: =F12/F8 | G13: =G12/G8 | H13: =H12/H8 | I13: =I12/I8 | ... L13: =L12/L8
A14: Membership fees as % of operating income | B14: =B7/B12 | C14: =C7/C12 | D14: =D7/D12 | E14: =E7/E12 | F14: =F7/F12 | G14: =G7/G12 | H14: =H7/H12 | I14: =I7/I12 | ... L14: =L7/L12
A15: Interest income and other growth | C15: 0.03 | D15: 0.03 | E15: 0.03 | F15: 0.03 | G15: 0.03 | H15: 0.03 | I15: 0.03 | J15: 0.03 | K15: 0.03 | L15: 0.03
A16: Interest income and other, net ($m) | B16: ='Income Statement'!F11 | C16: =B16*(1+C15) | D16: =C16*(1+D15) | E16: =D16*(1+E15) | F16: =E16*(1+F15) | G16: =F16*(1+G15) | H16: =G16*(1+H15) | I16: =H16*(1+I15) | J16: =I16*(1+J15) | ... L16: =K16*(1+L15)
A17: Interest expense ($m) | B17: ='Income Statement'!F10 | C17: =B17 | D17: =C17 | E17: =D17 | F17: =E17 | G17: =F17 | H17: =G17 | I17: =H17 | J17: =I17 | ... L17: =K17
A18: Income before taxes ($m) | B18: =B12+B16+B17 | C18: =C12+C16+C17 | D18: =D12+D16+D17 | E18: =E12+E16+E17 | F18: =F12+F16+F17 | G18: =G12+G16+G17 | H18: =H12+H16+H17 | I18: =I12+I16+I17 | ... L18: =L12+L16+L17
A19: Tax rate | B19: ='Key Ratios'!F16 | C19: 0.247 | D19: 0.247 | E19: 0.247 | F19: 0.247 | G19: 0.247 | H19: 0.247 | I19: 0.247 | J19: 0.247 | K19: 0.247 | L19: 0.247
A20: Net income ($m) | B20: =B18*(1-B19) | C20: =C18*(1-C19) | D20: =D18*(1-D19) | E20: =E18*(1-E19) | F20: =F18*(1-F19) | G20: =G18*(1-G19) | H20: =H18*(1-H19) | I20: =I18*(1-I19) | ... L20: =L18*(1-L19)
A21: Diluted shares (m) | B21: ='Income Statement'!F16/1000 | C21: =B21 | D21: =C21 | E21: =D21 | F21: =E21 | G21: =F21 | H21: =G21 | I21: =H21 | J21: =I21 | ... L21: =K21
A22: Diluted EPS ($) | B22: =B20/B21 | C22: =C20/C21 | D22: =D20/D21 | E22: =E20/E21 | F22: =F20/F21 | G22: =G20/G21 | H22: =H20/H21 | I22: =I20/I21 | ... L22: =L20/L21
A23: EPS growth (FY2027E vs recurring FY2026) | C23: =C22/'Income Statement'!F27-1 | D23: =D22/C22-1 | E23: =E22/D22-1 | F23: =F22/E22-1 | G23: =G22/F22-1 | H23: =H22/G22-1 | I23: =I22/H22-1 | J23: =J22/I22-1 | K23: =K22/J22-1 | L23: =L22/K22-1
A24: D&A as % of net sales | B24: ='Key Ratios'!F23 | C24: 0.009 | D24: 0.009 | E24: 0.009 | F24: 0.009 | G24: 0.009 | H24: 0.009 | I24: 0.009 | J24: 0.009 | K24: 0.009 | L24: 0.009
A25: D&A ($m) | B25: ='Cash Flow'!F5 | C25: =C5*C24 | D25: =D5*D24 | E25: =E5*E24 | F25: =F5*F24 | G25: =G5*G24 | H25: =H5*H24 | I25: =I5*I24 | J25: =J5*J24 | ... L25: =L5*L24
A26: EBITDA ($m) | B26: =B12+B25 | C26: =C12+C25 | D26: =D12+D25 | E26: =E12+E25 | F26: =F12+F25 | G26: =G12+G25 | H26: =H12+H25 | I26: =I12+I25 | ... L26: =L12+L25
A27: Capex as % of net sales | B27: ='Key Ratios'!F22 | C27: =Overview!B23/C5 | D27: 0.0225 | E27: 0.022 | F27: 0.0215 | G27: 0.021 | H27: 0.0205 | I27: 0.02 | J27: 0.0195 | K27: 0.019 | L27: 0.019
A28: Capex ($m) | B28: =-'Cash Flow'!F9 | C28: =C5*C27 | D28: =D5*D27 | E28: =E5*E27 | F28: =F5*F27 | G28: =G5*G27 | H28: =H5*H27 | I28: =I5*I27 | J28: =J5*J27 | ... L28: =L5*L27
A29: Operating NWC as % of net sales (held at FY2026) | B29: ='Key Ratios'!F24 | C29: =$B$29 | D29: =$B$29 | E29: =$B$29 | F29: =$B$29 | G29: =$B$29 | H29: =$B$29 | I29: =$B$29 | J29: =$B$29 | ... L29: =$B$29
A30: Operating NWC ($m) | B30: =B5*B29 | C30: =C5*C29 | D30: =D5*D29 | E30: =E5*E29 | F30: =F5*F29 | G30: =G5*G29 | H30: =H5*H29 | I30: =I5*I29 | ... L30: =L5*L29
A31: Cash released by working capital ($m) | C31: =-(C30-B30) | D31: =-(D30-C30) | E31: =-(E30-D30) | F31: =-(F30-E30) | G31: =-(G30-F30) | H31: =-(H30-G30) | I31: =-(I30-H30) | J31: =-(J30-I30) | ... L31: =-(L30-K30)
A32: NOPAT = operating income × (1 − tax) ($m) | B32: =B12*(1-B19) | C32: =C12*(1-C19) | D32: =D12*(1-D19) | E32: =E12*(1-E19) | F32: =F12*(1-F19) | G32: =G12*(1-G19) | H32: =H12*(1-H19) | I32: =I12*(1-I19) | ... L32: =L12*(1-L19)
A33: FREE CASH FLOW TO FIRM ($m) | C33: =C32+C25-C28+C31 | D33: =D32+D25-D28+D31 | E33: =E32+E25-E28+E31 | F33: =F32+F25-F28+F31 | G33: =G32+G25-G28+G31 | H33: =H32+H25-H28+H31 | I33: =I32+I25-I28+I31 | J33: =J32+J25-J28+J31 | ... L33: =L32+L25-L28+L31
A34: FCFF ÷ NOPAT | C34: =C33/C32 | D34: =D33/D32 | E34: =E33/E32 | F34: =F33/F32 | G34: =G33/G32 | H34: =H33/H32 | I34: =I33/I32 | J34: =J33/J32 | ... L34: =L33/L32
A36: HOW THE DRIVERS WERE SET
A37: Net sales +8.0% in FY2027: FY2026 comps ex gas and FX were 6.6%, and 28 net new warehouses in FY2027 (3.0% of the base, less productive at first) add ~1.5pp; we do NOT
A38: extrapolate the ~3pp gas-price lift to Q4. Fades 0.5pp a year to 5.5% in FY2032, then 0.25pp a year to 4.5% by FY2036.
A39: Membership fees +6.5%: Q4 fee growth ex the fee increase and FX was 6.8%, and Q4 FY2026 was the last quarter carrying the Sep-2024 increase. FY2031 carries +9.0% for
A40: the next fee increase — the last five came every 5–7 years (2000, 2006, 2011, 2017, 2024). Best estimate, not a haircut.
A41: Merchandise margin +6bp a year to FY2031 (it rose from 1.49% in FY2023 to 1.91% recurring in FY2026), then +3bp. Operating margin on revenue reaches the level in row
...

Sheet DCF
A1: Method 1 — FCFF DCF at WACC (unlevered cash flow ↔ WACC)
A2: Valuation date 16-Oct-2026. Mid-year convention: FY2027 cash flow centred on 1-Mar-2027, 0.373 years out.
A3: DISCOUNT RATE
A4: Risk-free — US 10-yr Treasury, 16-Oct-2026 | B4: =Overview!B17
A5: Beta | B5: =Overview!B16
A6: Equity risk premium | B6: =Overview!B18
A7: COST OF EQUITY | B7: =B4+B5*B6
A8: Credit spread over Treasuries | B8: 0.005 | D8: Costco is rated Aa3/A+; ~50bp is a long-dated single-A/AA spread
A9: Pre-tax cost of debt | B9: =B4+B8
A10: Tax rate | B10: =Forecast!C19
A11: Market capitalisation ($m) | B11: =Overview!B8
A12: Debt ($m) | B12: ='Balance Sheet'!F34
A13: Equity weight | B13: =B11/(B11+B12)
A14: WACC | B14: =B13*B7+(1-B13)*B9*(1-B10)
A16: CASH FLOWS ($m)
C17: FY2027E | D17: FY2028E | E17: FY2029E | F17: FY2030E | G17: FY2031E | H17: FY2032E | I17: FY2033E | J17: FY2034E | K17: FY2035E | L17: FY2036E
A18: Free cash flow to firm | C18: =Forecast!C33 | D18: =Forecast!D33 | E18: =Forecast!E33 | F18: =Forecast!F33 | G18: =Forecast!G33 | H18: =Forecast!H33 | I18: =Forecast!I33 | J18: =Forecast!J33 | ... L18: =Forecast!L33
A19: Years from valuation date (mid-year) | C19: 0.373 | D19: =C19+1 | E19: =D19+1 | F19: =E19+1 | G19: =F19+1 | H19: =G19+1 | I19: =H19+1 | J19: =I19+1 | K19: =J19+1 | L19: =K19+1
A20: Discount factor | C20: =1/(1+$B$14)^C19 | D20: =1/(1+$B$14)^D19 | E20: =1/(1+$B$14)^E19 | F20: =1/(1+$B$14)^F19 | G20: =1/(1+$B$14)^G19 | H20: =1/(1+$B$14)^H19 | I20: =1/(1+$B$14)^I19 | J20: =1/(1+$B$14)^J19 | ... L20: =1/(1+$B$14)^L19
A21: Present value | C21: =C18*C20 | D21: =D18*D20 | E21: =E18*E20 | F21: =F18*F20 | G21: =G18*G20 | H21: =H18*H20 | I21: =I18*I20 | J21: =J18*J20 | ... L21: =L18*L20
A23: TERMINAL VALUE — growth and reinvestment tied (g = RONIC × reinvestment rate)
A24: Sum of PV, FY2027E–FY2036E | B24: =SUM(C21:L21)
A25: Terminal growth | B25: 0.04 | D25: below the 5.09% risk-free; ~US long-run nominal growth
A26: Return on new invested capital in perpetuity | B26: 0.3 | D26: ROIC was ~43% in FY2026 (Key Ratios); faded, as new-market warehouses mature slowly
A27: Reinvestment rate = g ÷ RONIC | B27: =B25/B26
A28: FY2037 NOPAT ($m) | B28: =Forecast!L32*(1+B25)
A29: Terminal FCFF ($m) | B29: =B28*(1-B27) | D29: FCFF/NOPAT steps from FY2036's level (Forecast row 34) to 1 − g/RONIC here; row 49 holds it flat
A30: Terminal value at mid-FY2036 ($m) | B30: =B29/(B14-B25)
A31: Discount period for terminal value (mid-year) | B31: =L19
A32: PV of terminal value ($m) | B32: =B30/(1+B14)^B31
A33: ENTERPRISE VALUE ($m) | B33: =B24+B32
A34: Terminal share of enterprise value | B34: =B32/B33
A35: Implied terminal value ÷ FY2036E NOPAT (x) | B35: =B30/Forecast!L32
A36: Plus cash and short-term investments ($m) | B36: ='Balance Sheet'!F35 | D36: Interest income ran ~3.3% on this cash, below the 10-yr — worth about carrying value, no premium
A37: Less debt ($m) | B37: =-B12 | D37: Finance-lease liabilities sit inside other liabilities and are not split out in the release; not deducted
A38: Equity value ($m) | B38: =B33+B36+B37
A39: Diluted shares (m), FY2026 weighted average | B39: =Forecast!B21
A40: METHOD 1 — DCF VALUE PER SHARE ($) | B40: =B38/B39
A41: vs price | B41: =B40/Overview!B6-1
A43: WHAT THE PRICE IMPLIES
...

Sheet Valuation
A1: Valuation — Walmart-relative methods lead; Costco's own history and the DCF are zero-weight cross-checks
A3: COST OF EQUITY AND HURDLES
A4: Risk-free — US 10-yr Treasury, 16-Oct-2026 | B4: =DCF!B4
A5: Beta | B5: =DCF!B5
A6: Equity risk premium | B6: =DCF!B6
A7: COST OF EQUITY (BUY hurdle) | B7: =B4+B5*B6
A8: ACCUMULATE hurdle (10-yr + 2pp) | B8: =B4+B9
A9: ACCUMULATE spread over the 10-yr (house rule) | B9: 0.02
A10: KEY INPUTS
A11: Live price ($) | B11: =Overview!B6
A12: Diluted shares (m) | B12: =Forecast!B21
A13: FY2027E EPS ($) | B13: =Forecast!C22
A14: FY2026 EBITDA, reported ($m) — Costco's multiple is computed on this same basis (row 32); Walmart's is the vendor's | B14: ='Income Statement'!F9+'Cash Flow'!F5
A15: Net cash less lease liabilities ($m) — matches the peer EV definition | B15: ='Balance Sheet'!F35-'Balance Sheet'!F34-'Balance Sheet'!F25
A16: Dividend yield | B16: =Overview!B13
A17: Share of Costco's current premium to Walmart retained | B17: 1 | D17: Peers & Street rows 81–91: today's premium is the series low (62% at the Oct-2023 yield peak) — no basis for a haircut
A18: METHOD 1 — FCFF DCF (shown as a FLOOR, 0% weight — house method for staples)
A19: METHOD 1 — VALUE PER SHARE ($) | B19: =DCF!B40
A21: METHOD 2 — FORWARD P/E vs WALMART, TODAY'S PREMIUM KEPT (two-thirds weight)
A22: Walmart forward P/E (x) | B22: ='Peers & Street'!F6 | D22: same vendor, same day as Costco's own (next row)
A23: Costco forward P/E on consensus FY2027 EPS (x) | B23: ='Peers & Street'!F5
A24: Forward P/E applied = Walmart + retained share × (Costco − Walmart) (x) | B24: =B22+B17*(B23-B22)
A25: METHOD 2 — VALUE PER SHARE ($) | B25: =B24*B13
A26: Forward P/E at which Method 2 equals the price (x) | B26: =B11/B13
A28: METHOD 3 — EV/EBITDA vs WALMART, TODAY'S PREMIUM KEPT (one-third weight)
A29: Walmart EV/EBITDA, trailing (x) | B29: ='Peers & Street'!G6
A30: EV/EBITDA applied = Walmart + retained share × (Costco − Walmart) (x) | B30: =B29+B17*('Peers & Street'!G5-B29)
A31: METHOD 3 — VALUE PER SHARE ($) | B31: =(B30*B14+B15)/B12
A32: EV/EBITDA at which Method 3 equals the price (x) | B32: =(B11*B12-B15)/B14
A34: BLENDED VALUATION AND RATING
A35: Method | B35: Value/share ($) | C35: vs price | D35: Weight
A36: FCFF DCF at WACC | B36: =B19 | C36: =B36/$B$11-1 | D36: 0
A37: Forward P/E vs Walmart, premium kept | B37: =B25 | C37: =B37/$B$11-1 | D37: 0.6667
A38: EV/EBITDA vs Walmart, premium kept | B38: =B31 | C38: =B38/$B$11-1 | D38: 0.3333
A39: Costco's own P/E, Oct-2023 yield-peak window (cross-check) | B39: ='Peers & Street'!B91*'Income Statement'!F27 | C39: =B39/$B$11-1 | D39: 0
A40: BLENDED FAIR VALUE ($) | B40: =SUMPRODUCT(B36:B39,D36:D39)
A41: Upside / (downside) | B41: =B40/B11-1
A42: Add: dividend yield | B42: =B16
A43: TOTAL EXPECTED RETURN | B43: =B41+B42
A44: RATING | B44: =IF(D44<>"",D44,C44) | C44: =IF(B43>B7,"BUY",IF(B43>B8,"ACCUMULATE",IF(B43>0,"HOLD","REDUCE"))) | D44: HOLD | E44: ="C44 = band rating ("&C44&"); D44 = analyst override. One reason: HOLD needs FY2027 EPS of $"&TEXT('Stress Tests'!B45,"0.00")&" against our $"&TEXT(B13,"0.00")&", a "&TEXT('Stress Tests'!B46,"0.0%")&" gap inside our "&TEXT(ABS('Peers & Street'!B60),"0.0%")&" shortfall to consensus (Stress Tests rows 42, 45–46). Row 46 is reference only."
...

Sheet Stress Tests
A1: Stress tests — the best argument against the call, 12-month view, conservatism check and break-evens
A3: THE BEST ARGUMENT AGAINST THIS CALL — if the multiple simply holds
A4: Our FY2028E EPS growth | B4: =Forecast!D23
A5: One-year return if today's forward multiple holds (our EPS) = growth + dividend yield | B5: =B4+Valuation!B16
A6: Rating that return would earn | B6: =IF(B5>Valuation!B7,"BUY",IF(B5>Valuation!B8,"ACCUMULATE",IF(B5>0,"HOLD","REDUCE")))
A7: Consensus FY2028 EPS growth (S&P Global) | B7: ='Peers & Street'!B24/'Peers & Street'!B23-1
A8: One-year return if the multiple holds (consensus EPS) | B8: =B7+Valuation!B16
A9: Rating that return would earn | B9: =IF(B8>Valuation!B7,"BUY",IF(B8>Valuation!B8,"ACCUMULATE",IF(B8>0,"HOLD","REDUCE")))
A10: Best total return anywhere in the 16-cell grid | B10: =MAX(Valuation!B69:E72)
A11: Grid cells with a positive total return | B11: =COUNTIF(Valuation!B69:E72,">0")
A12: 12-month price target = fair value × (1 + cost of equity) − regular dividend ($) | B12: =Valuation!B40*(1+Valuation!B7)-Overview!B12
A13: 12-month price target vs price (price return; the rating test uses row 46) | B13: =B12/Valuation!B11-1
A14: Damodaran implied US ERP, 1-Jan-2026 | B14: 0.0423
A15: CONSERVATISM CHECK — the prudent inputs, reversed one at a time and then together
A16: WACC with ERP at Damodaran's 4.23% (1-Jan-2026) | B16: =DCF!B13*(DCF!B4+DCF!B5*$B$14)+(1-DCF!B13)*DCF!B9*(1-DCF!B10)
A17: DCF at that WACC ($) | B17: =((SUMPRODUCT(DCF!$C$18:$L$18,1/(1+$B$16)^DCF!$C$19:$L$19)+Forecast!$L$32*(1+DCF!$B$25)*(1-DCF!$B$25/DCF!$B$26)/($B$16-DCF!$B$25)/(1+$B$16)^DCF!$B$31+DCF!$B$36+DCF!$B$37)/DCF!$B$39) | D17: DCF has 0% weight: moves the floor, not fair value
A18: DCF with RONIC at FY2026's actual ROIC ($) | B18: =((SUMPRODUCT(DCF!$C$18:$L$18,1/(1+DCF!$B$14)^DCF!$C$19:$L$19)+Forecast!$L$32*(1+DCF!$B$25)*(1-DCF!$B$25/'Key Ratios'!$F$19)/(DCF!$B$14-DCF!$B$25)/(1+DCF!$B$14)^DCF!$B$31+DCF!$B$36+DCF!$B$37)/DCF!$B$39) | D18: DCF has 0% weight: moves the floor, not fair value
A19: Method 2 on consensus FY2027 EPS ($) | B19: =Valuation!B24*'Peers & Street'!B23
A20: All prudent inputs reversed — blended fair value ($) | B20: =Valuation!D36*((SUMPRODUCT(DCF!$C$18:$L$18,1/(1+$B$16)^DCF!$C$19:$L$19)+Forecast!$L$32*(1+DCF!$B$25)*(1-DCF!$B$25/'Key Ratios'!$F$19)/($B$16-DCF!$B$25)/(1+$B$16)^DCF!$B$31+DCF!$B$36+DCF!$B$37)/DCF!$B$39)+Valuation!D37*B19+Valuation!D38*Valuation!B31+Valuation!D39*Valuation!B39
A21: All prudent inputs reversed — total return | B21: =B20/Valuation!B11-1+Valuation!B16
A22: All prudent inputs reversed — rating | B22: =IF(B21>Valuation!B7,"BUY",IF(B21>Valuation!B8,"ACCUMULATE",IF(B21>0,"HOLD","REDUCE")))
A23: Blended fair value ÷ FY2027E EPS (x) — the multiple our fair value implies | B23: =Valuation!B40/Valuation!B13
A24: Our fair value's premium (+) or discount (−) to Walmart's forward multiple | B24: =B23/Valuation!B22-1
A25: Premium share at which the 12-month total return reaches zero | B25: =(Valuation!B11/(1+Valuation!B7)-Valuation!B61)/(Valuation!B64-Valuation!B61) | C25: =IF(ABS((Valuation!D37*(Valuation!B22+B25*(Valuation!B23-Valuation!B22))*Valuation!B13+Valuation!D38*((Valuation!B29+B25*('Peers & Street'!G5-Valuation!B29))*Valuation!B14+Valuation!B15)/Valuation!B12+Valuation!D39*Valuation!B39)/(Valuation!D37+Valuation!D38+Valuation!D39)*(1+Valuation!B7)/Valuation!B11-1)<0.0005,"PASS","FAIL")
A26: Premium share at which the total return on the RATING basis (row 43) reaches zero — HOLD needs more than this | B26: =(Valuation!B11*(1-Valuation!B16)-Valuation!B61)/(Valuation!B64-Valuation!B61) | C26: =IF(ABS((Valuation!D37*(Valuation!B22+B26*(Valuation!B23-Valuation!B22))*Valuation!B13+Valuation!D38*((Valuation!B29+B26*('Peers & Street'!G5-Valuation!B29))*Valuation!B14+Valuation!B15)/Valuation!B12+Valuation!D39*Valuation!B39)/(Valuation!D37+Valuation!D38+Valuation!D39)/Valuation!B11-1+Valuation!B16)<0.0005,"PASS","FAIL")
A27: 12-month total return on consensus FY2027 EPS (base weights) | B27: =Valuation!E64*(1+Valuation!B7)/Valuation!B11-1
A28: Share of the gap to price supplied by Method 2 (forward P/E) | B28: =Valuation!D37*(Valuation!B37-Valuation!B11)/(Valuation!B40-Valuation!B11)
A29: Share of the gap to price supplied by Method 3 (EV/EBITDA) | B29: =Valuation!D38*(Valuation!B38-Valuation!B11)/(Valuation!B40-Valuation!B11)
A30: Share of the gap to price supplied by Method 4 (own P/E, Oct-2023 window; 0% weight) | B30: =Valuation!D39*(Valuation!B39-Valuation!B11)/(Valuation!B40-Valuation!B11)
A31: Fair value vs the base grid cell (must be 0 at base weights) | B31: =Valuation!B40/Valuation!B64-1
A32: Forward P/E on FY2028E EPS at which the 12-month total return is zero (x) | B32: =(Valuation!B11-Overview!B12)/Forecast!D22
A33: vs Costco's forward P/E today on our FY2027E EPS (same basis) | B33: =B32/(Valuation!B11/Valuation!B13)-1
A34: Walmart P/E on its fiscal year to Jan-2027 (consensus EPS $2.89, stockanalysis; price 16-Oct-2026) (x) | B34: ='Peers & Street'!F89/2.89
A35: Method 2 with Walmart on that basis ($) — no effect while 100% of the premium is kept | B35: =(B34+Valuation!B17*(Valuation!B23-B34))*Valuation!B13
A36: Blended fair value with Walmart on that basis ($) — unchanged by construction at 100% kept | B36: =Valuation!D36*Valuation!B36+Valuation!D37*B35+Valuation!D38*Valuation!B38+Valuation!D39*Valuation!B39
A37: total return | B37: =B36/Valuation!B11-1+Valuation!B16
A38: Method 3 on recurring (ex tariff refund) EBITDA ($) | B38: =(Valuation!B30*Forecast!B26+Valuation!B15)/Valuation!B12
A39: Today's multiples alone (100% premium kept, our EPS, 0% DCF): total return | B39: =Valuation!B64/Valuation!B11-1+Valuation!B16
A41: WHY HOLD — the analyst override in Valuation!D44 (band rating REDUCE). One reason: the shortfall is smaller than our EPS gap to consensus
A42: Total return, spot basis, on consensus FY2027 EPS (base weights) | B42: =Valuation!E64/Valuation!B11-1+Valuation!B16
...

Sheet Scenarios
A1: Scenarios — Bear / Base / Bull, each a full re-computation of all three methods
A2: Base = every driver with zero deltas; must equal the blended fair value (checked on Valuation).
C4: Bear | D4: Base | E4: Bull
A5: Net sales growth delta, every year (pp) | C5: -0.015 | D5: 0 | E5: 0.015
A6: Membership fee growth delta, every year (pp) | C6: -0.01 | D6: 0 | E6: 0.01
A7: Merchandise margin step multiplier (× the base step, every year) | C7: 0.5 | D7: 1 | E7: 1.5
A8: WACC delta (pp) | C8: 0.005 | D8: 0 | E8: -0.005
A9: Terminal growth | C9: 0.035 | D9: =DCF!B25 | E9: 0.045
A10: Forward P/E applied (x) | C10: =Valuation!B22 | D10: =Valuation!B22+Valuation!B17*('Peers & Street'!F5-Valuation!B22) | E10: ='Peers & Street'!F5
A11: EV/EBITDA applied (x) | C11: =Valuation!B29 | D11: =Valuation!B29+Valuation!B17*('Peers & Street'!G5-Valuation!B29) | E11: ='Peers & Street'!G5
A12: Bear: sales −1.5pp, fees −1pp, margin steps halved, WACC +0.5pp, g 3.5%, Walmart multiples, own P/E at its 5-yr low. Bull: the reverse, with today's multiples.
A13: Costco's own trailing P/E applied (x) — bear: 5-yr year-end low; base: Oct-2023 window (0% weight); bull: today's | C13: ='Peers & Street'!B74 | D13: ='Peers & Street'!B91 | E13: =Overview!B19
A14: WACC | C14: =DCF!B14+C8 | D14: =DCF!B14+D8 | E14: =DCF!B14+E8
A15: Sum of PV, FY2027E–FY2036E ($m) | C15: =SUM(C44:L44) | D15: =SUM(C60:L60) | E15: =SUM(C76:L76)
A16: Terminal value ($m) | C16: =L38*(1+C9)*(1-C9/DCF!B26)/(C14-C9) | D16: =L54*(1+D9)*(1-D9/DCF!B26)/(D14-D9) | E16: =L70*(1+E9)*(1-E9/DCF!B26)/(E14-E9)
A17: PV of terminal value ($m) | C17: =C16/(1+C14)^DCF!B31 | D17: =D16/(1+D14)^DCF!B31 | E17: =E16/(1+E14)^DCF!B31
A18: Equity value ($m) | C18: =C15+C17+DCF!B36+DCF!B37 | D18: =D15+D17+DCF!B36+DCF!B37 | E18: =E15+E17+DCF!B36+DCF!B37
A19: Method 1 — DCF per share ($) | C19: =C18/Valuation!B12 | D19: =D18/Valuation!B12 | E19: =E18/Valuation!B12
A20: FY2027E EPS ($) | C20: =(C37+Forecast!C16+Forecast!C17)*(1-Forecast!C19)/Forecast!C21 | D20: =(C53+Forecast!C16+Forecast!C17)*(1-Forecast!C19)/Forecast!C21 | E20: =(C69+Forecast!C16+Forecast!C17)*(1-Forecast!C19)/Forecast!C21
A21: Method 2 — P/E per share ($) | C21: =C10*C20 | D21: =D10*D20 | E21: =E10*E20
A22: FY2026 EBITDA, reported ($m) — Costco multiple on this same basis | C22: ='Income Statement'!F9+'Cash Flow'!F5 | D22: ='Income Statement'!F9+'Cash Flow'!F5 | E22: ='Income Statement'!F9+'Cash Flow'!F5
A23: Method 3 — EV/EBITDA per share ($) | C23: =(C11*C22+Valuation!B15)/Valuation!B12 | D23: =(D11*D22+Valuation!B15)/Valuation!B12 | E23: =(E11*E22+Valuation!B15)/Valuation!B12
A24: Blended fair value ($) | C24: =Valuation!$D$36*C19+Valuation!$D$37*C21+Valuation!$D$38*C23+Valuation!$D$39*C28 | D24: =Valuation!$D$36*D19+Valuation!$D$37*D21+Valuation!$D$38*D23+Valuation!$D$39*D28 | E24: =Valuation!$D$36*E19+Valuation!$D$37*E21+Valuation!$D$38*E23+Valuation!$D$39*E28
A25: Upside / (downside) | C25: =C24/Valuation!$B$11-1 | D25: =D24/Valuation!$B$11-1 | E25: =E24/Valuation!$B$11-1
A26: Total expected return | C26: =C25+Valuation!$B$16 | D26: =D25+Valuation!$B$16 | E26: =E25+Valuation!$B$16
A27: Rating (Base carries the published rating, Valuation!B44, incl. analyst override; Bear/Bull are band ratings) | C27: =IF(C26>Valuation!$B$7,"BUY",IF(C26>Valuation!$B$8,"ACCUMULATE",IF(C26>0,"HOLD","REDUCE"))) | D27: =Valuation!B44 | E27: =IF(E26>Valuation!$B$7,"BUY",IF(E26>Valuation!$B$8,"ACCUMULATE",IF(E26>0,"HOLD","REDUCE")))
A28: Method 4 — own trailing P/E per share ($) | C28: =C13*'Income Statement'!$F$27 | D28: =D13*'Income Statement'!$F$27 | E28: =E13*'Income Statement'!$F$27
A30: BEAR — yearly re-computation ($m)
B31: FY2026A | C31: FY2027E | D31: FY2028E | E31: FY2029E | F31: FY2030E | G31: FY2031E | H31: FY2032E | I31: FY2033E | J31: FY2034E | K31: FY2035E | L31: FY2036E
A32: Net sales growth | C32: =Forecast!C4+$C$5 | D32: =Forecast!D4+$C$5 | E32: =Forecast!E4+$C$5 | F32: =Forecast!F4+$C$5 | G32: =Forecast!G4+$C$5 | H32: =Forecast!H4+$C$5 | I32: =Forecast!I4+$C$5 | J32: =Forecast!J4+$C$5 | ... L32: =Forecast!L4+$C$5
A33: Net sales | B33: =Forecast!B5 | C33: =B33*(1+C32) | D33: =C33*(1+D32) | E33: =D33*(1+E32) | F33: =E33*(1+F32) | G33: =F33*(1+G32) | H33: =G33*(1+H32) | I33: =H33*(1+I32) | J33: =I33*(1+J32) | ... L33: =K33*(1+L32)
A34: Membership fee growth | C34: =Forecast!C6+$C$6 | D34: =Forecast!D6+$C$6 | E34: =Forecast!E6+$C$6 | F34: =Forecast!F6+$C$6 | G34: =Forecast!G6+$C$6 | H34: =Forecast!H6+$C$6 | I34: =Forecast!I6+$C$6 | J34: =Forecast!J6+$C$6 | ... L34: =Forecast!L6+$C$6
A35: Membership fees | B35: =Forecast!B7 | C35: =B35*(1+C34) | D35: =C35*(1+D34) | E35: =D35*(1+E34) | F35: =E35*(1+F34) | G35: =F35*(1+G34) | H35: =G35*(1+H34) | I35: =H35*(1+I34) | J35: =I35*(1+J34) | ... L35: =K35*(1+L34)
A36: Merchandise margin | B36: =Forecast!B10 | C36: =B36+Forecast!C9*$C$7 | D36: =C36+Forecast!D9*$C$7 | E36: =D36+Forecast!E9*$C$7 | F36: =E36+Forecast!F9*$C$7 | G36: =F36+Forecast!G9*$C$7 | H36: =G36+Forecast!H9*$C$7 | I36: =H36+Forecast!I9*$C$7 | J36: =I36+Forecast!J9*$C$7 | ... L36: =K36+Forecast!L9*$C$7
A37: Operating income | C37: =C33*C36+C35 | D37: =D33*D36+D35 | E37: =E33*E36+E35 | F37: =F33*F36+F35 | G37: =G33*G36+G35 | H37: =H33*H36+H35 | I37: =I33*I36+I35 | J37: =J33*J36+J35 | ... L37: =L33*L36+L35
A38: NOPAT | C38: =C37*(1-Forecast!C19) | D38: =D37*(1-Forecast!D19) | E38: =E37*(1-Forecast!E19) | F38: =F37*(1-Forecast!F19) | G38: =G37*(1-Forecast!G19) | H38: =H37*(1-Forecast!H19) | I38: =I37*(1-Forecast!I19) | J38: =J37*(1-Forecast!J19) | ... L38: =L37*(1-Forecast!L19)
A39: D&A | C39: =C33*Forecast!C24 | D39: =D33*Forecast!D24 | E39: =E33*Forecast!E24 | F39: =F33*Forecast!F24 | G39: =G33*Forecast!G24 | H39: =H33*Forecast!H24 | I39: =I33*Forecast!I24 | J39: =J33*Forecast!J24 | ... L39: =L33*Forecast!L24
A40: Capex | C40: =C33*Forecast!C27 | D40: =D33*Forecast!D27 | E40: =E33*Forecast!E27 | F40: =F33*Forecast!F27 | G40: =G33*Forecast!G27 | H40: =H33*Forecast!H27 | I40: =I33*Forecast!I27 | J40: =J33*Forecast!J27 | ... L40: =L33*Forecast!L27
A41: Operating NWC | B41: =Forecast!B30 | C41: =C33*Forecast!C29 | D41: =D33*Forecast!D29 | E41: =E33*Forecast!E29 | F41: =F33*Forecast!F29 | G41: =G33*Forecast!G29 | H41: =H33*Forecast!H29 | I41: =I33*Forecast!I29 | J41: =J33*Forecast!J29 | ... L41: =L33*Forecast!L29
A42: Cash released by NWC | C42: =-(C41-B41) | D42: =-(D41-C41) | E42: =-(E41-D41) | F42: =-(F41-E41) | G42: =-(G41-F41) | H42: =-(H41-G41) | I42: =-(I41-H41) | J42: =-(J41-I41) | ... L42: =-(L41-K41)
...

Sheet Peers & Street
A1: Peers and the Street
A2: Peer multiples: stockanalysis.com statistics pages (S&P Global Market Intelligence data). COST and WMT re-pulled at the 16-Oct-2026 close (read 18-Oct); BJ, PSMT, TGT and KR as at 1-Oct-2026 (cross-check band only). Consensus: S&P Global via stockanalysis.com, updated 15-Oct-2026.
A4: Company | B4: Ticker | C4: Market cap ($bn) | D4: EV ($bn) | E4: Trailing P/E (x) | F4: Forward P/E (x) | G4: EV/EBITDA TTM (x) | H4: ROIC | I4: Beta 5Y | J4: Dividend yield
A5: Costco Wholesale | B5: COST | C5: =Overview!B9/1000 | D5: 427.18 | E5: 47.64 | F5: 43.35 | G5: =Valuation!B32 | H5: 0.3926 | I5: =Overview!B16 | J5: =Overview!B13
A6: Walmart | B6: WMT | C6: 942.61 | D6: 1006.2 | E6: 43.05 | F6: 39.54 | G6: 22.83 | H6: 0.1331 | I6: 0.58 | J6: 0.0083
A7: BJ's Wholesale Club | B7: BJ | C7: 11.92 | D7: 14.66 | E7: 20.67 | F7: 19.43 | G7: 12.64 | H7: 0.1272 | I7: 0.185 | J7: 0
A8: PriceSmart | B8: PSMT | C8: 5.15 | D8: 5.17 | E8: 32.92 | F8: 29.86 | G8: 14.67 | H8: 0.1364 | I8: 0.775 | J8: 0.0084
A9: Target | B9: TGT | C9: 71.19 | D9: 84.97 | E9: 16.25 | F9: 16.87 | G9: 9.89 | H9: 0.1319 | I9: 0.995 | J9: 0.0296
A10: Kroger | B10: KR | C10: 35.13 | D10: 57.61 | E10: 34.07 | F10: 11.12 | G10: 7.16 | H10: 0.1387 | I10: 0.415 | J10: 0.0262
A11: Peer median (excl. Costco) | E11: =MEDIAN(E6:E10) | F11: =MEDIAN(F6:F10) | G11: =MEDIAN(G6:G10) | H11: =MEDIAN(H6:H10) | I11: =MEDIAN(I6:I10) | J11: =MEDIAN(J6:J10)
A12: Costco premium to Walmart, forward P/E | F12: =F5/F6-1
A13: Costco premium to Walmart, EV/EBITDA | G13: =G5/G6-1
A14: Walmart's 39.54x implies $3.00 EPS, about next-twelve-months; on its fiscal year to Jan-2027 ($2.89) it is 41.1x. Costco's 43.35x is on FY Aug-2027 consensus ($22.82).
A15: Only Walmart is used in the valuation. BJ's, PriceSmart, Target and Kroger are shown because printing only one comparator hides the rest.
A16: COST and WMT re-pulled at the 16-Oct-2026 close; BJ, TGT and KR at the 1-Oct close; PriceSmart's vendor page dated 29-Sep-2026.
A17: THE STREET — 40 analysts, S&P Global via stockanalysis.com, updated 15-Oct-2026
A18: Average price target ($) | B18: 1066
A19: Median price target ($) | B19: 1072
A20: Low ($) | B20: 770
A21: High ($) | B21: 1315
A22: Ratings, 15-Oct-2026: Strong Buy / Buy / Hold / Sell / Strong Sell | B22: 20 / 5 / 13 / 1 / 1
A23: Consensus FY2027 EPS ($) | B23: 22.82
A24: Consensus FY2028 EPS ($) | B24: 25.02
A25: Consensus FY2027 total revenue ($bn) | B25: 329.41
A26: Average target vs price | B26: =B18/Overview!B6-1
A27: Price ÷ consensus FY2027 EPS (x) | B27: =Overview!B6/B23
A28: Price ÷ consensus FY2028 EPS (x) | B28: =Overview!B6/B24
A30: TARGET CHANGES AFTER THE 24-SEP PRINT — Benzinga analyst-ratings page, read 2-Oct-2026 (Telsey: stockanalysis; Jefferies: MarketBeat, read 20-Oct-2026)
A31: Firm | B31: Rating | C31: Old target ($) | D31: New target ($) | E31: Date | F31: Action | G31: Source
A32: Bernstein (Zhihan Ma) | B32: Outperform | C32: 1144 | D32: 1143 | E32: 25-Sep-2026 | F32: cut | G32: Benzinga
A33: Mizuho (David Belinger) | B33: Outperform | C33: 1100 | D33: 1065 | E33: 25-Sep-2026 | F33: cut | G33: Benzinga
A34: JPMorgan (Christopher Horvers) | B34: Overweight | C34: 1100 | D34: 1015 | E34: 25-Sep-2026 | F34: cut | G34: Benzinga
A35: Raymond James (Bobby Griffin) | B35: Outperform | C35: 1100 | D35: 1050 | E35: 25-Sep-2026 | F35: cut | G35: Benzinga
A36: Truist (Scot Ciccarelli) | B36: Hold | C36: 1011 | D36: 955 | E36: 25-Sep-2026 | F36: cut | G36: Benzinga
A37: Wells Fargo (Edward Kelly) | B37: Equal-Weight | C37: 1000 | D37: 950 | E37: 25-Sep-2026 | F37: cut | G37: Benzinga
A38: Freedom Broker (Georgy Vashchenko) | B38: Buy | C38: 1030 | D38: 1010 | E38: 25-Sep-2026 | F38: cut | G38: Benzinga
A39: Deutsche Bank (Krisztina Katai) | B39: Buy | C39: 1091 | D39: 1079 | E39: 28-Sep-2026 | F39: cut | G39: Benzinga
A40: DA Davidson (Michael Baker) | B40: Neutral | C40: 1000 | D40: 1040 | E40: 25-Sep-2026 | F40: raise | G40: Benzinga
A41: RBC Capital (Steven Shemesh) | B41: Sector Perform | C41: 1000 | D41: 1000 | E41: 1-Oct-2026 | F41: unchanged | G41: Benzinga 25-Sep; reaffirmed 1-Oct (stockanalysis)
A42: Roth Capital (Bill Kirk) | B42: Sell | C42: 781 | D42: 781 | E42: 25-Sep-2026 | F42: unchanged | G42: Benzinga
...

Sheet Evidence
A1: Evidence block — every third-party figure the note relies on, dated and sourced
A2: Rows marked FEEDS feed the valuation; rows marked CONTEXT support the narrative and do NOT feed any number.
A4: Item | B4: Value | C4: Role | D4: Date | E4: Source
A5: US 10-yr Treasury par yield | B5: =TEXT(Overview!B17,"0.00%") | C5: FEEDS | D5: 16-Oct-2026 | E5: US Treasury, Daily Treasury Par Yield Curve Rates
A6: US 10-yr Treasury par yield, 30-Sep-2026 | B6: 5.29% | C6: CONTEXT | D6: 30-Sep-2026 | E6: US Treasury par yield table (5.26% on 29-Sep); FRED DGS10 4.79% on 1-Sep-2026
A7: Implied US equity risk premium | B7: =TEXT('Stress Tests'!B14,"0.00%") | C7: FEEDS (set at 4.5%, prudent) | D7: 1-Jan-2026 | E7: Damodaran, 'Data Update 2 for 2026'
A8: COST close | B8: ="$"&TEXT(Overview!B6,"#,##0.00") | C8: FEEDS | D8: 16-Oct-2026 | E8: stockanalysis.com price history; digrin
A9: COST beta, 5-year | B9: 0.87 (0.875 unrounded) | C9: FEEDS | D9: 16-Oct-2026 | E9: stockanalysis.com; Google Finance 0.86
A10: Peer multiples (WMT, BJ, PSMT, TGT, KR) | B10: see Peers & Street | C10: FEEDS (WMT and COST's own multiples) | D10: 16-Oct-2026 | E10: stockanalysis.com statistics pages, S&P Global data — COST and WMT at 16-Oct; others at 1-Oct
A11: FY2027 capex guidance | B11: ="$"&TEXT(Overview!B23/1000,"0.0")&"bn" | C11: FEEDS | D11: 24-Sep-2026 | E11: CFO Gary Millerchip, Q4 FY2026 call
A12: Tariff refund benefit | B12: $0.15/share net; $184m received in Q4 ($174m refunds + $10m interest), partly reinvested in prices | C12: FEEDS (recurring EPS) | D12: 24-Sep-2026 | E12: Q4 FY2026 release and call
A13: Q4 membership fee growth ex fee increase and FX | B13: =TEXT(Overview!B33,"0.0%") | C13: FEEDS (fee growth) | D13: 24-Sep-2026 | E13: Q4 FY2026 call
A14: Paid members / executive / cardholders | B14: 84.1m / 42.3m / 150.4m | C14: CONTEXT | D14: 24-Sep-2026 | E14: Q4 FY2026 call
A15: Renewal rates US&Canada / worldwide | B15: 92.3% / 89.8% | C15: CONTEXT | D15: 24-Sep-2026 | E15: Q4 FY2026 call
A16: Q4 gas price inflation contribution to comps | B16: ~3pp | C16: CONTEXT | D16: 24-Sep-2026 | E16: Q4 FY2026 call
A17: Q4 LIFO charge | B17: $152m vs $43m | C17: CONTEXT | D17: 24-Sep-2026 | E17: Q4 FY2026 call
A18: Warehouses; FY2027 openings | B18: 939; 33 incl. 5 relocations | C18: CONTEXT | D18: 24-Sep-2026 | E18: Q4 FY2026 release and call
A19: Warehouses: US & Puerto Rico / Canada | B19: 647 / 115 | C19: CONTEXT | D19: 24-Sep-2026 | E19: Q4 FY2026 release
A20: Costco Next marketplace discontinued | B20: not material | C20: CONTEXT | D20: 24-Sep-2026 | E20: Q4 FY2026 call
A21: Consensus target / FY2027 EPS / FY2028 EPS | B21: ="$"&TEXT('Peers & Street'!B18,"#,##0")&" / $"&TEXT('Peers & Street'!B23,"0.00")&" / $"&TEXT('Peers & Street'!B24,"0.00") | C21: FEEDS memo rows only (Stress Tests 7, 19) | D21: 15-Oct-2026 | E21: S&P Global via stockanalysis.com (40 analysts)
A22: Second poll: average target, 25 analysts | B22: ="$"&TEXT('Peers & Street'!B54,"#,##0") | C22: CONTEXT | D22: 2-Oct-2026 | E22: Benzinga analyst-ratings page
A23: Post-print target changes | B23: 9 cuts (8 real + Bernstein $1), 1 raise, 4 unchanged | C23: CONTEXT | D23: 25–30-Sep-2026 | E23: Benzinga; Telsey: stockanalysis; Jefferies: MarketBeat (read 20-Oct-2026)
A24: Consensus target before the print | B24: $1,077 | C24: CONTEXT | D24: 4-Sep-2026 | E24: S&P Global via stockanalysis.com
A25: Entity check: M&A, spin-offs, splits, capital raises in last 12 months | B25: none | C25: CONTEXT | D25: 2-Oct-2026 | E25: news search; net acquisitions $0; no split since January 2000
A26: Q4 FY2026 consensus EPS | B26: ="$"&TEXT('Peers & Street'!B63,"0.00")&" ($6.54–6.55 elsewhere)" | C26: CONTEXT | D26: 25-Sep-2026 | E26: Benzinga
A27: COST closes at fiscal year-ends FY2022–FY2026 | B27: see Peers & Street rows 69–73 | C27: CONTEXT | D27: 2-Oct-2026 | E27: Yahoo Finance chart data; FY2026 close cross-checked to stockanalysis
A28: Walmart consensus EPS, fiscal year to Jan-2027 | B28: $2.89 (41.11x) | C28: FEEDS memo rows only (Stress Tests 34–37) | D28: 16-Oct-2026 | E28: stockanalysis.com WMT forecast (S&P Global)
A29: Walmart adjusted EPS, FY2022–H1 FY2027 | B29: see Peers & Street rows 93–103 | C29: FEEDS premium history | D29: 2-Oct-2026 | E29: Walmart 8-K earnings releases, SEC EDGAR
A30: COST and WMT closes at history dates | B30: see Peers & Street rows 83–89 | C30: CROSS-CHECK (Method 4, 0% weight) | D30: 3-Oct-2026 | E30: Yahoo Finance chart data; recent WMT closes match Nasdaq
A31: US 10-yr at history dates | B31: 4.75%–4.98%, 14 sessions 3-Oct to 1-Nov-2023 | C31: CROSS-CHECK (Method 4 window, 0% weight) | D31: 3-Oct-2026 | E31: FRED DGS10
A32: US 10-yr, 1-Sep to 1-Oct-2026 (≥5.00% sessions) | B32: 5.00%–5.29%, 10 sessions | C32: CROSS-CHECK (Peers & Street rows 130–139) | D32: 3-Oct-2026 | E32: US Treasury par yield curve CSV, Sep/Oct 2026
A33: COST closes, Sep–Oct 2026 | B33: see Peers & Street rows 130–139 | C33: CROSS-CHECK | D33: 3-Oct-2026 | E33: StatMuse; stockanalysis.com; Bullstory — agree
A34: Costco 36-week EPS FY2026 / FY2025; Q1 FY2025 / FY2024 | B34: $14.01 / $12.34; $4.04 / $3.58 | C34: CROSS-CHECK (TTM EPS) | D34: 3-Oct-2026 | E34: Q3 FY2026 release and 10-Q; Q1 FY2025 10-Q (SEC EDGAR)
A35: S&P 500 forward 12-month P/E | B35: 17.7x / 21.5x / 19.0x | C35: CROSS-CHECK (rows 146–148) | D35: 20-Oct-2023 / 10-Jan-2025 / 2-Oct-2026 | E35: FactSet Earnings Insight (single source)
