Workbook
Name AD_PAT26: (Scorecard!$I$13+Scorecard!$I$14+Scorecard!$I$15+Scorecard!$I$16)*100

Sheet Cover
A1: DEAL DECODED #1 · HDFC LTD INTO HDFC BANK
A2: Outside-in analysis from public filings. Debjit Mukherjee, IB Independent. Market data to 19-Oct-2026. Not investment advice.
A4: HEADLINE OUTPUTS
A5: Exchange ratio | B5: ='Deal Terms'!B22
A6: Premium over unaffected market ratio | B6: ='Premium & Precedents'!B9
A7: Value transferred to HDFC Ltd holders (Rs crore) | B7: ='Premium & Precedents'!B13
A8: Precedent median premium | B8: ='Premium & Precedents'!D43
A9: Implied P/B (HDFC Ltd standalone FY22) | B9: ='Premium & Precedents'!B18
A10: Net transfer from legacy HDFC Bank holders (Rs crore) | B10: ='Premium & Precedents'!B15
A11: HDFC Ltd holders: earnings contribution vs ownership received | B11: ='Premium & Precedents'!B54
A12: … ownership received | B12: ='Premium & Precedents'!B56
A13: PV of CRR/SLR drag over the transition (Rs crore) | B13: =Synergies!B26
A14: PV of drag ÷ net transfer | B14: =Synergies!B31
A15: EPS accretion, illustrative pro forma (deck) | B15: ='Accretion-Dilution'!D9
A16: EPS accretion after the CRR/SLR drag (before funding saving) | B16: ='Accretion-Dilution'!D15
A17: EPS CAGR, three years before the merger (FY2020–FY2023) | B17: ='Accretion-Dilution'!E21
A18: … and across the merger (FY2023–FY2026) | B18: ='Accretion-Dilution'!G22
A19: HDFC Bank TSR, 1-Apr-2022 to 19-Oct-2026 | B19: ='Valuation & Verdict'!B9
A20: Nifty Bank price return, same window | B20: ='Valuation & Verdict'!B11
A21: Former HDFC Ltd holder's total return | B21: ='Valuation & Verdict'!B19
A22: Change in HDFC Bank P/B | B22: ='Valuation & Verdict'!B27
A23: ROE before the merger (FY2023) | B23: ='Valuation & Verdict'!B32
A24: … ROE pro forma at close (deck) | B24: ='Valuation & Verdict'!C32
A25: … ROE latest (Q2 FY27) | B25: ='Valuation & Verdict'!D32
A28: CHECKS (ALL MUST READ PASS)
A29: Share count ties to allotment intimation | B29: =IF('Deal Terms'!B27=0,"PASS","FAIL")
A30: Record-date HDFC Ltd shares (allotment / ratio) within 3% of the announcement count | B30: =IF(ABS('Deal Terms'!B29/'Deal Terms'!B30-1)<0.03,"PASS","FAIL")
A31: Drag grid base cell = Synergies | B31: =IF(Sensitivities!B11=0,"PASS","FAIL")
A32: Accretion grid corners = Accretion-Dilution | B32: =IF(AND(Sensitivities!B21=0,Sensitivities!F21=0),"PASS","FAIL")
A35: TAB MAP
A36: Deal Terms — snapshot, share arithmetic, timeline, RBI forbearance
A37: Target Standalone / Acquirer Standalone — FY2020–FY2023
A38: Premium & Precedents — what was paid
A39: Synergies — claims vs the CRR/SLR bill (PV over the transition); funding repair
A40: Accretion-Dilution — deck vs adjusted vs realised
A41: Pro Forma — sources & uses, ownership, balance-sheet shock
A42: Scorecard — 14 quarters after the deal
A43: Valuation & Verdict — TSR, decomposition, verdict
A44: Sensitivities — three grids
A45: Evidence — sources

Sheet Deal Terms
A1: HDFC Ltd into HDFC Bank — Deal Terms
A2: Source: scheme filings, Reg 30 intimations, NCLT notices, RBI/IRDAI disclosures (see Evidence). Units INR crore unless stated. Blue = input, black = formula, green = cross-sheet link.
A4: DEAL SNAPSHOT
A5: Announced | B5: 4-Apr-2022 (boards met before market open)
A6: Structure | B6: Composite scheme u/s 230–232; HDFC Investments and HDFC Holdings into HDFC Ltd, then HDFC Ltd into HDFC Bank
A7: Consideration | B7: All stock: 42 HDFC Bank shares (FV Re 1) for 25 HDFC Ltd shares (FV Rs 2)
A8: Cross-holding | B8: HDFC group's ~21% stake in HDFC Bank extinguished; bank becomes 100% public
A9: Accounting | B9: Pooling of interests (AS-14)
A10: Effective date | B10: 1-Jul-2023 (record date 13-Jul-2023, allotment 14-Jul-2023)
A11: Fairness opinion — HDFC Bank | B11: Morgan Stanley India (ratio fair to HDFC Bank)
A12: Fairness opinion — HDFC Ltd | B12: BofA Securities India (ratio fair to HDFC Ltd)
A13: Registered valuers | B13: H. C. Ruparelia with Deloitte (bank); Drushti Desai with Bansi S. Mehta & Co. (HDFC Ltd); joint report 4-Apr-2022
A14: Valuation approaches considered | B14: Asset, income/DCF, market price, cost (per law-firm summary; weights not extractable from scanned annexures)
A15: Guided timeline | B15: 15–18 months (management, 4-Apr-2022); actual 15 months to effective date
A16: Headline size | B16: ~USD 40bn (press)
A19: SHARE ARITHMETIC
A20: HDFC Bank shares per 25 HDFC Ltd shares | B20: 42
A21: HDFC Ltd shares exchanged (denominator) | B21: 25
A22: Exchange ratio (HDFC Bank shares per HDFC Ltd share) | B22: =B20/B21
A23: HDFC Bank shares outstanding before (crore) | B23: 559.17988
A24: New shares issued to HDFC Ltd holders (crore) | B24: 311.03965
A25: Cross-held shares cancelled (crore) | B25: 116.46258
A26: HDFC Bank shares outstanding after (crore) | B26: =B23+B24-B25
A27: Check vs allotment intimation (753.7569464 crore) — must be 0 | B27: =ROUND(B26-753.7569464,4)
A28: Former HDFC Ltd holders' share of the combined bank | B28: =B24/B26
A29: HDFC Ltd shares at record date implied by allotment (crore) | B29: =B24/B22
A30: HDFC Ltd shares at announcement (crore) | B30: 181.73
A32: TIMELINE AND APPROVALS
A33: Date | B33: Event
A34: 4-Apr-2022 | B34: Boards approve; announcement
A35: 2-Jul-2022 | B35: BSE no adverse observations / NSE no objection
A36: 4-Jul-2022 | B36: RBI no-objection
A37: 7/8-Jul-2022 | B37: PFRDA approval
A38: 8-Aug-2022 | B38: NHB no-objection
A39: 12-Aug-2022 | B39: CCI approval
A40: 25-Nov-2022 | B40: Shareholder meetings; HDFC Bank 99.681% for (public 99.537%)
A41: 17-Mar-2023 | B41: NCLT Mumbai sanction
A42: 20-Apr-2023 | B42: RBI forbearance letter: CRR/SLR/LCR relief refused; PSL phased over 3 years
A43: 23-Jun-2023 | B43: IRDAI approval (HDFC Life/ERGO stakes above 50%)
A44: 1-Jul-2023 | B44: Scheme effective
...

Sheet Target Standalone
A1: HDFC Ltd (target) — standalone, FY2020–FY2023
A2: Ind AS standalone; INR crore unless stated. Source: HDFC Ltd annual reports, results, Q4 FY23 call (see Evidence). n/a = not retrieved.
B4: FY2020 | C4: FY2021 | D4: FY2022 | E4: FY2023
A5: AUM incl. loans sold | B5: 516773 | C5: 569894 | D5: 653902 | E5: 723988
A6: Loans outstanding | B6: 450903 | C6: 498298 | D6: 568363 | E6: n/a
A7: Borrowings (bank/FI + market + deposits) | B7: 419102 | C7: 441365 | D7: 499681 | E7: 568222
A8: of which deposits | B8: 132324 | C8: 150131 | D8: 160900 | E8: 152111
A9: Shareholders' funds | B9: 86158 | C9: 108783 | D9: 120251 | E9: 133985
A10: Profit after tax (standalone) | B10: 17770 | C10: 12027 | D10: 13742 | E10: 16239
A11: Consolidated PAT attributable to HDFC | B11: n/a | C11: n/a | D11: 22595 | E11: 26161
A12: EPS (Rs) | B12: 103 | C12: 68 | D12: 76 | E12: 89.2
A13: BVPS (Rs) | B13: 497 | C13: 603 | D13: 663 | E13: n/a
A14: Dividend per share (Rs) | B14: n/a | C14: 23 | D14: 30 | E14: 44
A15: NIM | B15: n/a | C15: 0.035 | D15: 0.035 | E15: 0.036
A16: Gross NPA | B16: 0.0199 | C16: 0.0198 | D16: 0.0191 | E16: 0.0118
A18: ROE (PAT ÷ average shareholders' funds) | C18: =C10/AVERAGE(B9,C9) | D18: =D10/AVERAGE(C9,D9) | E18: =E10/AVERAGE(D9,E9)
A19: Borrowings ÷ shareholders' funds (leverage) | B19: =B7/B9 | C19: =C7/C9 | D19: =D7/D9 | E19: =E7/E9
A21: FY2020 PAT and EPS include a Rs 9,020 cr fair-value gain on the GRUH–Bandhan merger. Standalone figures include the stakes in HDFC Bank and the subsidiaries.

Sheet Acquirer Standalone
A1: HDFC Bank (acquirer) — standalone, FY2020–FY2023 (pre-merger)
A2: Indian GAAP standalone; INR crore unless stated. Source: HDFC Bank 6-K results filings (SEC EDGAR). Per-share figures pre-bonus (1:1 bonus Aug-2025).
B4: FY2020 | C4: FY2021 | D4: FY2022 | E4: FY2023
A5: Total assets | B5: 1530511 | C5: 1746871 | D5: 2068535 | E5: 2466081
A6: Advances (net) | B6: 993703 | C6: 1132837 | D6: 1368821 | E6: 1600586
A7: Deposits | B7: 1147502 | C7: 1335060 | D7: 1559217 | E7: 1883395
A8: CASA ratio | B8: 0.422 | C8: 0.461 | D8: 0.482 | E8: 0.444
A9: Net interest income | B9: 56186 | C9: 64880 | D9: 72010 | E9: 86842
A10: Profit after tax | B10: 26257 | C10: 31117 | D10: 36961 | E10: 44109
A11: Net worth | B11: 170986 | C11: 203721 | D11: 240093 | E11: 280199
A12: Basic EPS (Rs) | B12: 48 | C12: 56.6 | D12: 66.8 | E12: 79.25
A13: CET1 | B13: 0.164 | C13: 0.169 | D13: 0.167 | E13: 0.164
A14: Gross NPA | B14: 0.0126 | C14: 0.0132 | D14: 0.0117 | E14: 0.0112
A15: ROA (average) | B15: 0.0201 | C15: 0.0197 | D15: 0.0203 | E15: 0.0207
A16: Branches | B16: 5254 | C16: 5608 | D16: 6342 | E16: 7821
A18: Loan-to-deposit ratio (advances ÷ deposits) | B18: =B6/B7 | C18: =C6/C7 | D18: =D6/D7 | E18: =E6/E7
A19: ROE (PAT ÷ average net worth) | C19: =C10/AVERAGE(B11,C11) | D19: =D10/AVERAGE(C11,D11) | E19: =E10/AVERAGE(D11,E11)
A20: BVPS (net worth ÷ shares) (Rs) | B20: =B11/B21 | C20: =C11/C21 | D20: =D11/D21 | E20: =E11/E21
A21: Shares (PAT ÷ EPS, crore) | B21: =B10/B12 | C21: =C10/C12 | D21: =D10/D12 | E21: =E10/E12
A22: EPS CAGR FY2020–FY2023 (pre-merger trend) | B22: =(E12/B12)^(1/3)-1
A24: BVPS derived from net worth ÷ (PAT ÷ EPS); the bank's FY2022 reported BVPS was Rs 433.0 (used on Premium & Precedents and Valuation & Verdict).

Sheet Premium & Precedents
A1: What was paid — premium, implied multiples, precedents
A2: Unaffected date = 1-Apr-2022, the last close before the 4-Apr-2022 pre-market announcement. Prices: BSE closes (press), cross-checked by back-calculating the 4-Apr % moves and the deck's market caps.
A4: PREMIUM
A5: HDFC Ltd close, 1-Apr-2022 (Rs) | B5: 2450.95
A6: HDFC Bank close, 1-Apr-2022 (Rs) | B6: 1506.3
A7: Deal exchange ratio | B7: ='Deal Terms'!B22
A8: Unaffected market ratio (HDFC Ltd ÷ HDFC Bank) | B8: =B5/B6
A9: PREMIUM OF DEAL RATIO OVER MARKET RATIO | B9: =B7/B8-1
A10: Implied value per HDFC Ltd share at the unaffected bank price (Rs) | B10: =B7*B6
A11: HDFC Ltd shares at announcement (crore) | B11: ='Deal Terms'!B30
A12: HDFC Ltd unaffected market cap | B12: =B5*B11
A13: VALUE TRANSFERRED TO HDFC LTD HOLDERS BY THE PREMIUM | B13: =B12*B9
A14: Implied equity value of HDFC Ltd at the deal ratio | B14: =B10*B11
A15: NET TRANSFER FROM LEGACY HDFC BANK HOLDERS (HDFC Ltd holders fund their own share) | B15: =B13*(1-'Deal Terms'!B28)
A16: IMPLIED MULTIPLES (HDFC LTD)
A17: FY2022 BVPS, standalone (Rs) | B17: ='Target Standalone'!D13
A18: Implied P/B, standalone FY2022 | B18: =B10/B17
A19: Unaffected P/B, standalone FY2022 | B19: =B5/B17
A20: FY2022 EPS, standalone (Rs) | B20: ='Target Standalone'!D12
A21: Implied P/E, standalone FY2022 | B21: =B10/B20
A22: Implied P/E, consolidated FY2022 (equity value ÷ attributable PAT) | B22: =B14/'Target Standalone'!D11
A23: Standalone multiples include HDFC Ltd's 21% stake in the bank and its subsidiaries; they are not the multiple paid for the mortgage book alone.
A25: ANNOUNCEMENT-DAY REACTION, 4-APR-2022 (BSE)
B26: HDFC Ltd | C26: HDFC Bank
A27: Close, 4-Apr-2022 (Rs) | B27: 2678.9 | C27: 1656.45
A28: Move on the day | B28: =B27/B5-1 | C28: =C27/B6-1
A29: Market-cap change on the day (reported) | B29: 41326 | C29: 83280
A30: Combined value created on the day | B30: =B29+C29
A31: Both stocks were ~25% below their 4-Apr intraday highs by 19-May-2022: the day-one value creation did not hold.
A33: PRECEDENT TRANSACTIONS — INDIAN FINANCIAL SERVICES
A34: Deal | B34: Announced | C34: Terms | D34: Premium / (discount) | E34: Note
A35: Kotak Mahindra + ING Vysya | B35: 20-Nov-2014 | C35: 725 : 1,000 | D35: 0.16 | E35: Bank-bank; fairness opinions Avendus, Edelweiss
A36: IDFC Bank + Capital First | B36: 13-Jan-2018 | C36: 139 : 10 | D36: 0.12 | E36: NBFC into bank; premium derived
A37: GRUH Finance into Bandhan Bank | B37: 7-Jan-2019 | C37: 568 : 1,000 | D37: -0.07 | E37: Closest HFC-into-bank precedent; HDFC was the seller
A38: IDFC Ltd into IDFC First Bank | B38: 3-Jul-2023 | C38: 155 : 100 | D38: 0.2 | E38: Holdco reverse merger
A39: ICICI Ltd into ICICI Bank | B39: 25-Oct-2001 | C39: 1 : 2 | D39: n/v | E39: DFI parent into bank; premium not verified
A40: HDFC Bank + Centurion Bank of Punjab | B40: 25-Feb-2008 | C40: 1 : 29 | D40: n/v | E40: Premium not verified
A41: HDFC Ltd into HDFC Bank | B41: 4-Apr-2022 | C41: 42 : 25 | D41: =B9
A43: Precedent premium — median (verified deals) | D43: =MEDIAN(D35:D38)
A44: Precedent premium — 25th percentile | D44: =QUARTILE(D35:D38,1)
...

Sheet Synergies
A1: Synergies claimed vs the regulatory bill
A2: Management gave no rupee synergy target. The quantifiable item is a dis-synergy: RBI refused to phase CRR/SLR on HDFC Ltd's liabilities. Yields are desk assumptions (blue) — see Sensitivities.
A4: WHAT MANAGEMENT CLAIMED (4-APR-2022)
A5: EPS accretion | B5: 'EPS accretive from the first year itself' (K. Mistry); deck pro forma EPS ~65 → ~67
A6: Cost of funds | B6: 'the overall cost of funds will come down' (K. Mistry)
A7: Cost-to-income | B7: Merged ~32–33% vs 36–37% for the bank alone (S. Jagdishan)
A8: Cross-sell | B8: 70% of HDFC customers don't bank with HDFC Bank; >70% of bank customers have no mortgage
A9: Rupee synergy target | B9: None disclosed
A11: THE REGULATORY DIS-SYNERGY — CRR AND SLR ON HDFC LTD'S LIABILITIES
A12: Liabilities brought in (HDFC Ltd gross borrowings, FY2023) — NDTL proxy; upper bound (inter-bank and intra-group items would be netted) | B12: ='Target Standalone'!E7
A13: Cash reserve ratio (earns nothing) | B13: 0.045
A14: Statutory liquidity ratio (held in G-secs) | B14: 0.18
A15: Yield on the loans these balances displace (desk assumption) | B15: 0.086
A16: Yield on SLR G-secs (desk assumption, 10-yr ~7.1–7.3% in 2023) | B16: 0.072
A17: Tax rate | B17: 0.2517
A18: CRR balance required | B18: =B12*B13
A19: SLR balance required | B19: =B12*B14
A20: Total locked in reserves | B20: =B18+B19 | C20: Press estimates were ~Rs 1 lakh crore; ours is ~28% higher because the base is gross borrowings — treat as an upper bound.
A21: Pre-tax earnings drag per year | B21: =B18*B15+B19*(B15-B16)
A22: AFTER-TAX EARNINGS DRAG PER YEAR | B22: =B21*(1-B17)
A23: HDFC Bank P/E at the unaffected price (FY2022 EPS) — memo | B23: ='Premium & Precedents'!B6/'Acquirer Standalone'!D12
A24: Cost of equity used to discount the drag (desk assumption) | B24: 0.13
A25: Years of transition (close to Sep-2026 is ~3.25 years) | B25: 3
A26: PRESENT VALUE OF THE DRAG OVER THE TRANSITION | B26: =B22*(1-(1+B24)^-B25)/B24
A27: Memo: perpetual capitalisation at the bank's P/E (upper bound — NOT used; CRR/SLR is the permanent cost of being a bank) | B27: =B22*B23
A28: Gross value transferred by the premium | B28: ='Premium & Precedents'!B13
A29: Net transfer from legacy HDFC Bank holders | B29: ='Premium & Precedents'!B15
A30: PV of the drag ÷ gross premium | B30: =B26/B28
A31: PV of the drag ÷ net transfer | B31: =B26/B29
A32: The risk was disclosed on day one (management had 'requested RBI for phased compliance'); the surprise was the refusal. The SLR leg is an upper estimate: it ignores mortgage credit cost, zero risk weight on G-secs and liquid assets HDFC Ltd already held. Not modelled: LCR, priority-sector cost, cost-of-funds benefit.
A34: FUNDING REPAIR — WHAT HAS BEEN DELIVERED
A35: Standalone borrowings at the Dec-2023 peak (Rs bn) | B35: =Scorecard!N7
A36: Standalone borrowings, Sep-2026 (Rs bn) | B36: =Scorecard!N18
A37: Borrowings retired (Rs bn) | B37: =B35-B36
A38: Pre-merger standalone borrowings, Jun-2023 (Rs bn) | B38: =Scorecard!N5
A39: Borrowings today ÷ pre-merger level (x) | B39: =B36/B38
A40: Management (Oct-2026 call): ~Rs 2.6 lakh cr of legacy maturities substituted with deposits | B40: 2600
A42: THE REFUSAL ITSELF — VALUE OF THE PHASE-IN THAT WAS DENIED
A43: Relief under a 3-year phase-in: share of the drag avoided in years 1 and 2 | B43: =2/3 | C43: =1/3
A44: PV of the denied phase-in (Rs crore) | B44: =B22*B43/(1+B24)+B22*C43/(1+B24)^2
...

Sheet Accretion-Dilution
A1: Accretion / dilution — promised vs realised
A2: Announcement pro forma from the 4-Apr-2022 deck (annualised Dec-2021, standalone). Realised EPS from HDFC Bank results; FY2026 = sum of quarterly standalone EPS, bonus-adjusted ×2.
A4: AT ANNOUNCEMENT — THE DECK'S PRO FORMA (ANNUALISED DEC-2021)
B5: HDFC Bank | C5: HDFC Ltd | D5: Pro forma
A6: Annualised PAT | B6: 35875 | C6: 13388 | D6: 49263
A7: Shares (crore) | B7: 554 | D7: 742
A8: EPS (Rs) | B8: =B6/B7 | D8: =D6/D7
A9: EPS ACCRETION, ILLUSTRATIVE PRO FORMA (deck printed ~+3%) | D9: =D8/B8-1
A11: ADJUSTED FOR WHAT RBI LATER REFUSED (CRR/SLR FROM DAY ONE)
A12: HDFC Ltd borrowings at FY2022 (liabilities brought in) | B12: ='Target Standalone'!D7
A13: After-tax CRR/SLR drag on that base | B13: =B12*(Synergies!B13*Synergies!B15+Synergies!B14*(Synergies!B15-Synergies!B16))*(1-Synergies!B17)
A14: Pro forma EPS after the drag (Rs) | D14: =(D6-B13)/D7
A15: EPS ACCRETION / (DILUTION) AFTER THE DRAG, BEFORE ANY FUNDING SAVING (FY2022 base) | D15: =D14/B8-1
A16: Funding-cost saving needed on HDFC Ltd's book to break even on EPS (bp) | D16: =MAX(0,(B8*D7-(D6-B13))/(1-Synergies!B17)/B12*10000)
A18: REALISED — HDFC BANK STANDALONE EPS (Rs, PRE-BONUS BASIS)
B19: FY2020 | C19: FY2021 | D19: FY2022 | E19: FY2023 | F19: FY2024 (derived) | G19: FY2026
A20: Basic EPS | B20: ='Acquirer Standalone'!B12 | C20: ='Acquirer Standalone'!C12 | D20: ='Acquirer Standalone'!D12 | E20: ='Acquirer Standalone'!E12 | F20: =(Scorecard!I5+Scorecard!I6+Scorecard!I7+Scorecard!I8)*100/('Deal Terms'!B23*0.25+'Deal Terms'!B26*0.75) | G20: =(Scorecard!R13+Scorecard!R14+Scorecard!R15+Scorecard!R16)*2
A21: EPS CAGR, FY2020–FY2023 (three years before the merger) | E21: =(E20/B20)^(1/3)-1
A22: EPS CAGR, FY2023–FY2026 (three years across the merger) | G22: =(G20/E20)^(1/3)-1
A23: PAT growth FY2023–FY2026 vs EPS growth (share issuance absorbs the difference) | E23: =AD_PAT26/'Acquirer Standalone'!E10-1 | G23: =G20/E20-1
A25: FY2024 EPS growth — the 'accretive from the first year' test (derived: FY24 PAT ÷ time-weighted shares) | F25: =F20/E20-1
A26: FY2023 EPS growth, the last standalone year, for comparison | E26: =E20/D20-1
A27: FY2026 standalone PAT Rs 74,670 cr = sum of quarterly PAT; includes the Rs 9,130 cr HDB Financial IPO gain, offset by a Rs 9,000 cr floating provision in the same quarter.

Sheet Pro Forma
A1: Sources & uses, ownership and the balance sheet
A2: All-stock deal: the 'source' is new HDFC Bank shares; the 'use' is 100% of HDFC Ltd. Values at the unaffected HDFC Bank price.
A4: SOURCES AND USES (AT THE UNAFFECTED BANK PRICE)
A5: Sources | B5: Rs crore | D5: Uses | E5: Rs crore
A6: New HDFC Bank shares issued | B6: ='Deal Terms'!B24*'Premium & Precedents'!B6 | D6: 100% of HDFC Ltd (record-date shares × implied value) | E6: ='Deal Terms'!B29*'Premium & Precedents'!B10
A7: less: HDFC Ltd's own HDFC Bank shares, cancelled | B7: =-'Deal Terms'!B25*'Premium & Precedents'!B6
A8: NET NEW SHARES ISSUED (net issuance value) | B8: =B6+B7
A9: Check: sources = uses (must be ~0; rounding of the record-date share count) | B9: =ROUND(B6-E6,0)
A10: Cancelled stake as % of HDFC Ltd's unaffected market cap | B10: =-B7/'Premium & Precedents'!B12
A12: OWNERSHIP OF THE COMBINED BANK
A13: Former HDFC Ltd holders | B13: ='Deal Terms'!B28
A14: Existing HDFC Bank public holders | B14: =1-B13
A15: Promoter / parent holding after the deal | B15: 0
A17: PRO FORMA AT ANNOUNCEMENT (DECK, STANDALONE, 31-DEC-2021)
B18: HDFC Bank | C18: HDFC Ltd | D18: Pro forma | E18: Change
A19: Net worth | B19: 229640 | C19: 115400 | D19: 330768 | E19: =D19/B19-1
A20: Advances | B20: 1268863 | C20: 525806 | D20: 1786669 | E20: =D20/B20-1
A21: Annualised PAT | B21: 35875 | C21: 13388 | D21: 49263 | E21: =D21/B21-1
A22: Shares (crore) | B22: 554 | C22: 181 | D22: 742 | E22: =D22/B22-1
A23: BVPS (Rs) | B23: 414 | C23: 638 | D23: 446 | E23: =D23/B23-1
A25: BALANCE SHEET SHOCK — LAST QUARTER STANDALONE VS FIRST QUARTER MERGED
B26: Jun-2023 | C26: Sep-2023 | D26: Change
A27: Gross advances (Rs bn) | B27: =Scorecard!B5 | C27: =Scorecard!B6 | D27: =C27/B27-1
A28: Deposits (Rs bn) | B28: =Scorecard!C5 | C28: =Scorecard!C6 | D28: =C28/B28-1
A29: Loan-to-deposit ratio | B29: =Scorecard!F5 | C29: =Scorecard!F6 | D29: =C29-B29
A30: CASA ratio | B30: =Scorecard!D5 | C30: =Scorecard!D6 | D30: =C30-B30
A31: NIM on total assets | B31: =Scorecard!G5 | C31: =Scorecard!G6 | D31: =C31-B31
A32: Borrowings (Rs bn) | B32: =Scorecard!N5 | C32: =Scorecard!N6 | D32: =C32/B32-1

Sheet Scorecard
A1: Post-deal scorecard — HDFC Bank standalone, quarterly
A2: Source: HDFC Bank results releases and presentations (bank site; SEC 6-K). Rs bn; ratios %. LDR = gross advances ÷ deposits (desk derivation). EPS/BVPS bonus-adjusted (1:1, Aug-2025). Q1 FY24 = pre-merger.
A4: Quarter | B4: Gross advances | C4: Deposits | D4: CASA | E4: Cost/income | F4: LDR (derived) | G4: NIM, total assets | H4: NII | I4: PAT | J4: ROA | K4: ROE | L4: CET1 | M4: Gross NPA | N4: Borrowings | O4: Borr. % liabilities | P4: BVPS (adj.) | Q4: Branches | R4: EPS (adj.)
A5: Q1FY24 | B5: 16156.7 | C5: 19131 | D5: 0.425 | E5: 0.428 | F5: =B5/C5 | G5: 0.041 | H5: 236 | I5: 119.5 | J5: n/r | K5: n/r | L5: 0.162 | M5: 0.0117 | N5: 2094.2 | O5: n/r | P5: 263 | Q5: 7860 | R5: 10.7
A6: Q2FY24 | B6: 23546.3 | C6: 21728.6 | D6: 0.376 | E6: 0.404 | F6: =B6/C6 | G6: 0.0365 | H6: 273.9 | I6: 159.8 | J6: n/r | K6: n/r | L6: 0.173 | M6: 0.0134 | N6: 7167.7 | O6: 0.21 | P6: 267 | Q6: 7945 | R6: n/r
A7: Q3FY24 | B7: 24693 | C7: 22140 | D7: 0.377 | E7: 0.403 | F7: =B7/C7 | G7: 0.034 | H7: 284.7 | I7: 163.7 | J7: n/r | K7: n/r | L7: 0.163 | M7: 0.0126 | N7: 7377 | O7: n/r | P7: 278 | Q7: 8091 | R7: n/r
A8: Q4FY24 | B8: 25078 | C8: 23798 | D8: 0.382 | E8: 0.38 | F8: =B8/C8 | G8: 0.0344 | H8: 290.8 | I8: 165.1 | J8: n/r | K8: n/r | L8: 0.163 | M8: 0.0124 | N8: 6621.5 | O8: 0.18 | P8: 290 | Q8: 8738 | R8: n/r
A9: Q1FY25 | B9: 24869 | C9: 23791 | D9: 0.363 | E9: 0.41 | F9: =B9/C9 | G9: 0.0347 | H9: 298.4 | I9: 161.7 | J9: n/r | K9: n/r | L9: 0.168 | M9: 0.0133 | N9: 5993.4 | O9: n/r | P9: 301 | Q9: 8851 | R9: 10.64
A10: Q2FY25 | B10: 25190 | C10: 25001 | D10: 0.353 | E10: 0.406 | F10: =B10/C10 | G10: 0.0346 | H10: 301.1 | I10: 168.2 | J10: n/r | K10: n/r | L10: 0.173 | M10: 0.0136 | N10: 5855.6 | O10: n/r | P10: 304 | Q10: 9092 | R10: n/r
A11: Q3FY25 | B11: 25426 | C11: 25638 | D11: 0.34 | E11: 0.406 | F11: =B11/C11 | G11: 0.0343 | H11: 306.5 | I11: 167.4 | J11: n/r | K11: n/r | L11: 0.175 | M11: 0.0142 | N11: 5702.4 | O11: 0.15 | P11: 316 | Q11: 9143 | R11: 11
A12: Q4FY25 | B12: 26435 | C12: 27147 | D12: 0.348 | E12: 0.398 | F12: =B12/C12 | G12: 0.0346 | H12: 320.7 | I12: 176.2 | J12: n/r | K12: n/r | L12: 0.172 | M12: 0.0133 | N12: 5479.3 | O12: 0.14 | P12: 328 | Q12: 9455 | R12: 11.5
A13: Q1FY26 | B13: 26532 | C13: 27641 | D13: 0.339 | E13: 0.396 | F13: =B13/C13 | G13: 0.0335 | H13: 314.4 | I13: 181.6 | J13: 0.019 | K13: 0.147 | L13: 0.174 | M13: 0.014 | N13: 5100.6 | O13: 0.13 | P13: 341 | Q13: 9499 | R13: 11.9
A14: Q2FY26 | B14: 27692 | C14: 28018 | D14: 0.339 | E14: 0.392 | F14: =B14/C14 | G14: 0.0327 | H14: 315.5 | I14: 186.4 | J14: 0.019 | K14: 0.144 | L14: 0.175 | M14: 0.0124 | N14: 5096 | O14: 0.13 | P14: 340 | Q14: 9545 | R14: 12.1
A15: Q3FY26 | B15: 28446 | C15: 28601 | D15: 0.336 | E15: 0.392 | F15: =B15/C15 | G15: 0.0335 | H15: 326.2 | I15: 186.5 | J15: 0.0192 | K15: 0.139 | L15: 0.174 | M15: 0.0124 | N15: 5211 | O15: 0.13 | P15: 353 | Q15: 9616 | R15: 12.1
A16: Q4FY26 | B16: 29600 | C16: 31053 | D16: 0.341 | E16: 0.399 | F16: =B16/C16 | G16: 0.0338 | H16: 330.8 | I16: 192.2 | J16: 0.0196 | K16: 0.141 | L16: 0.173 | M16: 0.0115 | N16: 4894 | O16: 0.11 | P16: 366 | Q16: 9689 | R16: 12.5
A17: Q1FY27 | B17: 30608 | C17: 31708 | D17: 0.323 | E17: 0.392 | F17: =B17/C17 | G17: 0.0326 | H17: 335.3 | I17: 190.6 | J17: 0.0185 | K17: 0.138 | L17: 0.174 | M17: 0.0117 | N17: 4618 | O17: 0.11 | P17: 379 | Q17: 9694 | R17: 12.4
A18: Q2FY27 | B18: 32195 | C18: 33274 | D18: 0.316 | E18: 0.391 | F18: =B18/C18 | G18: 0.0316 | H18: 346.2 | I18: 195.1 | J18: 0.0178 | K18: 0.135 | L18: 0.171 | M18: 0.0111 | N18: 4890 | O18: 0.11 | P18: 379 | Q18: 9706 | R18: 12.66
A20: Management targets vs record (see note): LDR to 85–90% in FY2027 — 96.8% at Sep-2026; NIM 'upward from the next quarter' (Oct-2026); legacy borrowings ~Rs 2.6 lakh cr to be substituted with deposits.
A21: Q2 FY24 NIM shown is core (3.65%); reported NIM was 3.4% after debt-funded merger costs. Q4 FY24 cost/income includes the HDFC Credila gain (41.3% excluding one-offs).

Sheet Valuation & Verdict
A1: Who captured the value — returns, decomposition and the verdict
A2: Prices: HDFC Bank 1-Apr-2022 Rs 1,506.30 (BSE); 19-Oct-2026 Rs 712.00 (post-bonus = Rs 1,424 pre-bonus). Index returns are price-only (NSE closing files); total-return indices would widen the gap.
A4: TOTAL SHAREHOLDER RETURN, 1-APR-2022 TO 19-OCT-2026
A5: HDFC Bank price, 1-Apr-2022 (Rs) | B5: ='Premium & Precedents'!B6
A6: HDFC Bank price, 19-Oct-2026, pre-bonus equivalent (Rs) | B6: =C6*2 | C6: 712 | D6: <- close, post-bonus (input)
A7: Dividends per pre-bonus share since 1-Apr-2022 (Rs) | B7: 107
A8: HDFC Bank price return | B8: =B6/B5-1
A9: HDFC BANK TOTAL SHAREHOLDER RETURN (dividends not reinvested) | B9: =(B6+B7)/B5-1
A10: Nifty 50, price return | B10: =D10/C10-1 | C10: 17670.45 | D10: 22888.95
A11: Nifty Bank, price return (price index; includes HDFC Bank) | B11: =D11/C11-1 | C11: 37148.5 | D11: 55488.1
A12: Underperformance vs Nifty Bank (pp) | B12: =(B9-B11)*100
A14: A FORMER HDFC LTD SHAREHOLDER (25 SHARES ON 1-APR-2022)
A15: Value on 1-Apr-2022 (25 × Rs 2,450.95) | B15: =25*'Premium & Precedents'!B5
A16: Value today: 42 shares -> 84 after bonus x today's close | B16: =84*C6
A17: HDFC Ltd dividends received (FY22 Rs 30 + FY23 Rs 44, × 25) | B17: =25*(30+44)
A18: HDFC Bank dividends received since the swap | B18: 3045
A19: TOTAL RETURN | B19: =(B16+B17+B18)/B15-1
A21: DECOMPOSITION OF HDFC BANK'S PRICE CHANGE — BOOK GREW, THE MULTIPLE FELL
A22: BVPS, Mar-2022, standalone, reported (Rs) | B22: 433
A23: BVPS, Sep-2026, standalone, pre-bonus equivalent (Rs) | B23: =Scorecard!P18*2
A24: Book value per share growth | B24: =B23/B22-1
A25: P/B on 1-Apr-2022 | B25: =B5/B22
A26: P/B on 19-Oct-2026 | B26: =B6/B23
A27: Change in P/B | B27: =B26/B25-1
A28: Check: (1 + book growth) × (1 + P/B change) − 1 = price return | B28: =ROUND((1+B24)*(1+B27)-1-B8,6)
A30: WHAT DROVE THE MULTIPLE — PROFITABILITY
B31: Bank alone (FY23 / Q1 FY24) | C31: Pro forma at close | D31: Latest (Q2 FY27) | E31: Change vs pro forma (bp)
A32: ROE | B32: ='Acquirer Standalone'!E19 | C32: ='Pro Forma'!D21/'Pro Forma'!D19 | D32: =Scorecard!K18 | E32: =(D32-C32)*10000
A33: NIM on total assets (core) | B33: =Scorecard!G5 | C33: =Scorecard!G6 | D33: =Scorecard!G18 | E33: =(D33-C33)*10000
A34: Loan-to-deposit ratio | B34: =Scorecard!F5 | C34: =Scorecard!F6 | D34: =Scorecard!F18 | E34: =(D34-C34)*10000
A35: CASA ratio | B35: =Scorecard!D5 | C35: =Scorecard!D6 | D35: =Scorecard!D18 | E35: =(D35-C35)*10000
A36: Cost/income | B36: =Scorecard!E5 | C36: =Scorecard!E6 | D36: =Scorecard!E18 | E36: =(D36-C36)*10000
A37: Pro forma ROE = deck's annualised pro forma PAT ÷ pro forma net worth (Dec-2021). Other 'pro forma' values are the first merged quarter (Q2 FY24); NIM is core (reported 3.4%).
A39: VALUE ACROSS THE WHOLE GROUP (APPROXIMATE)
A40: Combined unaffected value: bank + HDFC Ltd − cross-holding (Rs crore) | B40: ='Deal Terms'!B23*'Premium & Precedents'!B6+'Premium & Precedents'!B12-'Deal Terms'!B25*'Premium & Precedents'!B6
A41: HDFC Bank market value today (shares today x close) | B41: =C41*C6 | C41: 1541.86 | D41: <- shares today, crore (6-K paid-up capital Rs 1,541.86 cr, FV Re 1)
A42: Change in combined value | B42: =B41/B40-1
A43: Value had the combined group tracked Nifty Bank (price) | B43: =B40*(1+B11)
A44: RELATIVE VALUE SHORTFALL VS NIFTY BANK (approx.) | B44: =B43-B41
A46: WHAT ELSE HAPPENED — GOVERNANCE AND THE SECTOR
...

Sheet Sensitivities
A1: Sensitivities
A2: Each grid recomputes from the inputs on Synergies and Accretion-Dilution; base-case cells are checked against the source sheets.
A4: 1) PRESENT VALUE OF THE CRR/SLR DRAG (Rs crore) — loan yield (rows) × years of transition (columns), discounted at Synergies!B24
A5: Loan yield ↓ / years → | B5: 2 yrs | C5: 3 yrs | D5: 4 yrs | E5: 5 yrs | F5: 6 yrs
A6: 0.08 | B6: =Synergies!$B$12*(Synergies!$B$13*$A6+Synergies!$B$14*($A6-Synergies!$B$16))*(1-Synergies!$B$17)*(1-(1+Synergies!$B$24)^-2)/Synergies!$B$24 | C6: =Synergies!$B$12*(Synergies!$B$13*$A6+Synergies!$B$14*($A6-Synergies!$B$16))*(1-Synergies!$B$17)*(1-(1+Synergies!$B$24)^-3)/Synergies!$B$24 | D6: =Synergies!$B$12*(Synergies!$B$13*$A6+Synergies!$B$14*($A6-Synergies!$B$16))*(1-Synergies!$B$17)*(1-(1+Synergies!$B$24)^-4)/Synergies!$B$24 | E6: =Synergies!$B$12*(Synergies!$B$13*$A6+Synergies!$B$14*($A6-Synergies!$B$16))*(1-Synergies!$B$17)*(1-(1+Synergies!$B$24)^-5)/Synergies!$B$24 | F6: =Synergies!$B$12*(Synergies!$B$13*$A6+Synergies!$B$14*($A6-Synergies!$B$16))*(1-Synergies!$B$17)*(1-(1+Synergies!$B$24)^-6)/Synergies!$B$24
A7: 0.083 | B7: =Synergies!$B$12*(Synergies!$B$13*$A7+Synergies!$B$14*($A7-Synergies!$B$16))*(1-Synergies!$B$17)*(1-(1+Synergies!$B$24)^-2)/Synergies!$B$24 | C7: =Synergies!$B$12*(Synergies!$B$13*$A7+Synergies!$B$14*($A7-Synergies!$B$16))*(1-Synergies!$B$17)*(1-(1+Synergies!$B$24)^-3)/Synergies!$B$24 | D7: =Synergies!$B$12*(Synergies!$B$13*$A7+Synergies!$B$14*($A7-Synergies!$B$16))*(1-Synergies!$B$17)*(1-(1+Synergies!$B$24)^-4)/Synergies!$B$24 | E7: =Synergies!$B$12*(Synergies!$B$13*$A7+Synergies!$B$14*($A7-Synergies!$B$16))*(1-Synergies!$B$17)*(1-(1+Synergies!$B$24)^-5)/Synergies!$B$24 | F7: =Synergies!$B$12*(Synergies!$B$13*$A7+Synergies!$B$14*($A7-Synergies!$B$16))*(1-Synergies!$B$17)*(1-(1+Synergies!$B$24)^-6)/Synergies!$B$24
A8: 0.086 | B8: =Synergies!$B$12*(Synergies!$B$13*$A8+Synergies!$B$14*($A8-Synergies!$B$16))*(1-Synergies!$B$17)*(1-(1+Synergies!$B$24)^-2)/Synergies!$B$24 | C8: =Synergies!$B$12*(Synergies!$B$13*$A8+Synergies!$B$14*($A8-Synergies!$B$16))*(1-Synergies!$B$17)*(1-(1+Synergies!$B$24)^-3)/Synergies!$B$24 | D8: =Synergies!$B$12*(Synergies!$B$13*$A8+Synergies!$B$14*($A8-Synergies!$B$16))*(1-Synergies!$B$17)*(1-(1+Synergies!$B$24)^-4)/Synergies!$B$24 | E8: =Synergies!$B$12*(Synergies!$B$13*$A8+Synergies!$B$14*($A8-Synergies!$B$16))*(1-Synergies!$B$17)*(1-(1+Synergies!$B$24)^-5)/Synergies!$B$24 | F8: =Synergies!$B$12*(Synergies!$B$13*$A8+Synergies!$B$14*($A8-Synergies!$B$16))*(1-Synergies!$B$17)*(1-(1+Synergies!$B$24)^-6)/Synergies!$B$24
A9: 0.089 | B9: =Synergies!$B$12*(Synergies!$B$13*$A9+Synergies!$B$14*($A9-Synergies!$B$16))*(1-Synergies!$B$17)*(1-(1+Synergies!$B$24)^-2)/Synergies!$B$24 | C9: =Synergies!$B$12*(Synergies!$B$13*$A9+Synergies!$B$14*($A9-Synergies!$B$16))*(1-Synergies!$B$17)*(1-(1+Synergies!$B$24)^-3)/Synergies!$B$24 | D9: =Synergies!$B$12*(Synergies!$B$13*$A9+Synergies!$B$14*($A9-Synergies!$B$16))*(1-Synergies!$B$17)*(1-(1+Synergies!$B$24)^-4)/Synergies!$B$24 | E9: =Synergies!$B$12*(Synergies!$B$13*$A9+Synergies!$B$14*($A9-Synergies!$B$16))*(1-Synergies!$B$17)*(1-(1+Synergies!$B$24)^-5)/Synergies!$B$24 | F9: =Synergies!$B$12*(Synergies!$B$13*$A9+Synergies!$B$14*($A9-Synergies!$B$16))*(1-Synergies!$B$17)*(1-(1+Synergies!$B$24)^-6)/Synergies!$B$24
A10: 0.092 | B10: =Synergies!$B$12*(Synergies!$B$13*$A10+Synergies!$B$14*($A10-Synergies!$B$16))*(1-Synergies!$B$17)*(1-(1+Synergies!$B$24)^-2)/Synergies!$B$24 | C10: =Synergies!$B$12*(Synergies!$B$13*$A10+Synergies!$B$14*($A10-Synergies!$B$16))*(1-Synergies!$B$17)*(1-(1+Synergies!$B$24)^-3)/Synergies!$B$24 | D10: =Synergies!$B$12*(Synergies!$B$13*$A10+Synergies!$B$14*($A10-Synergies!$B$16))*(1-Synergies!$B$17)*(1-(1+Synergies!$B$24)^-4)/Synergies!$B$24 | E10: =Synergies!$B$12*(Synergies!$B$13*$A10+Synergies!$B$14*($A10-Synergies!$B$16))*(1-Synergies!$B$17)*(1-(1+Synergies!$B$24)^-5)/Synergies!$B$24 | F10: =Synergies!$B$12*(Synergies!$B$13*$A10+Synergies!$B$14*($A10-Synergies!$B$16))*(1-Synergies!$B$17)*(1-(1+Synergies!$B$24)^-6)/Synergies!$B$24
A11: Base-case check: 8.6% row, 3-year column vs Synergies!B26 (must be 0) | B11: =ROUND(C8-Synergies!B26,0)
A12: Compare with the ~Rs 14,500 cr gross premium and ~Rs 8,500 cr net transfer: at 3–4 years the PV is roughly half the gross premium and close to the net transfer.
A13: Lower bound (computed on Synergies rows 47-51): base Rs 4.6 lakh cr, 8.0% net loan yield, 100bp SLR spread -> ~Rs 1,860 cr a year after tax, ~Rs 4,400 cr PV over 3 years.
A14: 2) EPS ACCRETION / (DILUTION) AT ANNOUNCEMENT — funding-cost saving on HDFC Ltd's book (rows, bp) × share of the CRR/SLR drag borne (columns)
A15: Saving (bp) ↓ / drag borne → | B15: 0% | C15: 25% | D15: 50% | E15: 75% | F15: 100%
A16: 0 | B16: =(('Accretion-Dilution'!$D$6+'Accretion-Dilution'!$B$12*$A16/10000*(1-Synergies!$B$17)-'Accretion-Dilution'!$B$13*0)/'Accretion-Dilution'!$D$7)/'Accretion-Dilution'!$B$8-1 | C16: =(('Accretion-Dilution'!$D$6+'Accretion-Dilution'!$B$12*$A16/10000*(1-Synergies!$B$17)-'Accretion-Dilution'!$B$13*0.25)/'Accretion-Dilution'!$D$7)/'Accretion-Dilution'!$B$8-1 | D16: =(('Accretion-Dilution'!$D$6+'Accretion-Dilution'!$B$12*$A16/10000*(1-Synergies!$B$17)-'Accretion-Dilution'!$B$13*0.5)/'Accretion-Dilution'!$D$7)/'Accretion-Dilution'!$B$8-1 | E16: =(('Accretion-Dilution'!$D$6+'Accretion-Dilution'!$B$12*$A16/10000*(1-Synergies!$B$17)-'Accretion-Dilution'!$B$13*0.75)/'Accretion-Dilution'!$D$7)/'Accretion-Dilution'!$B$8-1 | F16: =(('Accretion-Dilution'!$D$6+'Accretion-Dilution'!$B$12*$A16/10000*(1-Synergies!$B$17)-'Accretion-Dilution'!$B$13*1.0)/'Accretion-Dilution'!$D$7)/'Accretion-Dilution'!$B$8-1
A17: 25 | B17: =(('Accretion-Dilution'!$D$6+'Accretion-Dilution'!$B$12*$A17/10000*(1-Synergies!$B$17)-'Accretion-Dilution'!$B$13*0)/'Accretion-Dilution'!$D$7)/'Accretion-Dilution'!$B$8-1 | C17: =(('Accretion-Dilution'!$D$6+'Accretion-Dilution'!$B$12*$A17/10000*(1-Synergies!$B$17)-'Accretion-Dilution'!$B$13*0.25)/'Accretion-Dilution'!$D$7)/'Accretion-Dilution'!$B$8-1 | D17: =(('Accretion-Dilution'!$D$6+'Accretion-Dilution'!$B$12*$A17/10000*(1-Synergies!$B$17)-'Accretion-Dilution'!$B$13*0.5)/'Accretion-Dilution'!$D$7)/'Accretion-Dilution'!$B$8-1 | E17: =(('Accretion-Dilution'!$D$6+'Accretion-Dilution'!$B$12*$A17/10000*(1-Synergies!$B$17)-'Accretion-Dilution'!$B$13*0.75)/'Accretion-Dilution'!$D$7)/'Accretion-Dilution'!$B$8-1 | F17: =(('Accretion-Dilution'!$D$6+'Accretion-Dilution'!$B$12*$A17/10000*(1-Synergies!$B$17)-'Accretion-Dilution'!$B$13*1.0)/'Accretion-Dilution'!$D$7)/'Accretion-Dilution'!$B$8-1
A18: 50 | B18: =(('Accretion-Dilution'!$D$6+'Accretion-Dilution'!$B$12*$A18/10000*(1-Synergies!$B$17)-'Accretion-Dilution'!$B$13*0)/'Accretion-Dilution'!$D$7)/'Accretion-Dilution'!$B$8-1 | C18: =(('Accretion-Dilution'!$D$6+'Accretion-Dilution'!$B$12*$A18/10000*(1-Synergies!$B$17)-'Accretion-Dilution'!$B$13*0.25)/'Accretion-Dilution'!$D$7)/'Accretion-Dilution'!$B$8-1 | D18: =(('Accretion-Dilution'!$D$6+'Accretion-Dilution'!$B$12*$A18/10000*(1-Synergies!$B$17)-'Accretion-Dilution'!$B$13*0.5)/'Accretion-Dilution'!$D$7)/'Accretion-Dilution'!$B$8-1 | E18: =(('Accretion-Dilution'!$D$6+'Accretion-Dilution'!$B$12*$A18/10000*(1-Synergies!$B$17)-'Accretion-Dilution'!$B$13*0.75)/'Accretion-Dilution'!$D$7)/'Accretion-Dilution'!$B$8-1 | F18: =(('Accretion-Dilution'!$D$6+'Accretion-Dilution'!$B$12*$A18/10000*(1-Synergies!$B$17)-'Accretion-Dilution'!$B$13*1.0)/'Accretion-Dilution'!$D$7)/'Accretion-Dilution'!$B$8-1
A19: 75 | B19: =(('Accretion-Dilution'!$D$6+'Accretion-Dilution'!$B$12*$A19/10000*(1-Synergies!$B$17)-'Accretion-Dilution'!$B$13*0)/'Accretion-Dilution'!$D$7)/'Accretion-Dilution'!$B$8-1 | C19: =(('Accretion-Dilution'!$D$6+'Accretion-Dilution'!$B$12*$A19/10000*(1-Synergies!$B$17)-'Accretion-Dilution'!$B$13*0.25)/'Accretion-Dilution'!$D$7)/'Accretion-Dilution'!$B$8-1 | D19: =(('Accretion-Dilution'!$D$6+'Accretion-Dilution'!$B$12*$A19/10000*(1-Synergies!$B$17)-'Accretion-Dilution'!$B$13*0.5)/'Accretion-Dilution'!$D$7)/'Accretion-Dilution'!$B$8-1 | E19: =(('Accretion-Dilution'!$D$6+'Accretion-Dilution'!$B$12*$A19/10000*(1-Synergies!$B$17)-'Accretion-Dilution'!$B$13*0.75)/'Accretion-Dilution'!$D$7)/'Accretion-Dilution'!$B$8-1 | F19: =(('Accretion-Dilution'!$D$6+'Accretion-Dilution'!$B$12*$A19/10000*(1-Synergies!$B$17)-'Accretion-Dilution'!$B$13*1.0)/'Accretion-Dilution'!$D$7)/'Accretion-Dilution'!$B$8-1
A20: 100 | B20: =(('Accretion-Dilution'!$D$6+'Accretion-Dilution'!$B$12*$A20/10000*(1-Synergies!$B$17)-'Accretion-Dilution'!$B$13*0)/'Accretion-Dilution'!$D$7)/'Accretion-Dilution'!$B$8-1 | C20: =(('Accretion-Dilution'!$D$6+'Accretion-Dilution'!$B$12*$A20/10000*(1-Synergies!$B$17)-'Accretion-Dilution'!$B$13*0.25)/'Accretion-Dilution'!$D$7)/'Accretion-Dilution'!$B$8-1 | D20: =(('Accretion-Dilution'!$D$6+'Accretion-Dilution'!$B$12*$A20/10000*(1-Synergies!$B$17)-'Accretion-Dilution'!$B$13*0.5)/'Accretion-Dilution'!$D$7)/'Accretion-Dilution'!$B$8-1 | E20: =(('Accretion-Dilution'!$D$6+'Accretion-Dilution'!$B$12*$A20/10000*(1-Synergies!$B$17)-'Accretion-Dilution'!$B$13*0.75)/'Accretion-Dilution'!$D$7)/'Accretion-Dilution'!$B$8-1 | F20: =(('Accretion-Dilution'!$D$6+'Accretion-Dilution'!$B$12*$A20/10000*(1-Synergies!$B$17)-'Accretion-Dilution'!$B$13*1.0)/'Accretion-Dilution'!$D$7)/'Accretion-Dilution'!$B$8-1
A21: Check: 0 bp / 0% cell = deck accretion; 0 bp / 100% cell = adjusted (both must be 0) | B21: =ROUND(B16-'Accretion-Dilution'!D9,6) | F21: =ROUND(F16-'Accretion-Dilution'!D15,6)
A23: 3) JUSTIFIED P/B = (ROE − g) ÷ (Ke − g), g = 8% — ROE (rows) × cost of equity (columns)
A24: ROE ↓ / Ke → | B24: 12.0% | C24: 12.5% | D24: 13.0% | E24: 13.5% | F24: 14.0% | H24: 0.08 | I24: ← growth g (input)
A25: 0.12 | B25: =($A25-$H$24)/(0.12-$H$24) | C25: =($A25-$H$24)/(0.125-$H$24) | D25: =($A25-$H$24)/(0.13-$H$24) | E25: =($A25-$H$24)/(0.135-$H$24) | F25: =($A25-$H$24)/(0.14-$H$24)
A26: 0.135 | B26: =($A26-$H$24)/(0.12-$H$24) | C26: =($A26-$H$24)/(0.125-$H$24) | D26: =($A26-$H$24)/(0.13-$H$24) | E26: =($A26-$H$24)/(0.135-$H$24) | F26: =($A26-$H$24)/(0.14-$H$24)
A27: 0.15 | B27: =($A27-$H$24)/(0.12-$H$24) | C27: =($A27-$H$24)/(0.125-$H$24) | D27: =($A27-$H$24)/(0.13-$H$24) | E27: =($A27-$H$24)/(0.135-$H$24) | F27: =($A27-$H$24)/(0.14-$H$24)
A28: 0.165 | B28: =($A28-$H$24)/(0.12-$H$24) | C28: =($A28-$H$24)/(0.125-$H$24) | D28: =($A28-$H$24)/(0.13-$H$24) | E28: =($A28-$H$24)/(0.135-$H$24) | F28: =($A28-$H$24)/(0.14-$H$24)
A29: 0.18 | B29: =($A29-$H$24)/(0.12-$H$24) | C29: =($A29-$H$24)/(0.125-$H$24) | D29: =($A29-$H$24)/(0.13-$H$24) | E29: =($A29-$H$24)/(0.135-$H$24) | F29: =($A29-$H$24)/(0.14-$H$24)
A30: ROE the current P/B implies at Ke 13% and g 8% | B30: =$H$24+'Valuation & Verdict'!B26*(0.13-$H$24)
A31: Illustrative, not a valuation call: the current P/B implies the market expects ROE to recover above today's 13.5%. Ke is a desk assumption (India 10-yr 7.40%, Oct-2026).

Sheet Evidence
A1: Evidence — sources for every input
A2: Full URL list: research packs DEALS/HDFC-HDFCBANK/_build/HDFC_DEAL_TERMS.md and HDFC_SCORECARD.md.
A4: Input | B4: Value | C4: Source | D4: Date
A5: Swap ratio, structure, valuers, fairness opinions | B5: 42 : 25 | C5: HDFC Ltd / HDFC Bank Reg 30 intimations; HDFC Bank 6-K | D5: 4-Apr-2022
A6: Unaffected closes | B6: Rs 2,450.95 / Rs 1,506.30 | C6: Business Today (BSE previous close); back-calculated from Business Standard 4-Apr moves; deck market caps | D6: 1-Apr-2022
A7: Announcement-day closes and m-cap change | B7: Rs 2,678.90 / Rs 1,656.45 | C7: Business Standard | D7: 4-Apr-2022
A8: Shares issued / cancelled / outstanding | B8: 311.04 / 116.46 / 753.76 cr | C8: HDFC Bank allotment intimation (BSE) | D8: 14-Jul-2023
A9: RBI forbearance decisions | B9: CRR/SLR/LCR refused; PSL phased | C9: HDFC Bank disclosure (BSE) | D9: 21-Apr-2023
A10: Shareholder vote | B10: 99.681% for | C10: HDFC Bank 6-K; meeting proceedings | D10: 25/26-Nov-2022
A11: HDFC Ltd financials FY20–FY23 | B11: see Target Standalone | C11: HDFC Ltd annual report FY22; Q4 FY23 call; Business Standard (FY20–21 results) | D11: 2020–2023
A12: HDFC Bank financials FY20–FY23 | B12: see Acquirer Standalone | C12: HDFC Bank 6-K results filings (SEC EDGAR) | D12: 2020–2023
A13: Deck pro forma | B13: EPS ~65 → ~67; BVPS 414 → 446 | C13: Announcement deck (HDFC Ltd Reg 30, Annexure) | D13: 4-Apr-2022
A14: Quarterly scorecard Q1 FY24–Q2 FY27 | B14: see Scorecard | C14: HDFC Bank results releases and presentations; 6-K | D14: Jul-2023 – Oct-2026
A15: HDFC Bank close | B15: Rs 712.00 | C15: StockAnalysis / NSE history (20-Oct market holiday) | D15: 19-Oct-2026
... A21: India 10-yr G-sec (for Ke) | B21: 7.40% | C21: RBI market rates | D21: 19-Oct-2026
