Workbook

Sheet Cover
A1: DEAL DECODED #2 · SUN PHARMA / ORGANON
A2: Outside-in analysis from public filings. Debjit Mukherjee, IB Independent. Market data to 28-Oct-2026. Live deal — not investment advice.
A4: HEADLINE OUTPUTS
A5: Offer per share ($) | B5: ='Deal Terms'!B20 -> 14
A6: Equity value ($m) | B6: ='Deal Terms'!B22 -> 3988.6
A7: Enterprise value, headline ($m) | B7: ='Deal Terms'!B27 -> 11750
A8: Premium to unaffected | B8: ='Premium & Precedents'!B7 -> 1.0260492
A9: EV / LTM adjusted EBITDA | B9: ='Premium & Precedents'!B19 -> 6.2874454
A10: Premium paid ($m) | B10: ='Premium & Precedents'!B16 -> 2019.941
A11: PV of synergies, net of cost to achieve ($m) | B11: =Synergies!B27 -> 1802.8785
A12: Premium ÷ PV of synergies | B12: =Synergies!B30 -> 1.1203977
A13: Standalone value per share, desk DCF ($) | B13: ='Valuation & Verdict'!B21 -> 10.277093
A14: Value to Sun incl. synergies, per share ($) | B14: ='Valuation & Verdict'!B37 -> 16.605203
A15: NPV to Sun shareholders ($m) | B15: ='Valuation & Verdict'!B39 -> 360.82232
A16: Share of Sun's guide needed to break even | B16: ='Valuation & Verdict'!B42 -> 0.82169026
A17: EPS accretion FY2028E, reported basis | B17: ='Accretion-Dilution'!B32 -> 0.11575973
A18: Pro forma net debt / EBITDA | B18: ='Pro Forma'!B19 -> 2.4676356
A19: Annualised arbitrage spread | B19: ='Spread & Odds'!B12 -> 0.072535767
A20: Implied probability of closing | B20: ='Spread & Odds'!B18 -> 0.98312762
A22: CHECKS (ALL MUST READ PASS)
A23: Equity value within 0.5% of Sun's stated $3.99bn | B23: =IF(ABS('Deal Terms'!B24)<0.005,"PASS","FAIL") -> PASS
A24: Premium to unaffected matches the proxy's ~103% | B24: =IF('Premium & Precedents'!B8=0,"PASS","FAIL") -> PASS
A25: Pro forma leverage within 0.3x of Sun's stated 2.3x | B25: =IF(ABS('Pro Forma'!B19-'Pro Forma'!B20)<=0.3,"PASS","FAIL") -> PASS
A26: Acquisition debt within the $12bn bridge | B26: =IF('Pro Forma'!B9>=0,"PASS","FAIL") -> PASS
A27: DCF reproduces Morgan Stanley's range within ±5% at each end | B27: =IF(AND(ABS('Valuation & Verdict'!B31)<=0.05,ABS('Valuation & Verdict'!C31)<=0.05),"PASS","FAIL") -> PASS
A28: Sensitivity grids tie to their source sheets | B28: =IF(AND(Sensitivities!B11=0,Sensitivities!B21=0,Sensitivities!B30=0,Sensitivities!B39=0,Sensitivities!B48=0),"PASS","FAIL") -> PASS
A31: TAB MAP
A32: Deal Terms — snapshot, price arithmetic, the auction
A33: Target Standalone — history, balance sheet, management projections
A34: Acquirer Standalone — Sun Pharma
A35: Premium & Precedents — what was paid; Morgan Stanley's ranges
A36: Synergies — PV and the share paid away
A37: Accretion-Dilution — EPS, the bridge to the Sun note, ROIC
A38: Pro Forma — sources & uses, leverage
A39: Spread & Odds — the live arbitrage
A40: Valuation & Verdict — DCF reconciled to Morgan Stanley, value to Sun, verdict
A41: Sensitivities — five grids
A42: Evidence — sources

Sheet Deal Terms
A1: Sun Pharma / Organon — Deal Terms
A2: Source: Organon DEFM14A (17-Jun-2026), 8-Ks, Q2 2026 10-Q; Sun Pharma release and investor call (27-Apr-2026). US$ millions unless stated. Blue = input, black = formula, green = cross-sheet link.
A4: DEAL SNAPSHOT
A5: Acquirer | B5: Sun Pharmaceutical Industries Ltd, via Sun Pharmaceutical Holdings USA, Inc.
A6: Target | B6: Organon & Co. (NYSE: OGN) — women's health, biosimilars, established brands; spun off from Merck in June 2021
A7: Signed / announced | B7: 26-Apr-2026 (signed) / announced before the Indian open, 27-Apr-2026
A8: Consideration | B8: All cash, $14.00 per Organon share; no financing condition
A9: Organon stockholder vote | B9: Approved 23-Jul-2026 (special meeting)
A10: Expected close | B10: 'Early 2027' (Organon 10-Q, 31-Jul-2026); Sun said 6–9 months on 27-Apr-2026
A11: Outside date | B11: 26-Jan-2027, extendable by either party to 26-Apr-2027
A12: Approvals outstanding | B12: Non-US antitrust, foreign direct investment and EU Foreign Subsidies Regulation clearances. HSR filed 21-May-2026, waiting period scheduled to expire 22-Jun-2026 (no later filing mentions HSR). Sun also has Indian overseas-investment filings to make. Australia (ACCC MN-35035): notified 22-Oct-2026, Phase 1 ends 3-Dec-2026; Sun has offered to license its generic ganirelix in Australia to Ferring
A13: Organon advisers | B13: Morgan Stanley (fairness opinion; fee ~$39.4m, $35.4m contingent on closing); Goldman Sachs (other alternatives); Sullivan & Cromwell
A14: Sun advisers | B14: J.P. Morgan, Jefferies; White & Case, AZB & Partners
A15: Financing | B15: Committed senior secured bridge up to $12bn (Citi, JPMorgan, MUFG lead); Sun cash $2.0–2.5bn; $1bn Sun funding commitment and affiliate guarantees
A16: Termination fee (Organon pays) | B16: $120m in specified circumstances; no reverse termination fee in the signed agreement
A17: Stated rationale | B17: 'a stronger and more diversified platform' (D. Shanghvi); 'a logical next step in strengthening Sun Pharma's global business' (K. Ganorkar)
A19: PRICE ARITHMETIC
A20: Offer price per share ($) | B20: 14
A21: Fully diluted shares, 24-Apr-2026, treasury method (m) | B21: 284.9
A22: EQUITY VALUE ($m) | B22: =B20*B21 -> 3988.6
A23: Sun's stated equity value on the call ($m) — check | B23: 3990
A24: Difference vs stated (must be within 0.5%) | B24: =B22/B23-1 -> -0.00035087719
A25: Net debt, 31-Mar-2026, per the proxy ($m) | B25: 7530
A26: ENTERPRISE VALUE, proxy basis ($m) | B26: =B22+B25 -> 11518.6
A27: Headline enterprise value in the release ($m) | B27: 11750
A28: Headline less proxy-basis EV ($m) — other debt-like items and timing | B28: =B27-B26 -> 231.4
A29: Termination fee ($m) | B29: 120
A30: as % of equity value | B30: =B29/B22 -> 0.030085744
A31: Shares outstanding at the record date, 15-Jun-2026 (m) | B31: 262.60943
A32: Dilutive equity awards implied (fully diluted less basic, m) | B32: =B21-B31 -> 22.290567
A34: THE AUCTION — EVERY PRICE IN THE PROXY'S BACKGROUND SECTION
A35: Date | B35: Bidder | C35: Proposal | D35: Low ($) | E35: High ($) | F35: OGN close that day ($) | G35: Mid premium to that close
A36: 31-Oct-2025 | B36: Party B (private healthcare holdco) | C36: US business only, $3.3bn
A37: 08-Dec-2025 | B37: Party B | C37: 100% of Organon | D37: 10.03 | E37: 10.03 | F37: 7.29 | G37: =AVERAGE(D37:E37)/F37-1 -> 0.37585734
A38: 17-Dec-2025 | B38: Sun Pharma | C38: First price range | D38: 12 | E38: 14 | F38: 6.99 | G38: =AVERAGE(D38:E38)/F38-1 -> 0.85979971
A39: 27-Jan-2026 | B39: Party B | C39: Revised | D39: 10.5 | E39: 11.5 | F39: 9 | G39: =AVERAGE(D39:E39)/F39-1 -> 0.22222222
A40: 29-Jan-2026 | B40: Sun Pharma | C40: Revised IOI — rejected by the Board | D40: 13.5 | E40: 13.5 | F40: 8.6 | G40: =AVERAGE(D40:E40)/F40-1 -> 0.56976744
A41: 18-Feb-2026 | B41: Party D (financial sponsor) | C41: IOI | D41: 9.5 | E41: 10.5 | F41: 7.46 | G41: =AVERAGE(D41:E41)/F41-1 -> 0.34048257
A42: 02-Mar-2026 | B42: Party C (European pharma) | C42: Offer | D42: 11.75 | E42: 11.75 | F42: 7.19 | G42: =AVERAGE(D42:E42)/F42-1 -> 0.63421419
A43: 09-Mar-2026 | B43: Party D | C43: Non-binding offer; no final bid | D43: 12 | E43: 14 | F43: 6.53 | G43: =AVERAGE(D43:E43)/F43-1 -> 0.99081164
...

Sheet Target Standalone
A1: Organon (target) — standalone history and management projections
A2: Source: Organon 10-K FY2025, Q4 2025 results release (12-Feb-2026), Q2 2026 10-Q, DEFM14A 'Organon Projections' (prepared March 2026). US$ millions.
A4: HISTORY (US GAAP, FISCAL YEARS TO DECEMBER)
B5: FY2023 | C5: FY2024 | D5: FY2025
A6: Revenue | B6: 6263 | C6: 6403 | D6: 6216
A7: Cost of sales | B7: 2515 | C7: 2688 | D7: 2903
A8: Gross profit | B8: =B6-B7 -> 3748 | C8: =C6-C7 -> 3715 | D8: =D6-D7 -> 3313
A9: SG&A | B9: 1893 | C9: 1760 | D9: 1721
A10: R&D | B10: 528 | C10: 469 | D10: 366
A11: Interest expense | B11: 527 | C11: 520 | D11: 504
A12: Net income | B12: 1023 | C12: 864 | D12: 187
A13: Diluted EPS ($) | B13: 3.99 | C13: 3.33 | D13: 0.72
A14: Adjusted EBITDA (company, non-GAAP) | C14: 1958 | D14: 1907
A15: Depreciation | B15: 120 | C15: 132 | D15: 156
A16: Amortisation | B16: 116 | C16: 145 | D16: 205
A17: Cash from operations | B17: 799 | C17: 939 | D17: 700
A18: Capital expenditure | B18: 251 | C18: 175 | D18: 162
A19: Nexplanon/Implanon NXT revenue | C19: 963 | D19: 921
A20: Free cash flow (CFO less capex) | B20: =B17-B18 -> 548 | C20: =C17-C18 -> 764 | D20: =D17-D18 -> 538
A21: Adjusted EBITDA margin | C21: =C14/C6 -> 0.30579416 | D21: =D14/D6 -> 0.30678893
A22: Nexplanon share of revenue | C22: =C19/C6 -> 0.15039825 | D22: =D19/D6 -> 0.14816602
A23: Revenue growth | C23: =C6/B6-1 -> 0.022353505 | D23: =D6/C6-1 -> -0.02920506
A24: FY2025 net income includes a $301m goodwill impairment. Nexplanon: US rod patents expire 2027 and 2030; a Paragraph IV filer (Xiromed) was sued in April 2025; the SEC has opened an investigation into the wholesaler sales-practices matter.
A26: BALANCE SHEET, 30-JUN-2026 (10-Q)
A27: Cash and cash equivalents | B27: 1132
A28: Total principal debt | B28: 8553
A29: Net debt, 30-Jun-2026 | B29: =B28-B27 -> 7421
A30: Goodwill | B30: 4153
A31: Intangibles, net | B31: 1112
A32: Total stockholders' equity | B32: 1006
A33: Weighted-average interest rate on borrowings | B33: 0.049
A34: Average debt maturity (years) | B34: 4.1
A36: MANAGEMENT PROJECTIONS (THE 'ORGANON PROJECTIONS', DEFM14A p.64) — the case the seller's banker valued
B37: Q2'26E | C37: Q3'26E | D37: Q4'26E | E37: 2026E | F37: 2027E | G37: 2028E | H37: 2029E | I37: 2030E
A38: Revenue | B38: 1546 | C38: 1613 | D38: 1632 | E38: 6252 | F38: 6475 | G38: 6693 | H38: 6822 | I38: 6470
A39: Adjusted EBITDA | B39: 451 | C39: 507 | D39: 522 | E39: 1894 | F39: 2018 | G39: 2099 | H39: 2150 | I39: 1986
A40: Unlevered free cash flow | B40: 118 | C40: 49 | D40: 338 | E40: 1010 | F40: 714 | G40: 958 | H40: 1117 | I40: 774
A41: Adjusted EBITDA margin | B41: =B39/B38 -> 0.29172057 | C41: =C39/C38 -> 0.31432114 | D41: =D39/D38 -> 0.31985294 | E41: =E39/E38 -> 0.30294306 | F41: =F39/F38 -> 0.31166023 | G41: =G39/G38 -> 0.31361124 | H41: =H39/H38 -> 0.31515685 | I41: =I39/I38 -> 0.30695518
A42: UFCF / Adjusted EBITDA (cash conversion) | B42: =B40/B39 -> 0.2616408 | C42: =C40/C39 -> 0.096646943 | D42: =D40/D39 -> 0.64750958 | E42: =E40/E39 -> 0.53326294 | F42: =F40/F39 -> 0.35381566 | G42: =G40/G39 -> 0.45640781 | H42: =H40/H39 -> 0.51953488 | I42: =I40/I39 -> 0.3897281
A43: Revenue CAGR 2026E–2030E | B43: =(I38/E38)^(1/4)-1 -> 0.0086054902
...

Sheet Acquirer Standalone
A1: Sun Pharma (acquirer) — standalone
A2: Source: desk Sun Pharma model (COVERAGE/SUN PHARMA, published 07-Sep-2026, built from company filings); prices NSE close 28-Oct-2026; Sun investor call 27-Apr-2026.
A5: Share price, 28-Oct-2026 (Rs) | B5: 1757.5
A6: Shares outstanding (crore) | B6: 239.93
A7: Market capitalisation (Rs crore) | B7: =B5*B6 -> 421676.97
A8: FY2026 EPS (Rs) | B8: 47.84
A9: TTM revenue (Rs crore) | B9: 59911
A10: TTM net profit (Rs crore) | B10: 12117
A11: Net cash before the deal (Rs crore) | B11: 20096
A12: of which investments / treasury (Rs crore) | B12: 24723
A13: of which borrowings (Rs crore) | B13: 4627
A14: Standalone EBITDA, FY2027E (Rs crore, desk) | B14: 18416
A15: Standalone EPS FY2028E (Rs, desk) | B15: 57.07
A16: Standalone EPS FY2029E (Rs, desk) | B16: 61.53
A17: Standalone EPS FY2030E (Rs, desk) | B17: 66.04
A18: Trailing P/E (x) | B18: =B5/B8 -> 36.73704
A19: USD/INR, 28-Oct-2026 | B19: 95.18
A20: USD/INR, 27-Apr-2026 (announcement) | B20: 94.2585
A22: Deal cost in rupees at signing FX (Rs crore) | B22: =Synergies!B6*B20/10 -> 110753.74
A23: Deal cost in rupees at today's FX (Rs crore) | B23: =Synergies!B6*B19/10 -> 111836.5
A24: Rupee cost added by currency since signing (Rs crore) | B24: =B23-B22 -> 1082.7625
A25: Sun's financial year ends 31 March, so Organon's calendar 2027 sits almost exactly in Sun's FY2028 — the first full year of ownership.

Sheet Premium & Precedents
A1: What was paid — premium, implied multiples, precedents
A2: Source: DEFM14A (premia, Morgan Stanley reference ranges), NYSE closes; multiples computed here on the proxy-basis EV.
A4: PREMIUM
A5: Offer price ($) | B5: ='Deal Terms'!B20 -> 14
A6: Unaffected close, 9-Apr-2026 — the proxy's unaffected date (a 19-Jan-2026 press report preceded it) ($) | B6: 6.91
A7: PREMIUM TO UNAFFECTED | B7: =B5/B6-1 -> 1.0260492
A8: Proxy states ~103% — check (difference) | B8: =ROUND(B7-C8,2) -> 0 | C8: 1.03
A9: Close 23-Apr-2026 (after the first leak, before the $13bn report) ($) | B9: 8.6
A10: Premium to 23-Apr-2026 close | B10: =B5/B9-1 -> 0.62790698
A11: Premium to 30-day VWAP through the unaffected date (proxy) | B11: 1.2
A12: Premium to close on 24-Oct-2025, before the CEO change and sales-practices announcement (proxy) | B12: 0.53
A13: 52-week intraday high before the unaffected date ($) | B13: 13.25
A14: Premium to 52-week high | B14: =B5/B13-1 -> 0.056603774
A15: Unaffected equity value ($m) | B15: =B6*'Deal Terms'!B21 -> 1968.659
A16: PREMIUM PAID IN DOLLARS (equity value less unaffected) | B16: ='Deal Terms'!B22-B15 -> 2019.941
A18: IMPLIED MULTIPLES (proxy-basis EV)
A19: EV / LTM adjusted EBITDA (31-Mar-2026) | B19: ='Deal Terms'!B26/'Target Standalone'!B44 -> 6.2874454
A20: EV / 2026E adjusted EBITDA | B20: ='Deal Terms'!B26/'Target Standalone'!E39 -> 6.0816262
A21: EV / 2027E adjusted EBITDA | B21: ='Deal Terms'!B26/'Target Standalone'!F39 -> 5.7079286
A22: EV / FY2025 revenue | B22: ='Deal Terms'!B26/'Target Standalone'!D6 -> 1.8530566
A23: Price / FY2025 adjusted EPS ($3.66) | B23: =B5/C23 -> 3.8251366 | C23: 3.66
A24: Price / book (30-Jun-2026 equity) | B24: ='Deal Terms'!B22/'Target Standalone'!B32 -> 3.9648111
A25: Unaffected EV / 2026E adjusted EBITDA (what the market paid) | B25: =(B15+'Deal Terms'!B25)/'Target Standalone'!E39 -> 5.0151315
A26: Equity as % of EV — the leverage the buyer takes on | B26: ='Deal Terms'!B22/'Deal Terms'!B26 -> 0.34627472
A28: MORGAN STANLEY'S REFERENCE RANGES vs $14.00 (DEFM14A pp.59–62)
A29: Method | B29: Low ($) | C29: High ($) | D29: Basis | E29: $14 vs high
A30: DCF — the only analysis used for the opinion | B30: 6.8 | C30: 13.9 | D30: WACC 10.2–10.9%, perpetual growth −2% to 0%, mid-year | E30: =$B$5/C30-1 -> 0.0071942446
A31: Trading comparables (Bausch Health, Viatris) — reference only | B31: 7.3 | C31: 19.7 | D31: 5.1–6.9x 2026E adjusted EBITDA | E31: =$B$5/C31-1 -> -0.2893401
A32: Morgan Stanley's two precedents — reference only | B32: 13.4 | C32: 15.3 | D32: 6.2–6.5x LTM EBITDA (Mallinckrodt/Endo 2025; Upjohn/Mylan 2019, a stock combination) | E32: =$B$5/C32-1 -> -0.08496732
A33: Morgan Stanley premia study, all-cash deals $1–15bn since 2020 — reference only | B33: 8.6 | C33: 11.5 | D33: 24%–67% (25th–75th pct) on the $6.91 unaffected close | E33: =$B$5/C33-1 -> 0.2173913
A34: Analyst price targets, discounted 1 year at 12.7% | B34: 4.4 | C34: 10.6 | D34: undiscounted range $5.00–12.00 | E34: =$B$5/C34-1 -> 0.32075472
A35: 52-week trading range to the unaffected date | B35: 5.69 | C35: 13.25 | D35: intraday | E35: =$B$5/C35-1 -> 0.056603774
A37: Premium to unaffected vs the 75th percentile of Morgan Stanley's premia study, in points | B37: =B7-C37 -> 0.3560492 | C37: 0.67
A38: EV/LTM EBITDA vs the midpoint of Morgan Stanley's two precedents | B38: =B19-AVERAGE(C38:D38) -> -0.062554585 | C38: 6.2 | D38: 6.5
A39: Two lenses, two answers: on multiples the price is ordinary (6.3x LTM EBITDA, inside the two precedents); on the share price it is extraordinary (+103%, 36 points above the 75th-percentile premium). The gap is the leverage: equity is a third of EV, so a move of about 1.1 turns of LTM EBITDA (unaffected to offer) doubles the equity.

Sheet Synergies
A1: Synergies — what Sun guided, what it is worth, how much was paid away
A2: Source: Sun investor call 27-Apr-2026 (CFO J. Satagopan: '$350 million … purely on the cost front', 'next two to four years'); Organon 8-K 17-Jul-2026 (seller's preliminary estimate ~$700m). Phasing, cost to achieve and discount rate are desk assumptions (blue).
A4: THE PRICE
A5: Equity value ($m) | B5: ='Deal Terms'!B22 -> 3988.6
A6: Headline EV paid ($m) | B6: ='Deal Terms'!B27 -> 11750
A7: Premium paid over unaffected ($m) | B7: ='Premium & Precedents'!B16 -> 2019.941
A9: SYNERGY ASSUMPTIONS
A10: Run-rate pre-tax cost synergies guided by Sun ($m) | B10: 350
A11: Share of Sun's guide delivered (base) | B11: 1
A12: Tax rate | B12: 0.25
A13: One-off cost to achieve, multiple of the guided run-rate (desk; not disclosed) | B13: 1
A14: Discount rate (desk base = Organon's risk: midpoint of Morgan Stanley's 10.2–10.9%) | B14: 0.105
A15: Perpetual growth of synergies after 2030 | B15: -0.01
A16: Memo: Organon's own preliminary cost-synergy estimate shown to Sun, 22-Jan-2026 ($m) | B16: 700
B17: 2026E | C17: 2027E | D17: 2028E | E17: 2029E | F17: 2030E
A18: Years from 31-Mar-2026 (mid-period) | B18: 0.375 | C18: 1.25 | D18: 2.25 | E18: 3.25 | F18: 4.25
A19: Phase-in of run-rate (closing early 2027) | B19: 0 | C19: 0.25 | D19: 0.6 | E19: 1 | F19: 1
A20: Cost to achieve, share spent | B20: 0 | C20: 0.5 | D20: 0.5 | E20: 0 | F20: 0
A21: After-tax synergies delivered ($m) | B21: =$B$10*$B$11*B19*(1-$B$12) -> 0 | C21: =$B$10*$B$11*C19*(1-$B$12) -> 65.625 | D21: =$B$10*$B$11*D19*(1-$B$12) -> 157.5 | E21: =$B$10*$B$11*E19*(1-$B$12) -> 262.5 | F21: =$B$10*$B$11*F19*(1-$B$12) -> 262.5
A22: After-tax cost to achieve ($m) — fixed, does not shrink with delivery | B22: =-$B$10*$B$13*B20*(1-$B$12) -> 0 | C22: =-$B$10*$B$13*C20*(1-$B$12) -> -131.25 | D22: =-$B$10*$B$13*D20*(1-$B$12) -> -131.25 | E22: =-$B$10*$B$13*E20*(1-$B$12) -> 0 | F22: =-$B$10*$B$13*F20*(1-$B$12) -> 0
A23: Discount factor | B23: =1/(1+$B$14)^B18 -> 0.96325028 | C23: =1/(1+$B$14)^C18 -> 0.88266753 | D23: =1/(1+$B$14)^D18 -> 0.79879415 | E23: =1/(1+$B$14)^E18 -> 0.72289063 | F23: =1/(1+$B$14)^F18 -> 0.65419967
A24: PV of synergies ($m) | B24: =B21*B23 -> 0 | C24: =C21*C23 -> 57.925057 | D24: =D21*D23 -> 125.81008 | E24: =E21*E23 -> 189.75879 | F24: =F21*F23 -> 171.72741
A25: PV of cost to achieve ($m) | B25: =B22*B23 -> 0 | C25: =C22*C23 -> -115.85011 | D25: =D22*D23 -> -104.84173 | E25: =E22*E23 -> 0 | F25: =F22*F23 -> 0
A26: PV of terminal synergies (mid-year convention, 4.25 years) ($m) | B26: =F21*(1+B15)/(B14-B15)/(1+B14)^F18 -> 1478.349
A27: PRESENT VALUE OF SYNERGIES, NET OF COST TO ACHIEVE ($m) | B27: =SUM(B24:F24)+SUM(B25:F25)+B26 -> 1802.8785
A28: PV of gross synergies per 100% of Sun's guide ($m) | B28: =(SUM(B24:F24)+B26)/B11 -> 2023.5704
A29: PV of cost to achieve ($m) | B29: =SUM(B25:F25) -> -220.69185
A30: Premium paid ÷ PV of synergies — share of the synergies handed to Organon holders | B30: =B7/B27 -> 1.1203977
A31: Share of Sun's guide needed to earn back the premium | B31: =(B7-B29)/B28 -> 1.1072671
A32: Share of synergy PV that sits in the terminal value | B32: =B26/(SUM(B24:F24)+B26) -> 0.73056468
A33: Memo: run-rate after tax capitalised at a multiple (cross-check only) | B33: =B10*B11*(1-B12)*C33 -> 1837.5 | C33: 7
A34: Sun guided $350m and did not quantify revenue synergies, so none are valued. The seller's preliminary estimate was about $700m (Organon 8-K, 17-Jul-2026) — the upside case in Sensitivities grid 2 (200% row).

Sheet Accretion-Dilution
A1: EPS accretion for Sun — on management's projections
A2: Year 1 = Sun FY2028 (April 2027 – March 2028), which is almost exactly Organon's calendar 2027. Debt held flat (no paydown) — conservative for years 2–3. US$ millions unless stated.
A4: FINANCING
A5: Uses: equity purchase ($m) | B5: ='Deal Terms'!B22 -> 3988.6
A6: Uses: Organon debt refinanced at change of control ($m, carrying value; face ~$8.6bn) | B6: ='Target Standalone'!B28 -> 8553
A7: Uses: fees and expenses (desk, ~1.3% of EV) | B7: 150
A8: TOTAL USES ($m) | B8: =SUM(B5:B7) -> 12691.6
A9: Sources: Sun cash (midpoint of $2.0–2.5bn guided) | B9: 2250
A10: Sources: new acquisition debt (balancing) ($m) | B10: =B8-B9 -> 10441.6
A11: Committed bridge ($m) | B11: 12000
A12: Pre-tax cost of acquisition debt (desk; Sun's new debt pricing not disclosed — Organon's existing debt costs ~5.5% per Sun's CFO) | B12: 0.065
A13: Pre-tax yield lost on Sun cash used (desk, rupee treasury) | B13: 0.075
A14: Tax rate | B14: =Synergies!B12 -> 0.25
A15: Organon depreciation + existing amortisation ($m, FY2025 run-rate) | B15: ='Target Standalone'!D15+'Target Standalone'!D16 -> 361
A16: Extra amortisation from purchase-price allocation (desk, illustrative midpoint of $400–600m) | B16: 500
A17: USD/INR | B17: ='Acquirer Standalone'!B19 -> 95.18
B19: FY2028E | C19: FY2029E | D19: FY2030E
A20: Organon adjusted EBITDA (management: CY2027E–CY2029E) | B20: ='Target Standalone'!F39 -> 2018 | C20: ='Target Standalone'!G39 -> 2099 | D20: ='Target Standalone'!H39 -> 2150
A21: Synergies realised, pre-tax | B21: =Synergies!$B$10*Synergies!$B$11*Synergies!C19 -> 87.5 | C21: =Synergies!$B$10*Synergies!$B$11*Synergies!D19 -> 210 | D21: =Synergies!$B$10*Synergies!$B$11*Synergies!E19 -> 350
A22: less: one-off cost to achieve, pre-tax | B22: =-Synergies!$B$10*Synergies!$B$13*Synergies!C20 -> -175 | C22: =-Synergies!$B$10*Synergies!$B$13*Synergies!D20 -> -175 | D22: =-Synergies!$B$10*Synergies!$B$13*Synergies!E20 -> 0
A23: less: D&A (existing) | B23: =-$B$15 -> -361 | C23: =-$B$15 -> -361 | D23: =-$B$15 -> -361
A24: less: interest on acquisition debt | B24: =-$B$10*$B$12 -> -678.704 | C24: =-$B$10*$B$12 -> -678.704 | D24: =-$B$10*$B$12 -> -678.704
A25: less: income lost on Sun cash | B25: =-$B$9*$B$13 -> -168.75 | C25: =-$B$9*$B$13 -> -168.75 | D25: =-$B$9*$B$13 -> -168.75
A26: less: PPA amortisation (illustrative) | B26: =-$B$16 -> -500 | C26: =-$B$16 -> -500 | D26: =-$B$16 -> -500
A27: Pre-tax contribution, reported basis ($m) | B27: =SUM(B20:B26) -> 222.046 | C27: =SUM(C20:C26) -> 425.546 | D27: =SUM(D20:D26) -> 791.546
A28: After-tax contribution ($m) | B28: =B27*(1-$B$14) -> 166.5345 | C28: =C27*(1-$B$14) -> 319.1595 | D28: =D27*(1-$B$14) -> 593.6595
A29: per Sun share (Rs) | B29: =B28*$B$17/10/'Acquirer Standalone'!$B$6 -> 6.6064076 | C29: =C28*$B$17/10/'Acquirer Standalone'!$B$6 -> 12.661027 | D29: =D28*$B$17/10/'Acquirer Standalone'!$B$6 -> 23.550415
A30: Sun standalone EPS (Rs, desk) | B30: ='Acquirer Standalone'!B15 -> 57.07 | C30: ='Acquirer Standalone'!B16 -> 61.53 | D30: ='Acquirer Standalone'!B17 -> 66.04
A31: Pro forma EPS, reported basis (Rs) | B31: =B30+B29 -> 63.676408 | C31: =C30+C29 -> 74.191027 | D31: =D30+D29 -> 89.590415
A32: EPS ACCRETION, REPORTED BASIS (after integration cost and PPA) | B32: =B31/B30-1 -> 0.11575973 | C32: =C31/C30-1 -> 0.20576998 | D32: =D31/D30-1 -> 0.35660835
A33: EPS accretion before PPA and integration cost (cash EPS) | B33: =(B30+(B27-B22-B26)*(1-$B$14)*$B$17/10/'Acquirer Standalone'!$B$6)/B30-1 -> 0.46765895 | C33: =(C30+(C27-C22-C26)*(1-$B$14)*$B$17/10/'Acquirer Standalone'!$B$6)/C30-1 -> 0.5321618 | D33: =(D30+(D27-D22-D26)*(1-$B$14)*$B$17/10/'Acquirer Standalone'!$B$6)/D30-1 -> 0.58186901
A34: EPS accretion with zero synergies and no integration cost (PPA kept) | B34: =(B30+(B27-B21-B22)*(1-$B$14)*$B$17/10/'Acquirer Standalone'!$B$6)/B30-1 -> 0.16137629 | C34: =(C30+(C27-C21-C22)*(1-$B$14)*$B$17/10/'Acquirer Standalone'!$B$6)/C30-1 -> 0.18884596 | D34: =(D30+(D27-D21-D22)*(1-$B$14)*$B$17/10/'Acquirer Standalone'!$B$6)/D30-1 -> 0.19892589
A36: BRIDGE TO THE 7-SEP SUN PHARMA NOTE (FY2028E, cash EPS)
A37: This model, cash EPS (management case, 100% synergies, today's FX) | B37: =B33 -> 0.46765895
A38: with 50% of the synergies (the Sun note's assumption) | B38: =(B30+(B27-B22-B26-B21*(1-C38))*(1-B14)*B17/10/'Acquirer Standalone'!B6)/B30-1 -> 0.44485067 | C38: 0.5
A39: … and at the Sun note's FX | B39: =(B30+(B27-B22-B26-B21*(1-C38))*(1-B14)*C39/10/'Acquirer Standalone'!B6)/B30-1 -> 0.4136298 | C39: 88.5
A40: Sun note (7-Sep-2026): accretion carried | B40: 0.289
A41: Residual: other differences in the Sun note's build (not reconciled line by line) | B41: =B40-B39 -> -0.1246298
A43: RETURN ON THE MONEY — ROIC vs COST OF CAPITAL
A44: Total price paid (headline EV + fees) ($m) | B44: =Synergies!B6+B7 -> 11900
...

Sheet Pro Forma
A1: Sources & uses, pro forma leverage
A2: US$ millions; rupee figures converted at the 28-Oct-2026 rate.
A4: Sources | B4: $m | D4: Uses | E4: $m
A5: Sun cash | B5: ='Accretion-Dilution'!B9 -> 2250 | D5: Organon equity at $14.00 | E5: ='Accretion-Dilution'!B5 -> 3988.6
A6: New acquisition debt | B6: ='Accretion-Dilution'!B10 -> 10441.6 | D6: Organon debt refinanced | E6: ='Accretion-Dilution'!B6 -> 8553
D7: Fees and expenses | E7: ='Accretion-Dilution'!B7 -> 150
A8: TOTAL | B8: =B5+B6 -> 12691.6 | D8: TOTAL | E8: =SUM(E5:E7) -> 12691.6
A9: Acquisition debt headroom under the $12bn bridge ($m) | B9: ='Accretion-Dilution'!B11-B6 -> 1558.4
A11: PRO FORMA LEVERAGE AT CLOSE
A12: Acquisition debt ($m) | B12: =B6 -> 10441.6
A13: Sun existing borrowings ($m) | B13: ='Acquirer Standalone'!B13*10/'Acquirer Standalone'!B19 -> 486.13154
A14: less: Sun treasury left after funding ($m) | B14: =-('Acquirer Standalone'!B12*10/'Acquirer Standalone'!B19-B5) -> -347.49947
A15: less: Organon cash, 30-Jun-2026 ($m) | B15: =-'Target Standalone'!B27 -> -1132
A16: PRO FORMA NET DEBT ($m) | B16: =SUM(B12:B15) -> 9448.2321
A17: Sun standalone EBITDA FY2027E ($m) | B17: ='Acquirer Standalone'!B14*10/'Acquirer Standalone'!B19 -> 1934.8603
A18: Organon adjusted EBITDA 2026E ($m) | B18: ='Target Standalone'!E39 -> 1894
A19: NET DEBT / COMBINED EBITDA | B19: =B16/(B17+B18) -> 2.4676356
A20: Sun's stated figure (investor call) | B20: 2.3
A21: Organon share of combined EBITDA | B21: =B18/(B17+B18) -> 0.49466417
A22: A company with roughly Rs 20,000 crore of net cash moves to about 2.5x net debt to EBITDA, nearly half of the EBITDA coming from a business whose revenue management expects to fall after 2029.

Sheet Spread & Odds
A1: Live deal — merger-arbitrage spread and the odds the market is pricing
A2: Prices: NYSE close 28-Oct-2026. Expected close and break price are desk assumptions (blue). Refresh on the day of posting.
A4: Offer per share ($) | B4: ='Deal Terms'!B20 -> 14
A5: OGN close, 28-Oct-2026 ($) | B5: 13.78
A6: Dividends expected before close ($, $0.02 quarterly) | B6: 0.02
A7: Gross spread ($) | B7: =B4+B6-B5 -> 0.24
A8: Gross spread (%) | B8: =B7/B5 -> 0.017416546
A9: Valuation date | B9: 46323
A10: Expected close (desk: the first outside date, 26-Jan-2027) | B10: 46413
A11: Days to close | B11: =B10-B9 -> 90
A12: ANNUALISED SPREAD | B12: =(1+B8)^(365/B11)-1 -> 0.072535767
A13: US 3-month T-bill, 28-Oct-2026 | B13: 0.03995
A14: Excess over T-bills (points) | B14: =B12-B13 -> 0.032585767
A15: Unaffected close ($) | B15: ='Premium & Precedents'!B6 -> 6.91
A16: S&P 500 change, 9-Apr to 28-Oct-2026 | B16: =C16/D16-1 -> 0.13470561 | C16: 7743.98 | D16: 6824.66 | E16: <- S&P 500 on 28-Oct and 9-Apr-2026
A17: Break price if the deal fails, desk assumption: unaffected moved with the S&P 500 ($) | B17: =B15*(1+B16) -> 7.8408158
A18: IMPLIED PROBABILITY OF CLOSING (risk-neutral, T-bill discounting) | B18: =(B5*(1+B13*B11/365)-B17)/(B4+B6-B17) -> 0.98312762
A19: Downside if it breaks (%) | B19: =B17/B5-1 -> -0.43100031
A20: Upside if it closes (%) | B20: =B8 -> 0.017416546
A21: Downside ÷ upside | B21: =-B19/B20 -> 24.746601
A23: ANNUALISED SPREAD BY CLOSING DATE
A24: Closing date | B24: Days | C24: Annualised | D24: vs T-bill
A25: 26-Jan-2027 — first outside date | B25: =E25-$B$9 -> 90 | C25: =(1+$B$8)^(365/B25)-1 -> 0.072535767 | D25: =C25-$B$13 -> 0.032585767 | E25: 46413
A26: 31-Mar-2027 — 'early 2027' | B26: =E26-$B$9 -> 154 | C26: =(1+$B$8)^(365/B26)-1 -> 0.041773055 | D26: =C26-$B$13 -> 0.0018230553 | E26: 46477
A27: 26-Apr-2027 — extended outside date | B27: =E27-$B$9 -> 180 | C27: =(1+$B$8)^(365/B27)-1 -> 0.035633027 | D27: =C27-$B$13 -> -0.0043169728 | E27: 46503
A29: On our break-price assumption the market prices about a 98% chance of completion. The spread only beats T-bills comfortably if the deal closes by the January outside date; at an April close it earns about what cash does. About 2% to gain against roughly 43% to lose if regulators or financing fail.

Sheet Valuation & Verdict
A1: What it is worth, the market's verdict, and ours
A2: Standalone DCF on management's projections, rebuilt to reproduce Morgan Stanley's range; desk discount rate and terminal build in blue.
A4: STANDALONE DCF — ORGANON ON MANAGEMENT'S PROJECTIONS
A5: Discount rate for Organon (desk base = midpoint of Morgan Stanley's 10.2–10.9%) | B5: =Synergies!B14 -> 0.105
A6: Perpetual growth after 2030 (Morgan Stanley range −2% to 0%) | B6: =Synergies!B15 -> -0.01
A7: 2030E adjusted EBITDA (management) | B7: ='Target Standalone'!I39 -> 1986
A8: less: stock-based compensation (FY2025) | B8: 77
A9: Depreciation (FY2025) | B9: ='Target Standalone'!D15 -> 156
A10: less: tax at 25% on EBITDA less depreciation | B10: =(B7-B9)*Synergies!B12 -> 457.5
A11: less: capital expenditure (FY2025) | B11: ='Target Standalone'!D18 -> 162
A12: less: working-capital investment (flat revenue) | B12: 0
A13: TERMINAL FREE CASH FLOW, clean (no one-off costs) ($m) | B13: =B7-B8-B10-B11-B12 -> 1289.5
A14: Memo: 2027E–2029E average UFCF, which still carries the one-offs ($m) | B14: =AVERAGE('Target Standalone'!F40:H40) -> 929.66667
B15: Rest of 2026E | C15: 2027E | D15: 2028E | E15: 2029E | F15: 2030E
A16: Unlevered FCF ($m) | B16: =SUM('Target Standalone'!B40:D40) -> 505 | C16: ='Target Standalone'!F40 -> 714 | D16: ='Target Standalone'!G40 -> 958 | E16: ='Target Standalone'!H40 -> 1117 | F16: ='Target Standalone'!I40 -> 774
A17: Years from 31-Mar-2026 (mid-period) | B17: =Synergies!B18 -> 0.375 | C17: =Synergies!C18 -> 1.25 | D17: =Synergies!D18 -> 2.25 | E17: =Synergies!E18 -> 3.25 | F17: =Synergies!F18 -> 4.25
A18: PV ($m) | B18: =B16/(1+$B$5)^B17 -> 486.44139 | C18: =C16/(1+$B$5)^C17 -> 630.22462 | D18: =D16/(1+$B$5)^D17 -> 765.24479 | E18: =E16/(1+$B$5)^E17 -> 807.46884 | F18: =F16/(1+$B$5)^F17 -> 506.35054
A19: PV of terminal value (mid-year convention, 4.25 years) ($m) | B19: =B13*(1+B6)/(B5-B6)/(1+B5)^F17 -> 7262.2136
A20: STANDALONE ENTERPRISE VALUE ($m) | B20: =SUM(B18:F18)+B19 -> 10457.944
A21: Standalone value per share ($) | B21: =(B20-'Deal Terms'!B25)/'Deal Terms'!B21 -> 10.277093
A23: RECONCILIATION — THIS DCF AT MORGAN STANLEY'S INPUTS
A24: Discount rate / growth | B24: Rate | C24: Growth | D24: Value per share ($)
A25: Corner 1 | B25: 0.102 | C25: -0.02 | D25: =((SUMPRODUCT($B$16:$F$16,1/(1+B25)^$B$17:$F$17)+$B$13*(1+C25)/(B25-C25)/(1+B25)^$F$17)-'Deal Terms'!$B$25)/'Deal Terms'!$B$21 -> 8.9197938
A26: Corner 2 | B26: 0.102 | C26: 0 | D26: =((SUMPRODUCT($B$16:$F$16,1/(1+B26)^$B$17:$F$17)+$B$13*(1+C26)/(B26-C26)/(1+B26)^$F$17)-'Deal Terms'!$B$25)/'Deal Terms'!$B$21 -> 14.225079
A27: Corner 3 | B27: 0.109 | C27: -0.02 | D27: =((SUMPRODUCT($B$16:$F$16,1/(1+B27)^$B$17:$F$17)+$B$13*(1+C27)/(B27-C27)/(1+B27)^$F$17)-'Deal Terms'!$B$25)/'Deal Terms'!$B$21 -> 6.8441496
A28: Corner 4 | B28: 0.109 | C28: 0 | D28: =((SUMPRODUCT($B$16:$F$16,1/(1+B28)^$B$17:$F$17)+$B$13*(1+C28)/(B28-C28)/(1+B28)^$F$17)-'Deal Terms'!$B$25)/'Deal Terms'!$B$21 -> 11.443698
A29: This DCF's range at Morgan Stanley's inputs: low / high ($) | B29: =MIN(D25:D28) -> 6.8441496 | C29: =MAX(D25:D28) -> 14.225079
A30: Morgan Stanley's reported DCF range: low / high ($) | B30: ='Premium & Precedents'!B30 -> 6.8 | C30: ='Premium & Precedents'!C30 -> 13.9
A31: Gap at each end | B31: =B29/B30-1 -> 0.006492584 | C31: =C29/C30-1 -> 0.023386953
A33: VALUE TO SUN
A34: Standalone enterprise value ($m) | B34: =B20 -> 10457.944
A35: + PV of synergies, net of cost to achieve ($m) | B35: =Synergies!B27 -> 1802.8785
A36: VALUE TO SUN, INCLUDING SYNERGIES ($m) | B36: =B34+B35 -> 12260.822
A37: per Organon share ($) | B37: =(B36-'Deal Terms'!B25)/'Deal Terms'!B21 -> 16.605203
A38: Price paid: headline EV + fees ($m) | B38: ='Accretion-Dilution'!B44 -> 11900
A39: NPV TO SUN SHAREHOLDERS ($m) | B39: =B36-B38 -> 360.82232
A40: Share of the synergy value kept by Sun | B40: =B39/B35 -> 0.20013679
A41: NPV with zero synergies ($m) | B41: =B34-B38 -> -1442.0562
A42: Share of Sun's $350m guide needed to break even | B42: =(B38-B34-Synergies!B29)/Synergies!B28 -> 0.82169026
A44: THE MARKET'S VERDICT
...

Sheet Sensitivities
A1: Sensitivities
A2: Each grid recomputes from the inputs on Synergies, Valuation & Verdict and Accretion-Dilution. Axis values are inputs (blue).
A4: 1) NPV TO SUN ($m) — Sun's guide delivered (rows) × price paid as EV / 2026E EBITDA (columns), at the base discount rate
A5: Delivery ↓ / EV/EBITDA → | B5: 5.5 | C5: 6 | D5: ='Deal Terms'!B26/'Target Standalone'!E39 -> 6.0816262 | E5: 6.5 | F5: 7 | G5: 7.5
A6: 0.5 | B6: ='Valuation & Verdict'!$B$34+Synergies!$B$28*$A6+Synergies!$B$29-(B$5*'Target Standalone'!$E$39+'Deal Terms'!$B$28+'Accretion-Dilution'!$B$7) -> 450.63713 | C6: ='Valuation & Verdict'!$B$34+Synergies!$B$28*$A6+Synergies!$B$29-(C$5*'Target Standalone'!$E$39+'Deal Terms'!$B$28+'Accretion-Dilution'!$B$7) -> -496.36287 | D6: ='Valuation & Verdict'!$B$34+Synergies!$B$28*$A6+Synergies!$B$29-(D$5*'Target Standalone'!$E$39+'Deal Terms'!$B$28+'Accretion-Dilution'!$B$7) -> -650.96287 | E6: ='Valuation & Verdict'!$B$34+Synergies!$B$28*$A6+Synergies!$B$29-(E$5*'Target Standalone'!$E$39+'Deal Terms'!$B$28+'Accretion-Dilution'!$B$7) -> -1443.3629 | F6: ='Valuation & Verdict'!$B$34+Synergies!$B$28*$A6+Synergies!$B$29-(F$5*'Target Standalone'!$E$39+'Deal Terms'!$B$28+'Accretion-Dilution'!$B$7) -> -2390.3629 | G6: ='Valuation & Verdict'!$B$34+Synergies!$B$28*$A6+Synergies!$B$29-(G$5*'Target Standalone'!$E$39+'Deal Terms'!$B$28+'Accretion-Dilution'!$B$7) -> -3337.3629
A7: 0.75 | B7: ='Valuation & Verdict'!$B$34+Synergies!$B$28*$A7+Synergies!$B$29-(B$5*'Target Standalone'!$E$39+'Deal Terms'!$B$28+'Accretion-Dilution'!$B$7) -> 956.52972 | C7: ='Valuation & Verdict'!$B$34+Synergies!$B$28*$A7+Synergies!$B$29-(C$5*'Target Standalone'!$E$39+'Deal Terms'!$B$28+'Accretion-Dilution'!$B$7) -> 9.5297242 | D7: ='Valuation & Verdict'!$B$34+Synergies!$B$28*$A7+Synergies!$B$29-(D$5*'Target Standalone'!$E$39+'Deal Terms'!$B$28+'Accretion-Dilution'!$B$7) -> -145.07028 | E7: ='Valuation & Verdict'!$B$34+Synergies!$B$28*$A7+Synergies!$B$29-(E$5*'Target Standalone'!$E$39+'Deal Terms'!$B$28+'Accretion-Dilution'!$B$7) -> -937.47028 | F7: ='Valuation & Verdict'!$B$34+Synergies!$B$28*$A7+Synergies!$B$29-(F$5*'Target Standalone'!$E$39+'Deal Terms'!$B$28+'Accretion-Dilution'!$B$7) -> -1884.4703 | G7: ='Valuation & Verdict'!$B$34+Synergies!$B$28*$A7+Synergies!$B$29-(G$5*'Target Standalone'!$E$39+'Deal Terms'!$B$28+'Accretion-Dilution'!$B$7) -> -2831.4703
A8: 1 | B8: ='Valuation & Verdict'!$B$34+Synergies!$B$28*$A8+Synergies!$B$29-(B$5*'Target Standalone'!$E$39+'Deal Terms'!$B$28+'Accretion-Dilution'!$B$7) -> 1462.4223 | C8: ='Valuation & Verdict'!$B$34+Synergies!$B$28*$A8+Synergies!$B$29-(C$5*'Target Standalone'!$E$39+'Deal Terms'!$B$28+'Accretion-Dilution'!$B$7) -> 515.42232 | D8: ='Valuation & Verdict'!$B$34+Synergies!$B$28*$A8+Synergies!$B$29-(D$5*'Target Standalone'!$E$39+'Deal Terms'!$B$28+'Accretion-Dilution'!$B$7) -> 360.82232 | E8: ='Valuation & Verdict'!$B$34+Synergies!$B$28*$A8+Synergies!$B$29-(E$5*'Target Standalone'!$E$39+'Deal Terms'!$B$28+'Accretion-Dilution'!$B$7) -> -431.57768 | F8: ='Valuation & Verdict'!$B$34+Synergies!$B$28*$A8+Synergies!$B$29-(F$5*'Target Standalone'!$E$39+'Deal Terms'!$B$28+'Accretion-Dilution'!$B$7) -> -1378.5777 | G8: ='Valuation & Verdict'!$B$34+Synergies!$B$28*$A8+Synergies!$B$29-(G$5*'Target Standalone'!$E$39+'Deal Terms'!$B$28+'Accretion-Dilution'!$B$7) -> -2325.5777
A9: 1.25 | B9: ='Valuation & Verdict'!$B$34+Synergies!$B$28*$A9+Synergies!$B$29-(B$5*'Target Standalone'!$E$39+'Deal Terms'!$B$28+'Accretion-Dilution'!$B$7) -> 1968.3149 | C9: ='Valuation & Verdict'!$B$34+Synergies!$B$28*$A9+Synergies!$B$29-(C$5*'Target Standalone'!$E$39+'Deal Terms'!$B$28+'Accretion-Dilution'!$B$7) -> 1021.3149 | D9: ='Valuation & Verdict'!$B$34+Synergies!$B$28*$A9+Synergies!$B$29-(D$5*'Target Standalone'!$E$39+'Deal Terms'!$B$28+'Accretion-Dilution'!$B$7) -> 866.71491 | E9: ='Valuation & Verdict'!$B$34+Synergies!$B$28*$A9+Synergies!$B$29-(E$5*'Target Standalone'!$E$39+'Deal Terms'!$B$28+'Accretion-Dilution'!$B$7) -> 74.314908 | F9: ='Valuation & Verdict'!$B$34+Synergies!$B$28*$A9+Synergies!$B$29-(F$5*'Target Standalone'!$E$39+'Deal Terms'!$B$28+'Accretion-Dilution'!$B$7) -> -872.68509 | G9: ='Valuation & Verdict'!$B$34+Synergies!$B$28*$A9+Synergies!$B$29-(G$5*'Target Standalone'!$E$39+'Deal Terms'!$B$28+'Accretion-Dilution'!$B$7) -> -1819.6851
A10: 2 | B10: ='Valuation & Verdict'!$B$34+Synergies!$B$28*$A10+Synergies!$B$29-(B$5*'Target Standalone'!$E$39+'Deal Terms'!$B$28+'Accretion-Dilution'!$B$7) -> 3485.9927 | C10: ='Valuation & Verdict'!$B$34+Synergies!$B$28*$A10+Synergies!$B$29-(C$5*'Target Standalone'!$E$39+'Deal Terms'!$B$28+'Accretion-Dilution'!$B$7) -> 2538.9927 | D10: ='Valuation & Verdict'!$B$34+Synergies!$B$28*$A10+Synergies!$B$29-(D$5*'Target Standalone'!$E$39+'Deal Terms'!$B$28+'Accretion-Dilution'!$B$7) -> 2384.3927 | E10: ='Valuation & Verdict'!$B$34+Synergies!$B$28*$A10+Synergies!$B$29-(E$5*'Target Standalone'!$E$39+'Deal Terms'!$B$28+'Accretion-Dilution'!$B$7) -> 1591.9927 | F10: ='Valuation & Verdict'!$B$34+Synergies!$B$28*$A10+Synergies!$B$29-(F$5*'Target Standalone'!$E$39+'Deal Terms'!$B$28+'Accretion-Dilution'!$B$7) -> 644.99268 | G10: ='Valuation & Verdict'!$B$34+Synergies!$B$28*$A10+Synergies!$B$29-(G$5*'Target Standalone'!$E$39+'Deal Terms'!$B$28+'Accretion-Dilution'!$B$7) -> -302.00732
A11: Check: base delivery at the actual multiple vs Valuation & Verdict (must be 0) | B11: =ROUND(INDEX(D6:D10,MATCH(Synergies!B11,A6:A10,0))-'Valuation & Verdict'!B39,0) -> 0
A12: The third column is the price actually paid; price = multiple × 2026E EBITDA + other debt-like items + fees. The 200% row is Organon's own ~$700m preliminary estimate.
A14: 2) NPV TO SUN ($m) — discount rate for Organon and its synergies (rows) × Sun's guide delivered (columns)
A15: Discount rate ↓ / delivery → | B15: 0 | C15: 0.5 | D15: 1 | E15: 1.25 | F15: 2
A16: 0.08 | B16: =(SUMPRODUCT('Valuation & Verdict'!$B$16:$F$16,1/(1+$A16)^'Valuation & Verdict'!$B$17:$F$17)+'Valuation & Verdict'!$B$13*(1+'Valuation & Verdict'!$B$6)/($A16-'Valuation & Verdict'!$B$6)/(1+$A16)^'Valuation & Verdict'!$F$17)+(SUMPRODUCT(Synergies!$B$21:$F$21/Synergies!$B$11*B$15+Synergies!$B$22:$F$22,1/(1+$A16)^Synergies!$B$18:$F$18)+Synergies!$F$21/Synergies!$B$11*B$15*(1+Synergies!$B$15)/($A16-Synergies!$B$15)/(1+$A16)^Synergies!$F$18)-'Valuation & Verdict'!$B$38 -> 1470.466 | C16: =(SUMPRODUCT('Valuation & Verdict'!$B$16:$F$16,1/(1+$A16)^'Valuation & Verdict'!$B$17:$F$17)+'Valuation & Verdict'!$B$13*(1+'Valuation & Verdict'!$B$6)/($A16-'Valuation & Verdict'!$B$6)/(1+$A16)^'Valuation & Verdict'!$F$17)+(SUMPRODUCT(Synergies!$B$21:$F$21/Synergies!$B$11*C$15+Synergies!$B$22:$F$22,1/(1+$A16)^Synergies!$B$18:$F$18)+Synergies!$F$21/Synergies!$B$11*C$15*(1+Synergies!$B$15)/($A16-Synergies!$B$15)/(1+$A16)^Synergies!$F$18)-'Valuation & Verdict'!$B$38 -> 2804.3138 | D16: =(SUMPRODUCT('Valuation & Verdict'!$B$16:$F$16,1/(1+$A16)^'Valuation & Verdict'!$B$17:$F$17)+'Valuation & Verdict'!$B$13*(1+'Valuation & Verdict'!$B$6)/($A16-'Valuation & Verdict'!$B$6)/(1+$A16)^'Valuation & Verdict'!$F$17)+(SUMPRODUCT(Synergies!$B$21:$F$21/Synergies!$B$11*D$15+Synergies!$B$22:$F$22,1/(1+$A16)^Synergies!$B$18:$F$18)+Synergies!$F$21/Synergies!$B$11*D$15*(1+Synergies!$B$15)/($A16-Synergies!$B$15)/(1+$A16)^Synergies!$F$18)-'Valuation & Verdict'!$B$38 -> 4138.1616 | E16: =(SUMPRODUCT('Valuation & Verdict'!$B$16:$F$16,1/(1+$A16)^'Valuation & Verdict'!$B$17:$F$17)+'Valuation & Verdict'!$B$13*(1+'Valuation & Verdict'!$B$6)/($A16-'Valuation & Verdict'!$B$6)/(1+$A16)^'Valuation & Verdict'!$F$17)+(SUMPRODUCT(Synergies!$B$21:$F$21/Synergies!$B$11*E$15+Synergies!$B$22:$F$22,1/(1+$A16)^Synergies!$B$18:$F$18)+Synergies!$F$21/Synergies!$B$11*E$15*(1+Synergies!$B$15)/($A16-Synergies!$B$15)/(1+$A16)^Synergies!$F$18)-'Valuation & Verdict'!$B$38 -> 4805.0856 | F16: =(SUMPRODUCT('Valuation & Verdict'!$B$16:$F$16,1/(1+$A16)^'Valuation & Verdict'!$B$17:$F$17)+'Valuation & Verdict'!$B$13*(1+'Valuation & Verdict'!$B$6)/($A16-'Valuation & Verdict'!$B$6)/(1+$A16)^'Valuation & Verdict'!$F$17)+(SUMPRODUCT(Synergies!$B$21:$F$21/Synergies!$B$11*F$15+Synergies!$B$22:$F$22,1/(1+$A16)^Synergies!$B$18:$F$18)+Synergies!$F$21/Synergies!$B$11*F$15*(1+Synergies!$B$15)/($A16-Synergies!$B$15)/(1+$A16)^Synergies!$F$18)-'Valuation & Verdict'!$B$38 -> 6805.8573
A17: 0.09 | B17: =(SUMPRODUCT('Valuation & Verdict'!$B$16:$F$16,1/(1+$A17)^'Valuation & Verdict'!$B$17:$F$17)+'Valuation & Verdict'!$B$13*(1+'Valuation & Verdict'!$B$6)/($A17-'Valuation & Verdict'!$B$6)/(1+$A17)^'Valuation & Verdict'!$F$17)+(SUMPRODUCT(Synergies!$B$21:$F$21/Synergies!$B$11*B$15+Synergies!$B$22:$F$22,1/(1+$A17)^Synergies!$B$18:$F$18)+Synergies!$F$21/Synergies!$B$11*B$15*(1+Synergies!$B$15)/($A17-Synergies!$B$15)/(1+$A17)^Synergies!$F$18)-'Valuation & Verdict'!$B$38 -> 25.017724 | C17: =(SUMPRODUCT('Valuation & Verdict'!$B$16:$F$16,1/(1+$A17)^'Valuation & Verdict'!$B$17:$F$17)+'Valuation & Verdict'!$B$13*(1+'Valuation & Verdict'!$B$6)/($A17-'Valuation & Verdict'!$B$6)/(1+$A17)^'Valuation & Verdict'!$F$17)+(SUMPRODUCT(Synergies!$B$21:$F$21/Synergies!$B$11*C$15+Synergies!$B$22:$F$22,1/(1+$A17)^Synergies!$B$18:$F$18)+Synergies!$F$21/Synergies!$B$11*C$15*(1+Synergies!$B$15)/($A17-Synergies!$B$15)/(1+$A17)^Synergies!$F$18)-'Valuation & Verdict'!$B$38 -> 1210.4271 | D17: =(SUMPRODUCT('Valuation & Verdict'!$B$16:$F$16,1/(1+$A17)^'Valuation & Verdict'!$B$17:$F$17)+'Valuation & Verdict'!$B$13*(1+'Valuation & Verdict'!$B$6)/($A17-'Valuation & Verdict'!$B$6)/(1+$A17)^'Valuation & Verdict'!$F$17)+(SUMPRODUCT(Synergies!$B$21:$F$21/Synergies!$B$11*D$15+Synergies!$B$22:$F$22,1/(1+$A17)^Synergies!$B$18:$F$18)+Synergies!$F$21/Synergies!$B$11*D$15*(1+Synergies!$B$15)/($A17-Synergies!$B$15)/(1+$A17)^Synergies!$F$18)-'Valuation & Verdict'!$B$38 -> 2395.8364 | E17: =(SUMPRODUCT('Valuation & Verdict'!$B$16:$F$16,1/(1+$A17)^'Valuation & Verdict'!$B$17:$F$17)+'Valuation & Verdict'!$B$13*(1+'Valuation & Verdict'!$B$6)/($A17-'Valuation & Verdict'!$B$6)/(1+$A17)^'Valuation & Verdict'!$F$17)+(SUMPRODUCT(Synergies!$B$21:$F$21/Synergies!$B$11*E$15+Synergies!$B$22:$F$22,1/(1+$A17)^Synergies!$B$18:$F$18)+Synergies!$F$21/Synergies!$B$11*E$15*(1+Synergies!$B$15)/($A17-Synergies!$B$15)/(1+$A17)^Synergies!$F$18)-'Valuation & Verdict'!$B$38 -> 2988.5411 | F17: =(SUMPRODUCT('Valuation & Verdict'!$B$16:$F$16,1/(1+$A17)^'Valuation & Verdict'!$B$17:$F$17)+'Valuation & Verdict'!$B$13*(1+'Valuation & Verdict'!$B$6)/($A17-'Valuation & Verdict'!$B$6)/(1+$A17)^'Valuation & Verdict'!$F$17)+(SUMPRODUCT(Synergies!$B$21:$F$21/Synergies!$B$11*F$15+Synergies!$B$22:$F$22,1/(1+$A17)^Synergies!$B$18:$F$18)+Synergies!$F$21/Synergies!$B$11*F$15*(1+Synergies!$B$15)/($A17-Synergies!$B$15)/(1+$A17)^Synergies!$F$18)-'Valuation & Verdict'!$B$38 -> 4766.6551
A18: 0.1 | B18: =(SUMPRODUCT('Valuation & Verdict'!$B$16:$F$16,1/(1+$A18)^'Valuation & Verdict'!$B$17:$F$17)+'Valuation & Verdict'!$B$13*(1+'Valuation & Verdict'!$B$6)/($A18-'Valuation & Verdict'!$B$6)/(1+$A18)^'Valuation & Verdict'!$F$17)+(SUMPRODUCT(Synergies!$B$21:$F$21/Synergies!$B$11*B$15+Synergies!$B$22:$F$22,1/(1+$A18)^Synergies!$B$18:$F$18)+Synergies!$F$21/Synergies!$B$11*B$15*(1+Synergies!$B$15)/($A18-Synergies!$B$15)/(1+$A18)^Synergies!$F$18)-'Valuation & Verdict'!$B$38 -> -1152.5212 | C18: =(SUMPRODUCT('Valuation & Verdict'!$B$16:$F$16,1/(1+$A18)^'Valuation & Verdict'!$B$17:$F$17)+'Valuation & Verdict'!$B$13*(1+'Valuation & Verdict'!$B$6)/($A18-'Valuation & Verdict'!$B$6)/(1+$A18)^'Valuation & Verdict'!$F$17)+(SUMPRODUCT(Synergies!$B$21:$F$21/Synergies!$B$11*C$15+Synergies!$B$22:$F$22,1/(1+$A18)^Synergies!$B$18:$F$18)+Synergies!$F$21/Synergies!$B$11*C$15*(1+Synergies!$B$15)/($A18-Synergies!$B$15)/(1+$A18)^Synergies!$F$18)-'Valuation & Verdict'!$B$38 -> -88.208319 | D18: =(SUMPRODUCT('Valuation & Verdict'!$B$16:$F$16,1/(1+$A18)^'Valuation & Verdict'!$B$17:$F$17)+'Valuation & Verdict'!$B$13*(1+'Valuation & Verdict'!$B$6)/($A18-'Valuation & Verdict'!$B$6)/(1+$A18)^'Valuation & Verdict'!$F$17)+(SUMPRODUCT(Synergies!$B$21:$F$21/Synergies!$B$11*D$15+Synergies!$B$22:$F$22,1/(1+$A18)^Synergies!$B$18:$F$18)+Synergies!$F$21/Synergies!$B$11*D$15*(1+Synergies!$B$15)/($A18-Synergies!$B$15)/(1+$A18)^Synergies!$F$18)-'Valuation & Verdict'!$B$38 -> 976.10459 | E18: =(SUMPRODUCT('Valuation & Verdict'!$B$16:$F$16,1/(1+$A18)^'Valuation & Verdict'!$B$17:$F$17)+'Valuation & Verdict'!$B$13*(1+'Valuation & Verdict'!$B$6)/($A18-'Valuation & Verdict'!$B$6)/(1+$A18)^'Valuation & Verdict'!$F$17)+(SUMPRODUCT(Synergies!$B$21:$F$21/Synergies!$B$11*E$15+Synergies!$B$22:$F$22,1/(1+$A18)^Synergies!$B$18:$F$18)+Synergies!$F$21/Synergies!$B$11*E$15*(1+Synergies!$B$15)/($A18-Synergies!$B$15)/(1+$A18)^Synergies!$F$18)-'Valuation & Verdict'!$B$38 -> 1508.261 | F18: =(SUMPRODUCT('Valuation & Verdict'!$B$16:$F$16,1/(1+$A18)^'Valuation & Verdict'!$B$17:$F$17)+'Valuation & Verdict'!$B$13*(1+'Valuation & Verdict'!$B$6)/($A18-'Valuation & Verdict'!$B$6)/(1+$A18)^'Valuation & Verdict'!$F$17)+(SUMPRODUCT(Synergies!$B$21:$F$21/Synergies!$B$11*F$15+Synergies!$B$22:$F$22,1/(1+$A18)^Synergies!$B$18:$F$18)+Synergies!$F$21/Synergies!$B$11*F$15*(1+Synergies!$B$15)/($A18-Synergies!$B$15)/(1+$A18)^Synergies!$F$18)-'Valuation & Verdict'!$B$38 -> 3104.7304
A19: 0.105 | B19: =(SUMPRODUCT('Valuation & Verdict'!$B$16:$F$16,1/(1+$A19)^'Valuation & Verdict'!$B$17:$F$17)+'Valuation & Verdict'!$B$13*(1+'Valuation & Verdict'!$B$6)/($A19-'Valuation & Verdict'!$B$6)/(1+$A19)^'Valuation & Verdict'!$F$17)+(SUMPRODUCT(Synergies!$B$21:$F$21/Synergies!$B$11*B$15+Synergies!$B$22:$F$22,1/(1+$A19)^Synergies!$B$18:$F$18)+Synergies!$F$21/Synergies!$B$11*B$15*(1+Synergies!$B$15)/($A19-Synergies!$B$15)/(1+$A19)^Synergies!$F$18)-'Valuation & Verdict'!$B$38 -> -1662.7481 | C19: =(SUMPRODUCT('Valuation & Verdict'!$B$16:$F$16,1/(1+$A19)^'Valuation & Verdict'!$B$17:$F$17)+'Valuation & Verdict'!$B$13*(1+'Valuation & Verdict'!$B$6)/($A19-'Valuation & Verdict'!$B$6)/(1+$A19)^'Valuation & Verdict'!$F$17)+(SUMPRODUCT(Synergies!$B$21:$F$21/Synergies!$B$11*C$15+Synergies!$B$22:$F$22,1/(1+$A19)^Synergies!$B$18:$F$18)+Synergies!$F$21/Synergies!$B$11*C$15*(1+Synergies!$B$15)/($A19-Synergies!$B$15)/(1+$A19)^Synergies!$F$18)-'Valuation & Verdict'!$B$38 -> -650.96287 | D19: =(SUMPRODUCT('Valuation & Verdict'!$B$16:$F$16,1/(1+$A19)^'Valuation & Verdict'!$B$17:$F$17)+'Valuation & Verdict'!$B$13*(1+'Valuation & Verdict'!$B$6)/($A19-'Valuation & Verdict'!$B$6)/(1+$A19)^'Valuation & Verdict'!$F$17)+(SUMPRODUCT(Synergies!$B$21:$F$21/Synergies!$B$11*D$15+Synergies!$B$22:$F$22,1/(1+$A19)^Synergies!$B$18:$F$18)+Synergies!$F$21/Synergies!$B$11*D$15*(1+Synergies!$B$15)/($A19-Synergies!$B$15)/(1+$A19)^Synergies!$F$18)-'Valuation & Verdict'!$B$38 -> 360.82232 | E19: =(SUMPRODUCT('Valuation & Verdict'!$B$16:$F$16,1/(1+$A19)^'Valuation & Verdict'!$B$17:$F$17)+'Valuation & Verdict'!$B$13*(1+'Valuation & Verdict'!$B$6)/($A19-'Valuation & Verdict'!$B$6)/(1+$A19)^'Valuation & Verdict'!$F$17)+(SUMPRODUCT(Synergies!$B$21:$F$21/Synergies!$B$11*E$15+Synergies!$B$22:$F$22,1/(1+$A19)^Synergies!$B$18:$F$18)+Synergies!$F$21/Synergies!$B$11*E$15*(1+Synergies!$B$15)/($A19-Synergies!$B$15)/(1+$A19)^Synergies!$F$18)-'Valuation & Verdict'!$B$38 -> 866.71491 | F19: =(SUMPRODUCT('Valuation & Verdict'!$B$16:$F$16,1/(1+$A19)^'Valuation & Verdict'!$B$17:$F$17)+'Valuation & Verdict'!$B$13*(1+'Valuation & Verdict'!$B$6)/($A19-'Valuation & Verdict'!$B$6)/(1+$A19)^'Valuation & Verdict'!$F$17)+(SUMPRODUCT(Synergies!$B$21:$F$21/Synergies!$B$11*F$15+Synergies!$B$22:$F$22,1/(1+$A19)^Synergies!$B$18:$F$18)+Synergies!$F$21/Synergies!$B$11*F$15*(1+Synergies!$B$15)/($A19-Synergies!$B$15)/(1+$A19)^Synergies!$F$18)-'Valuation & Verdict'!$B$38 -> 2384.3927
A20: 0.11 | B20: =(SUMPRODUCT('Valuation & Verdict'!$B$16:$F$16,1/(1+$A20)^'Valuation & Verdict'!$B$17:$F$17)+'Valuation & Verdict'!$B$13*(1+'Valuation & Verdict'!$B$6)/($A20-'Valuation & Verdict'!$B$6)/(1+$A20)^'Valuation & Verdict'!$F$17)+(SUMPRODUCT(Synergies!$B$21:$F$21/Synergies!$B$11*B$15+Synergies!$B$22:$F$22,1/(1+$A20)^Synergies!$B$18:$F$18)+Synergies!$F$21/Synergies!$B$11*B$15*(1+Synergies!$B$15)/($A20-Synergies!$B$15)/(1+$A20)^Synergies!$F$18)-'Valuation & Verdict'!$B$38 -> -2129.3804 | C20: =(SUMPRODUCT('Valuation & Verdict'!$B$16:$F$16,1/(1+$A20)^'Valuation & Verdict'!$B$17:$F$17)+'Valuation & Verdict'!$B$13*(1+'Valuation & Verdict'!$B$6)/($A20-'Valuation & Verdict'!$B$6)/(1+$A20)^'Valuation & Verdict'!$F$17)+(SUMPRODUCT(Synergies!$B$21:$F$21/Synergies!$B$11*C$15+Synergies!$B$22:$F$22,1/(1+$A20)^Synergies!$B$18:$F$18)+Synergies!$F$21/Synergies!$B$11*C$15*(1+Synergies!$B$15)/($A20-Synergies!$B$15)/(1+$A20)^Synergies!$F$18)-'Valuation & Verdict'!$B$38 -> -1165.669 | D20: =(SUMPRODUCT('Valuation & Verdict'!$B$16:$F$16,1/(1+$A20)^'Valuation & Verdict'!$B$17:$F$17)+'Valuation & Verdict'!$B$13*(1+'Valuation & Verdict'!$B$6)/($A20-'Valuation & Verdict'!$B$6)/(1+$A20)^'Valuation & Verdict'!$F$17)+(SUMPRODUCT(Synergies!$B$21:$F$21/Synergies!$B$11*D$15+Synergies!$B$22:$F$22,1/(1+$A20)^Synergies!$B$18:$F$18)+Synergies!$F$21/Synergies!$B$11*D$15*(1+Synergies!$B$15)/($A20-Synergies!$B$15)/(1+$A20)^Synergies!$F$18)-'Valuation & Verdict'!$B$38 -> -201.95757 | E20: =(SUMPRODUCT('Valuation & Verdict'!$B$16:$F$16,1/(1+$A20)^'Valuation & Verdict'!$B$17:$F$17)+'Valuation & Verdict'!$B$13*(1+'Valuation & Verdict'!$B$6)/($A20-'Valuation & Verdict'!$B$6)/(1+$A20)^'Valuation & Verdict'!$F$17)+(SUMPRODUCT(Synergies!$B$21:$F$21/Synergies!$B$11*E$15+Synergies!$B$22:$F$22,1/(1+$A20)^Synergies!$B$18:$F$18)+Synergies!$F$21/Synergies!$B$11*E$15*(1+Synergies!$B$15)/($A20-Synergies!$B$15)/(1+$A20)^Synergies!$F$18)-'Valuation & Verdict'!$B$38 -> 279.89814 | F20: =(SUMPRODUCT('Valuation & Verdict'!$B$16:$F$16,1/(1+$A20)^'Valuation & Verdict'!$B$17:$F$17)+'Valuation & Verdict'!$B$13*(1+'Valuation & Verdict'!$B$6)/($A20-'Valuation & Verdict'!$B$6)/(1+$A20)^'Valuation & Verdict'!$F$17)+(SUMPRODUCT(Synergies!$B$21:$F$21/Synergies!$B$11*F$15+Synergies!$B$22:$F$22,1/(1+$A20)^Synergies!$B$18:$F$18)+Synergies!$F$21/Synergies!$B$11*F$15*(1+Synergies!$B$15)/($A20-Synergies!$B$15)/(1+$A20)^Synergies!$F$18)-'Valuation & Verdict'!$B$38 -> 1725.4653
A21: Check: base rate and delivery vs Valuation & Verdict (must be 0) | B21: =ROUND(INDEX(B16:F20,MATCH(Synergies!B14,A16:A20,0),MATCH(Synergies!B11,B15:F15,0))-'Valuation & Verdict'!B39,0) -> 0
A23: 3) NPV TO SUN ($m) — terminal free cash flow (rows) × discount rate (columns), base synergies
A24: Terminal FCF ↓ / rate → | B24: 0.09 | C24: 0.1 | D24: 0.105 | E24: 0.11
A25: 774 | B25: =(SUMPRODUCT('Valuation & Verdict'!$B$16:$F$16,1/(1+B$24)^'Valuation & Verdict'!$B$17:$F$17)+$A25*(1+'Valuation & Verdict'!$B$6)/(B$24-'Valuation & Verdict'!$B$6)/(1+B$24)^'Valuation & Verdict'!$F$17)+(SUMPRODUCT(Synergies!$B$21:$F$21+Synergies!$B$22:$F$22,1/(1+B$24)^Synergies!$B$18:$F$18)+Synergies!$F$21*(1+Synergies!$B$15)/(B$24-Synergies!$B$15)/(1+B$24)^Synergies!$F$18)-'Valuation & Verdict'!$B$38 -> -1142.5173 | C25: =(SUMPRODUCT('Valuation & Verdict'!$B$16:$F$16,1/(1+C$24)^'Valuation & Verdict'!$B$17:$F$17)+$A25*(1+'Valuation & Verdict'!$B$6)/(C$24-'Valuation & Verdict'!$B$6)/(1+C$24)^'Valuation & Verdict'!$F$17)+(SUMPRODUCT(Synergies!$B$21:$F$21+Synergies!$B$22:$F$22,1/(1+C$24)^Synergies!$B$18:$F$18)+Synergies!$F$21*(1+Synergies!$B$15)/(C$24-Synergies!$B$15)/(1+C$24)^Synergies!$F$18)-'Valuation & Verdict'!$B$38 -> -2118.1231 | D25: =(SUMPRODUCT('Valuation & Verdict'!$B$16:$F$16,1/(1+D$24)^'Valuation & Verdict'!$B$17:$F$17)+$A25*(1+'Valuation & Verdict'!$B$6)/(D$24-'Valuation & Verdict'!$B$6)/(1+D$24)^'Valuation & Verdict'!$F$17)+(SUMPRODUCT(Synergies!$B$21:$F$21+Synergies!$B$22:$F$22,1/(1+D$24)^Synergies!$B$18:$F$18)+Synergies!$F$21*(1+Synergies!$B$15)/(D$24-Synergies!$B$15)/(1+D$24)^Synergies!$F$18)-'Valuation & Verdict'!$B$38 -> -2542.3736 | E25: =(SUMPRODUCT('Valuation & Verdict'!$B$16:$F$16,1/(1+E$24)^'Valuation & Verdict'!$B$17:$F$17)+$A25*(1+'Valuation & Verdict'!$B$6)/(E$24-'Valuation & Verdict'!$B$6)/(1+E$24)^'Valuation & Verdict'!$F$17)+(SUMPRODUCT(Synergies!$B$21:$F$21+Synergies!$B$22:$F$22,1/(1+E$24)^Synergies!$B$18:$F$18)+Synergies!$F$21*(1+Synergies!$B$15)/(E$24-Synergies!$B$15)/(1+E$24)^Synergies!$F$18)-'Valuation & Verdict'!$B$38 -> -2931.3121
A26: 930 | B26: =(SUMPRODUCT('Valuation & Verdict'!$B$16:$F$16,1/(1+B$24)^'Valuation & Verdict'!$B$17:$F$17)+$A26*(1+'Valuation & Verdict'!$B$6)/(B$24-'Valuation & Verdict'!$B$6)/(1+B$24)^'Valuation & Verdict'!$F$17)+(SUMPRODUCT(Synergies!$B$21:$F$21+Synergies!$B$22:$F$22,1/(1+B$24)^Synergies!$B$18:$F$18)+Synergies!$F$21*(1+Synergies!$B$15)/(B$24-Synergies!$B$15)/(1+B$24)^Synergies!$F$18)-'Valuation & Verdict'!$B$38 -> -71.74489 | C26: =(SUMPRODUCT('Valuation & Verdict'!$B$16:$F$16,1/(1+C$24)^'Valuation & Verdict'!$B$17:$F$17)+$A26*(1+'Valuation & Verdict'!$B$6)/(C$24-'Valuation & Verdict'!$B$6)/(1+C$24)^'Valuation & Verdict'!$F$17)+(SUMPRODUCT(Synergies!$B$21:$F$21+Synergies!$B$22:$F$22,1/(1+C$24)^Synergies!$B$18:$F$18)+Synergies!$F$21*(1+Synergies!$B$15)/(C$24-Synergies!$B$15)/(1+C$24)^Synergies!$F$18)-'Valuation & Verdict'!$B$38 -> -1181.7516 | D26: =(SUMPRODUCT('Valuation & Verdict'!$B$16:$F$16,1/(1+D$24)^'Valuation & Verdict'!$B$17:$F$17)+$A26*(1+'Valuation & Verdict'!$B$6)/(D$24-'Valuation & Verdict'!$B$6)/(1+D$24)^'Valuation & Verdict'!$F$17)+(SUMPRODUCT(Synergies!$B$21:$F$21+Synergies!$B$22:$F$22,1/(1+D$24)^Synergies!$B$18:$F$18)+Synergies!$F$21*(1+Synergies!$B$15)/(D$24-Synergies!$B$15)/(1+D$24)^Synergies!$F$18)-'Valuation & Verdict'!$B$38 -> -1663.8119 | E26: =(SUMPRODUCT('Valuation & Verdict'!$B$16:$F$16,1/(1+E$24)^'Valuation & Verdict'!$B$17:$F$17)+$A26*(1+'Valuation & Verdict'!$B$6)/(E$24-'Valuation & Verdict'!$B$6)/(1+E$24)^'Valuation & Verdict'!$F$17)+(SUMPRODUCT(Synergies!$B$21:$F$21+Synergies!$B$22:$F$22,1/(1+E$24)^Synergies!$B$18:$F$18)+Synergies!$F$21*(1+Synergies!$B$15)/(E$24-Synergies!$B$15)/(1+E$24)^Synergies!$F$18)-'Valuation & Verdict'!$B$38 -> -2105.3581
A27: 1100 | B27: =(SUMPRODUCT('Valuation & Verdict'!$B$16:$F$16,1/(1+B$24)^'Valuation & Verdict'!$B$17:$F$17)+$A27*(1+'Valuation & Verdict'!$B$6)/(B$24-'Valuation & Verdict'!$B$6)/(1+B$24)^'Valuation & Verdict'!$F$17)+(SUMPRODUCT(Synergies!$B$21:$F$21+Synergies!$B$22:$F$22,1/(1+B$24)^Synergies!$B$18:$F$18)+Synergies!$F$21*(1+Synergies!$B$15)/(B$24-Synergies!$B$15)/(1+B$24)^Synergies!$F$18)-'Valuation & Verdict'!$B$38 -> 1095.1225 | C27: =(SUMPRODUCT('Valuation & Verdict'!$B$16:$F$16,1/(1+C$24)^'Valuation & Verdict'!$B$17:$F$17)+$A27*(1+'Valuation & Verdict'!$B$6)/(C$24-'Valuation & Verdict'!$B$6)/(1+C$24)^'Valuation & Verdict'!$F$17)+(SUMPRODUCT(Synergies!$B$21:$F$21+Synergies!$B$22:$F$22,1/(1+C$24)^Synergies!$B$18:$F$18)+Synergies!$F$21*(1+Synergies!$B$15)/(C$24-Synergies!$B$15)/(1+C$24)^Synergies!$F$18)-'Valuation & Verdict'!$B$38 -> -161.34671 | D27: =(SUMPRODUCT('Valuation & Verdict'!$B$16:$F$16,1/(1+D$24)^'Valuation & Verdict'!$B$17:$F$17)+$A27*(1+'Valuation & Verdict'!$B$6)/(D$24-'Valuation & Verdict'!$B$6)/(1+D$24)^'Valuation & Verdict'!$F$17)+(SUMPRODUCT(Synergies!$B$21:$F$21+Synergies!$B$22:$F$22,1/(1+D$24)^Synergies!$B$18:$F$18)+Synergies!$F$21*(1+Synergies!$B$15)/(D$24-Synergies!$B$15)/(1+D$24)^Synergies!$F$18)-'Valuation & Verdict'!$B$38 -> -706.40489 | E27: =(SUMPRODUCT('Valuation & Verdict'!$B$16:$F$16,1/(1+E$24)^'Valuation & Verdict'!$B$17:$F$17)+$A27*(1+'Valuation & Verdict'!$B$6)/(E$24-'Valuation & Verdict'!$B$6)/(1+E$24)^'Valuation & Verdict'!$F$17)+(SUMPRODUCT(Synergies!$B$21:$F$21+Synergies!$B$22:$F$22,1/(1+E$24)^Synergies!$B$18:$F$18)+Synergies!$F$21*(1+Synergies!$B$15)/(E$24-Synergies!$B$15)/(1+E$24)^Synergies!$F$18)-'Valuation & Verdict'!$B$38 -> -1205.28
A28: ='Valuation & Verdict'!B13 -> 1289.5 | B28: =(SUMPRODUCT('Valuation & Verdict'!$B$16:$F$16,1/(1+B$24)^'Valuation & Verdict'!$B$17:$F$17)+$A28*(1+'Valuation & Verdict'!$B$6)/(B$24-'Valuation & Verdict'!$B$6)/(1+B$24)^'Valuation & Verdict'!$F$17)+(SUMPRODUCT(Synergies!$B$21:$F$21+Synergies!$B$22:$F$22,1/(1+B$24)^Synergies!$B$18:$F$18)+Synergies!$F$21*(1+Synergies!$B$15)/(B$24-Synergies!$B$15)/(1+B$24)^Synergies!$F$18)-'Valuation & Verdict'!$B$38 -> 2395.8364 | C28: =(SUMPRODUCT('Valuation & Verdict'!$B$16:$F$16,1/(1+C$24)^'Valuation & Verdict'!$B$17:$F$17)+$A28*(1+'Valuation & Verdict'!$B$6)/(C$24-'Valuation & Verdict'!$B$6)/(1+C$24)^'Valuation & Verdict'!$F$17)+(SUMPRODUCT(Synergies!$B$21:$F$21+Synergies!$B$22:$F$22,1/(1+C$24)^Synergies!$B$18:$F$18)+Synergies!$F$21*(1+Synergies!$B$15)/(C$24-Synergies!$B$15)/(1+C$24)^Synergies!$F$18)-'Valuation & Verdict'!$B$38 -> 976.10459 | D28: =(SUMPRODUCT('Valuation & Verdict'!$B$16:$F$16,1/(1+D$24)^'Valuation & Verdict'!$B$17:$F$17)+$A28*(1+'Valuation & Verdict'!$B$6)/(D$24-'Valuation & Verdict'!$B$6)/(1+D$24)^'Valuation & Verdict'!$F$17)+(SUMPRODUCT(Synergies!$B$21:$F$21+Synergies!$B$22:$F$22,1/(1+D$24)^Synergies!$B$18:$F$18)+Synergies!$F$21*(1+Synergies!$B$15)/(D$24-Synergies!$B$15)/(1+D$24)^Synergies!$F$18)-'Valuation & Verdict'!$B$38 -> 360.82232 | E28: =(SUMPRODUCT('Valuation & Verdict'!$B$16:$F$16,1/(1+E$24)^'Valuation & Verdict'!$B$17:$F$17)+$A28*(1+'Valuation & Verdict'!$B$6)/(E$24-'Valuation & Verdict'!$B$6)/(1+E$24)^'Valuation & Verdict'!$F$17)+(SUMPRODUCT(Synergies!$B$21:$F$21+Synergies!$B$22:$F$22,1/(1+E$24)^Synergies!$B$18:$F$18)+Synergies!$F$21*(1+Synergies!$B$15)/(E$24-Synergies!$B$15)/(1+E$24)^Synergies!$F$18)-'Valuation & Verdict'!$B$38 -> -201.95757
A29: 1400 | B29: =(SUMPRODUCT('Valuation & Verdict'!$B$16:$F$16,1/(1+B$24)^'Valuation & Verdict'!$B$17:$F$17)+$A29*(1+'Valuation & Verdict'!$B$6)/(B$24-'Valuation & Verdict'!$B$6)/(1+B$24)^'Valuation & Verdict'!$F$17)+(SUMPRODUCT(Synergies!$B$21:$F$21+Synergies!$B$22:$F$22,1/(1+B$24)^Synergies!$B$18:$F$18)+Synergies!$F$21*(1+Synergies!$B$15)/(B$24-Synergies!$B$15)/(1+B$24)^Synergies!$F$18)-'Valuation & Verdict'!$B$38 -> 3154.3002 | C29: =(SUMPRODUCT('Valuation & Verdict'!$B$16:$F$16,1/(1+C$24)^'Valuation & Verdict'!$B$17:$F$17)+$A29*(1+'Valuation & Verdict'!$B$6)/(C$24-'Valuation & Verdict'!$B$6)/(1+C$24)^'Valuation & Verdict'!$F$17)+(SUMPRODUCT(Synergies!$B$21:$F$21+Synergies!$B$22:$F$22,1/(1+C$24)^Synergies!$B$18:$F$18)+Synergies!$F$21*(1+Synergies!$B$15)/(C$24-Synergies!$B$15)/(1+C$24)^Synergies!$F$18)-'Valuation & Verdict'!$B$38 -> 1639.3677 | D29: =(SUMPRODUCT('Valuation & Verdict'!$B$16:$F$16,1/(1+D$24)^'Valuation & Verdict'!$B$17:$F$17)+$A29*(1+'Valuation & Verdict'!$B$6)/(D$24-'Valuation & Verdict'!$B$6)/(1+D$24)^'Valuation & Verdict'!$F$17)+(SUMPRODUCT(Synergies!$B$21:$F$21+Synergies!$B$22:$F$22,1/(1+D$24)^Synergies!$B$18:$F$18)+Synergies!$F$21*(1+Synergies!$B$15)/(D$24-Synergies!$B$15)/(1+D$24)^Synergies!$F$18)-'Valuation & Verdict'!$B$38 -> 983.13686 | E29: =(SUMPRODUCT('Valuation & Verdict'!$B$16:$F$16,1/(1+E$24)^'Valuation & Verdict'!$B$17:$F$17)+$A29*(1+'Valuation & Verdict'!$B$6)/(E$24-'Valuation & Verdict'!$B$6)/(1+E$24)^'Valuation & Verdict'!$F$17)+(SUMPRODUCT(Synergies!$B$21:$F$21+Synergies!$B$22:$F$22,1/(1+E$24)^Synergies!$B$18:$F$18)+Synergies!$F$21*(1+Synergies!$B$15)/(E$24-Synergies!$B$15)/(1+E$24)^Synergies!$F$18)-'Valuation & Verdict'!$B$38 -> 383.09322
A30: Check: base terminal FCF and rate vs Valuation & Verdict (must be 0) | B30: =ROUND(INDEX(B28:E28,MATCH(Synergies!B14,B24:E24,0))-'Valuation & Verdict'!B39,0) -> 0
A31: $774m = 2030E UFCF as published; $930m = 2027E–2029E average UFCF (both still carry the one-off costs); the base row is the clean build on Valuation & Verdict.
A33: 4) EPS ACCRETION FY2028E, reported basis — Sun's guide delivered (rows) × cost of acquisition debt (columns)
A34: Delivery ↓ / debt cost → | B34: 0.055 | C34: 0.06 | D34: 0.065 | E34: 0.07 | F34: 0.08
