Workbook

Sheet Cover
B2: HINDUSTAN UNILEVER LIMITED (HUL)
B3: Business Valuation Model — FMCG Sector | NSE: HINDUNILVR
B4: All figures in ₹ Millions (INR Mn) unless otherwise stated | Updated: 21 Jul 2026
B7: MODEL NAVIGATION
B8: Sheet | E8: Description
B9: Income Statement | E9: Revenue, EBIT, PAT — FY2022 to FY2026
B10: Balance Sheet | E10: Assets, Liabilities & Equity — FY2022 to FY2026
B11: Cash Flow | E11: Operating, Investing, Financing — FY2022 to FY2026
B12: Key Ratios | E12: Margins, Returns, Liquidity, Efficiency
B13: DCF Model | E13: Intrinsic value via Free Cash Flow discounting (to be built)
B14: PE Valuation | E14: Relative valuation via Price/Earnings multiples (to be built)
B16: ⚠ Color Coding: Blue = Hardcoded Input | Black = Formula | Green = Cross-sheet Link
B17: Source: Hindustan Unilever Annual Reports (NSE Filings) | FY2022–FY2026 (April–March fiscal year)
B20: VALUATION SUMMARY & METHODOLOGY NOTE
B22: Approach | C22: Target Price (₹) | D22: vs. ₹2,140 | E22: Signal
B23: DCF (Base Case) | C23: ='DCF Model'!C47 | D23: ='DCF Model'!C49 | E23: SELL
B24: P/E (Median 5Y multiple) | C24: ='PE Valuation'!D28 | D24: ='PE Valuation'!E28 | E24: BUY
B25: Reverse DCF Implied g | C25: ='DCF Model'!C78 | D25: vs 4.5% base | E25: DEMANDING
B28: Methodology & Reconciliation
B30: The two valuation approaches diverge sharply: DCF implies ₹712 (‑67% downside); P/E implies ₹2,826 (+33% upside).
B31: This is a classic FMCG "quality premium" disconnect. Three drivers explain the gap:
B33: 1. Terminal growth assumption. | C33: DCF assumes 4.5% perpetual growth. Reverse DCF shows the market is pricing in ~9.1% — well above India's long-run nominal GDP and HUL's recent 6.5% 5Y CAGR.
B34: 2. P/E reflects market sentiment, not intrinsic value. | C34: FMCG names trade at premium multiples (50–60x) due to brand moats, cash generation, and low cyclicality — a regime DCF doesn't capture.
B35: 3. Terminal value dominates DCF. | C35: ~75% of EV sits in the terminal value, making the result highly sensitive to WACC and g (see Sensitivity table on DCF Model sheet).
B37: Recommendation: | C37: Use DCF as a discipline check, not a target. The implied ~9.1% terminal growth is aggressive for a mature FMCG franchise. A blended view (70% P/E, 30% DCF) gives a fair value of ~₹2,190 — essentially in line with the market price of ₹2,140. Rating: HOLD (no margin of safety at current levels; quality intact).
B39: Data Source: | C39: screener.in consolidated financials (sourced from BSE/NSE filings & HUL Annual Reports FY22–FY26). Original figures in ₹ Crores; converted to ₹ Mn (×10).

Sheet IS
B2: HINDUSTAN UNILEVER LIMITED — INCOME STATEMENT
B3: Consolidated P&L | FY2022 – FY2026 (April – March Fiscal Year)
B4: Figures in ₹ Millions (INR Mn) | FY ends March 31 | Source: HUL Annual Reports (NSE Filings)
B6: Line Item | C6: FY2022 | D6: FY2023 | E6: FY2024 | F6: FY2025 | G6: FY2026
B7: REVENUE
B8: Net Revenue / Net Sales | C8: 524460 | D8: 605800 | E8: 618960 | F8: 631210 | G8: 644680
B9: Cost of Revenue (COGS) | C9: 395890 | D9: 464330 | E9: 472370 | F9: 482780 | G9: 494290
B10: Gross Profit | C10: =C8-C9 | D10: =D8-D9 | E10: =E8-E9 | F10: =F8-F9 | G10: =G8-G9
B11: Gross Margin % | C11: =C10/C8 | D11: =D10/D8 | E11: =E10/E8 | F11: =F10/F8 | G11: =G10/G8
B13: OPERATING EXPENSES
B14: SG&A Expenses
B15: R&D Expenses
B16: Other Operating Expenses
B17: Total Operating Expenses | C17: =SUM(C14:C16) | D17: =SUM(D14:D16) | E17: =SUM(E14:E16) | F17: =SUM(F14:F16) | G17: =SUM(G14:G16)
B19: PROFITABILITY
B20: EBITDA | C20: 128570 | D20: 141470 | E20: 146590 | F20: 148430 | G20: 150390
B21: Depreciation & Amortization | C21: 10910 | D21: 11370 | E21: 12160 | F21: 13550 | G21: 13330
B22: EBIT (Operating Income) | C22: =C20-C21 | D22: =D20-D21 | E22: =E20-E21 | F22: =F20-F21 | G22: =G20-G21
B23: EBIT Margin % | C23: =C22/C8 | D23: =D22/D8 | E23: =E22/E8 | F23: =F22/F8 | G23: =G22/G8
B24: Interest Expense | C24: 1060 | D24: 1140 | E24: 3340 | F24: 3950 | G24: 4100
B25: Interest Income
B26: Other Non-Operating Income | C26: 2190 | D26: 4480 | E26: 8170 | F26: 13220 | G26: 9570
B27: Income Before Tax (PBT) | C27: =C22-C24+C25+C26 | D27: =D22-D24+D25+D26 | E27: =E22-E24+E25+E26 | F27: =F22-F24+F25+F26 | G27: =G22-G24+G25+G26
B28: Income Tax Expense | C28: =C27*0.25 | D28: =D27*0.24 | E28: =E27*0.26 | F28: =F27*0.26 | G28: =G27*0.25
B29: Net Income (PAT) | C29: =C27-C28 | D29: =D27-D28 | E29: =E27-E28 | F29: =F27-F28 | G29: =G27-G28
B30: Net Profit Margin % | C30: =C29/C8 | D30: =D29/D8 | E30: =E29/E8 | F30: =F29/F8 | G30: =G29/G8
B32: PER SHARE DATA
B33: EPS (Basic, ₹) | C33: 37.79 | D33: 43.07 | E33: 43.74 | F33: 45.32 | G33: =G29/G35
B34: EPS (Diluted, ₹) | C34: 37.79 | D34: 43.07 | E34: 43.74 | F34: 45.32 | G34: =G29/G35
B35: Weighted Avg. Shares (Mn) | C35: =C29/C33 | D35: =D29/D33 | E35: =E29/E33 | F35: =F29/F33 | G35: 2349.6
B37: Source: Hindustan Unilever NSE Filings | FY2022–FY2026 | Generated: 22 May 2026

Sheet BS
B2: HINDUSTAN UNILEVER LIMITED — BALANCE SHEET
B3: Consolidated Balance Sheet | FY2022 – FY2026 (April – March Fiscal Year)
B4: Figures in ₹ Millions (INR Mn) | FY ends March 31 | Source: HUL Annual Reports (NSE Filings)
B6: Line Item | C6: FY2022 | D6: FY2023 | E6: FY2024 | F6: FY2025 | G6: FY2026
B7: CURRENT ASSETS
B8: Cash & Cash Equivalents
B9: Short-Term Investments
B10: Cash & Short-Term Investments | C10: =C8+C9 | D10: =D8+D9 | E10: =E8+E9 | F10: =F8+F9 | G10: =G8+G9
B11: Net Receivables
B12: Inventory
B13: Prepaid Expenses
B14: Other Current Assets
B15: Total Current Assets | C15: =SUM(C10:C14) | D15: =SUM(D10:D14) | E15: =SUM(E10:E14) | F15: =SUM(F10:F14) | G15: =SUM(G10:G14)
B17: NON-CURRENT ASSETS
B18: Property, Plant & Equipment (Net) | C18: 527860 | D18: 538100 | E18: 547690 | F18: 553440 | G18: 583080
B19: Goodwill
B20: Intangible Assets
B21: Long-Term Investments | C21: 35210 | D21: 28820 | E21: 46250 | F21: 38100 | G21: 43590
B22: Other Non-Current Assets | C22: 141990 | D22: 163850 | E22: 190950 | F22: 207090 | G22: 170850
B23: Total Non-Current Assets | C23: =SUM(C18:C22) | D23: =SUM(D18:D22) | E23: =SUM(E18:E22) | F23: =SUM(F18:F22) | G23: =SUM(G18:G22)
B25: TOTAL ASSETS | C25: =C15+C23 | D25: =D15+D23 | E25: =E15+E23 | F25: =F15+F23 | G25: =G15+G23
B27: CURRENT LIABILITIES
B28: Accounts Payable
B29: Short-Term Debt
B30: Tax Payables
B31: Other Current Liabilities | C31: 204020 | D31: 215540 | E31: 257870 | F31: 288130 | G31: 295350
B32: Total Current Liabilities | C32: =SUM(C28:C31) | D32: =SUM(D28:D31) | E32: =SUM(E28:E31) | F32: =SUM(F28:F31) | G32: =SUM(G28:G31)
B34: NON-CURRENT LIABILITIES
B35: Long-Term Debt | C35: 10430 | D35: 12190 | E35: 14840 | F35: 16480 | G35: 14780
B36: Deferred Tax Liabilities
B37: Lease Obligations (Non-Current)
B38: Other Non-Current Liabilities
B39: Total Non-Current Liabilities | C39: =SUM(C35:C38) | D39: =SUM(D35:D38) | E39: =SUM(E35:E38) | F39: =SUM(F35:F38) | G39: =SUM(G35:G38)
B41: TOTAL LIABILITIES | C41: =C32+C39 | D41: =D32+D39 | E41: =E32+E39 | F41: =F32+F39 | G41: =G32+G39
B43: SHAREHOLDERS' EQUITY
B44: Share Capital | C44: 2350 | D44: 2350 | E44: 2350 | F44: 2350 | G44: 2350
B45: Retained Earnings | C45: 488260 | D45: 500690 | E45: 509830 | F45: 491670 | G45: 485040
B46: Additional Paid-In Capital
B47: Other Comprehensive Income
B48: Total Shareholders' Equity | C48: =SUM(C44:C47) | D48: =SUM(D44:D47) | E48: =SUM(E44:E47) | F48: =SUM(F44:F47) | G48: =SUM(G44:G47)
...

Sheet CF
B2: HINDUSTAN UNILEVER LIMITED — CASH FLOW STATEMENT
B3: Consolidated Cash Flows | FY2022 – FY2026 (April – March Fiscal Year)
B4: Figures in ₹ Millions (INR Mn) | FY ends March 31 | Source: HUL Annual Reports (NSE Filings)
B6: Line Item | C6: FY2022 | D6: FY2023 | E6: FY2024 | F6: FY2025 | G6: FY2026
B7: OPERATING ACTIVITIES
B8: Net Income | C8: =IS!C29 | D8: =IS!D29 | E8: =IS!E29 | F8: =IS!F29 | G8: =IS!G29
B9: Depreciation & Amortization | C9: =IS!C21 | D9: =IS!D21 | E9: =IS!E21 | F9: =IS!F21 | G9: =IS!G21
B10: Deferred Income Tax
B11: Stock-Based Compensation
B12: Change in Accounts Receivable
B13: Change in Inventory
B14: Change in Accounts Payable
B15: Other Working Capital Changes
B16: Other Non-Cash Items | C16: =C17-SUM(C8:C15) | D16: =D17-SUM(D8:D15) | E16: =E17-SUM(E8:E15) | F16: =F17-SUM(F8:F15) | G16: =G17-SUM(G8:G15)
B17: Net Cash from Operating Activities | C17: 90480 | D17: 99910 | E17: 154690 | F17: 118860 | G17: 109990
B19: INVESTING ACTIVITIES
B20: Capital Expenditure (Capex) | C20: -10530 | D20: -10110 | E20: -14570 | F20: -12620 | G20: -13310
B21: Acquisitions (Net)
B22: Purchases of Investments
B23: Sales & Maturities of Investments
B24: Other Investing Activities | C24: =C25-SUM(C20:C23) | D24: =D25-SUM(D20:D23) | E24: =E25-SUM(E20:E23) | F24: =F25-SUM(F20:F23) | G24: =G25-SUM(G20:G23)
B25: Net Cash from Investing Activities | C25: -17280 | D25: -14840 | E25: -53240 | F25: 64730 | G25: -36840
B27: FINANCING ACTIVITIES
B28: Net Debt Issuance
B29: Common Dividends Paid
B30: Other Financing Activities | C30: =C31-SUM(C28:C29) | D30: =D31-SUM(D28:D29) | E30: =E31-SUM(E28:E29) | F30: =F31-SUM(F28:F29) | G30: =G31-SUM(G28:G29)
B31: Net Cash from Financing Activities | C31: -80150 | D31: -89530 | E31: -100340 | F31: -131010 | G31: -108100
B33: Net Change in Cash | C33: =C17+C25+C31 | D33: =D17+D25+D31 | E33: =E17+E25+E31 | F33: =F17+F25+F31 | G33: =G17+G25+G31
B34: Cash at Beginning of Period
B35: Cash at End of Period
B37: FREE CASH FLOW
B38: Operating Cash Flow | C38: =C17 | D38: =D17 | E38: =E17 | F38: =F17 | G38: =G17
B39: Capital Expenditure | C39: =C20 | D39: =D20 | E39: =E20 | F39: =F20 | G39: =G20
B40: Free Cash Flow (FCF) | C40: =C38+C39 | D40: =D38+D39 | E40: =E38+E39 | F40: =F38+F39 | G40: =G38+G39
B41: FCF Margin % | C41: =C40/IS!C8 | D41: =D40/IS!D8 | E41: =E40/IS!E8 | F41: =F40/IS!F8 | G41: =G40/IS!G8
B43: OTHER
B44: Income Taxes Paid
B45: Interest Paid
B47: Source: Hindustan Unilever NSE Filings | FY2022–FY2026 | Generated: 22 May 2026

Sheet Key Ratios
B2: HINDUSTAN UNILEVER LIMITED — KEY FINANCIAL RATIOS
B3: Consolidated Ratios | FY2022 – FY2026 | Figures from IS, BS, CF Sheets
B4: ⚡ All ratios computed via cross-sheet formulas. Green = cross-sheet link.
B6: Ratio | C6: FY2022 | D6: FY2023 | E6: FY2024 | F6: FY2025 | G6: FY2026
B7: PROFITABILITY RATIOS
B8: Gross Margin % | C8: =IS!C10/IS!C8 | D8: =IS!D10/IS!D8 | E8: =IS!E10/IS!E8 | F8: =IS!F10/IS!F8 | G8: =IS!G10/IS!G8
B9: EBITDA Margin % | C9: =IS!C20/IS!C8 | D9: =IS!D20/IS!D8 | E9: =IS!E20/IS!E8 | F9: =IS!F20/IS!F8 | G9: =IS!G20/IS!G8
B10: EBIT Margin % | C10: =IS!C22/IS!C8 | D10: =IS!D22/IS!D8 | E10: =IS!E22/IS!E8 | F10: =IS!F22/IS!F8 | G10: =IS!G22/IS!G8
B11: Net Profit Margin % | C11: =IS!C29/IS!C8 | D11: =IS!D29/IS!D8 | E11: =IS!E29/IS!E8 | F11: =IS!F29/IS!F8 | G11: =IS!G29/IS!G8
B12: Return on Assets (ROA) | C12: =IS!C29/BS!C25 | D12: =IS!D29/BS!D25 | E12: =IS!E29/BS!E25 | F12: =IS!F29/BS!F25 | G12: =IS!G29/BS!G25
B13: Return on Equity (ROE) | C13: =IS!C29/BS!C50 | D13: =IS!D29/BS!D50 | E13: =IS!E29/BS!E50 | F13: =IS!F29/BS!F50 | G13: =IS!G29/BS!G50
B14: Return on Capital Employed (ROCE) | C14: =IS!C22/(BS!C25-BS!C32) | D14: =IS!D22/(BS!D25-BS!D32) | E14: =IS!E22/(BS!E25-BS!E32) | F14: =IS!F22/(BS!F25-BS!F32) | G14: =IS!G22/(BS!G25-BS!G32)
B16: LIQUIDITY RATIOS
B17: Current Ratio | C17: =BS!C15/BS!C32 | D17: =BS!D15/BS!D32 | E17: =BS!E15/BS!E32 | F17: =BS!F15/BS!F32 | G17: =BS!G15/BS!G32
B18: Quick Ratio | C18: =(BS!C15-BS!C12)/BS!C32 | D18: =(BS!D15-BS!D12)/BS!D32 | E18: =(BS!E15-BS!E12)/BS!E32 | F18: =(BS!F15-BS!F12)/BS!F32 | G18: =(BS!G15-BS!G12)/BS!G32
B20: LEVERAGE RATIOS
B21: Debt / Equity | C21: =BS!C55/BS!C50 | D21: =BS!D55/BS!D50 | E21: =BS!E55/BS!E50 | F21: =BS!F55/BS!F50 | G21: =BS!G55/BS!G50
B22: Net Debt / EBITDA | C22: =BS!C56/IS!C20 | D22: =BS!D56/IS!D20 | E22: =BS!E56/IS!E20 | F22: =BS!F56/IS!F20 | G22: =BS!G56/IS!G20
B23: Interest Coverage (EBIT/Int) | C23: =IS!C22/IS!C24 | D23: =IS!D22/IS!D24 | E23: =IS!E22/IS!E24 | F23: =IS!F22/IS!F24 | G23: =IS!G22/IS!G24
B25: EFFICIENCY RATIOS
B26: Asset Turnover | C26: =IS!C8/BS!C25 | D26: =IS!D8/BS!D25 | E26: =IS!E8/BS!E25 | F26: =IS!F8/BS!F25 | G26: =IS!G8/BS!G25
B27: Inventory Turnover * | C27: n/a | D27: n/a | E27: n/a | F27: n/a | G27: n/a
B28: Receivables Turnover * | C28: n/a | D28: n/a | E28: n/a | F28: n/a | G28: n/a
B29: * Inventory & receivables not broken out in BS (rolled into Other Assets); ratio unavailable.
B30: CASH FLOW RATIOS
B31: FCF Margin % | C31: =CF!C40/IS!C8 | D31: =CF!D40/IS!D8 | E31: =CF!E40/IS!E8 | F31: =CF!F40/IS!F8 | G31: =CF!G40/IS!G8
B32: FCF / Net Income | C32: =CF!C40/IS!C29 | D32: =CF!D40/IS!D29 | E32: =CF!E40/IS!E29 | F32: =CF!F40/IS!F29 | G32: =CF!G40/IS!G29
B33: Capex / Revenue % | C33: =ABS(CF!C39)/IS!C8 | D33: =ABS(CF!D39)/IS!D8 | E33: =ABS(CF!E39)/IS!E8 | F33: =ABS(CF!F39)/IS!F8 | G33: =ABS(CF!G39)/IS!G8
B34: Dividend Payout Ratio | C34: =ABS(CF!C29)/IS!C29 | D34: =ABS(CF!D29)/IS!D29 | E34: =ABS(CF!E29)/IS!E29 | F34: =ABS(CF!F29)/IS!F29 | G34: =ABS(CF!G29)/IS!G29
B36: Source: Cross-sheet formulas from IS, BS, CF sheets | Generated: 22 May 2026

Sheet DCF Model
B2: HINDUSTAN UNILEVER LIMITED — DCF VALUATION MODEL
B3: 5-Year Explicit Forecast + Gordon Growth Terminal Value | Figures in ₹ Mn
B6: KEY ASSUMPTIONS
B7: Revenue Growth Rate (Explicit) | C7: 0.07
B8: EBIT Margin (Steady) | C8: 0.21
B9: Tax Rate | C9: 0.25
B10: D&A as % of Revenue | C10: 0.021
B11: Capex as % of Revenue | C11: 0.022
B12: Δ Working Capital as % of Revenue | C12: 0.01
B13: WACC | C13: 0.11
B14: Terminal Growth Rate (g) | C14: 0.045
B15: Diluted Shares Outstanding (Mn) | C15: =IS!G35
B16: Net Debt / (Cash) (₹ Mn) | C16: =BS!G56
B17: Current Share Price (₹) | C17: 2139.7
B19: FREE CASH FLOW PROJECTION
B20: Line Item (₹ Mn) | C20: FY2026A | D20: FY2027E | E20: FY2028E | F20: FY2029E | G20: FY2030E | H20: FY2031E
B21: Revenue | C21: =IS!G8 | D21: =C21*(1+$C$7) | E21: =D21*(1+$C$7) | F21: =E21*(1+$C$7) | G21: =F21*(1+$C$7) | H21: =G21*(1+$C$7)
B22: Revenue Growth % | D22: =D21/C21-1 | E22: =E21/D21-1 | F22: =F21/E21-1 | G22: =G21/F21-1 | H22: =H21/G21-1
B23: EBIT | C23: =IS!G22 | D23: =D21*$C$8 | E23: =E21*$C$8 | F23: =F21*$C$8 | G23: =G21*$C$8 | H23: =H21*$C$8
B24: EBIT Margin % | C24: =C23/C21 | D24: =D23/D21 | E24: =E23/E21 | F24: =F23/F21 | G24: =G23/G21 | H24: =H23/H21
B25: Less: Taxes on EBIT | D25: =-D23*$C$9 | E25: =-E23*$C$9 | F25: =-F23*$C$9 | G25: =-G23*$C$9 | H25: =-H23*$C$9
B26: NOPAT | D26: =D23+D25 | E26: =E23+E25 | F26: =F23+F25 | G26: =G23+G25 | H26: =H23+H25
B27: Plus: D&A | D27: =D21*$C$10 | E27: =E21*$C$10 | F27: =F21*$C$10 | G27: =G21*$C$10 | H27: =H21*$C$10
B28: Less: Capex | D28: =-D21*$C$11 | E28: =-E21*$C$11 | F28: =-F21*$C$11 | G28: =-G21*$C$11 | H28: =-H21*$C$11
B29: Less: Δ Working Capital | D29: =-D21*$C$12 | E29: =-E21*$C$12 | F29: =-F21*$C$12 | G29: =-G21*$C$12 | H29: =-H21*$C$12
B30: Unlevered Free Cash Flow | D30: =SUM(D26:D29) | E30: =SUM(E26:E29) | F30: =SUM(F26:F29) | G30: =SUM(G26:G29) | H30: =SUM(H26:H29)
B32: DISCOUNTING & TERMINAL VALUE
B33: Period | D33: 1 | E33: 2 | F33: 3 | G33: 4 | H33: 5
B34: Discount Factor | D34: =1/(1+$C$13)^D33 | E34: =1/(1+$C$13)^E33 | F34: =1/(1+$C$13)^F33 | G34: =1/(1+$C$13)^G33 | H34: =1/(1+$C$13)^H33
B35: PV of FCF | D35: =D30*D34 | E35: =E30*E34 | F35: =F30*F34 | G35: =G30*G34 | H35: =H30*H34
B37: Terminal Value (Gordon Growth) | C37: =H30*(1+C14)/(C13-C14)
B38: PV of Terminal Value | C38: =C37*H34
B40: VALUATION SUMMARY
B41: Sum of PV of Explicit FCFs | C41: =SUM(D35:H35)
B42: PV of Terminal Value | C42: =C38
B43: Enterprise Value (EV) | C43: =C41+C42
B44: Less: Net Debt | C44: =-C16
B45: Equity Value | C45: =C43+C44
B46: Diluted Shares (Mn) | C46: =C15
B47: DCF Intrinsic Value / Share (₹) | C47: =C45/C46
...

Sheet PE Valuation
B2: HINDUSTAN UNILEVER LIMITED — P/E RELATIVE VALUATION
B3: Earnings Multiple Approach | Historical P/E Bands + Forward Earnings
B6: HISTORICAL EPS & P/E
B7: Metric | C7: FY2022 | D7: FY2023 | E7: FY2024 | F7: FY2025 | G7: FY2026
B8: EPS (₹) | C8: =IS!C33 | D8: =IS!D33 | E8: =IS!E33 | F8: =IS!F33 | G8: =IS!G33
B9: EPS Growth % | D9: =D8/C8-1 | E9: =E8/D8-1 | F9: =F8/E8-1 | G9: =G8/F8-1
B10: Avg Share Price (₹) | C10: 2270 | D10: 2585 | E10: 2470 | F10: 2400 | G10: 2350
B11: P/E Multiple (x) | C11: =C10/C8 | D11: =D10/D8 | E11: =E10/E8 | F11: =F10/F8 | G11: =G10/G8
B13: P/E BAND STATISTICS
B14: 5-Yr Average P/E | C14: =AVERAGE(C11:G11)
B15: 5-Yr Max P/E | C15: =MAX(C11:G11)
B16: 5-Yr Min P/E | C16: =MIN(C11:G11)
B17: 5-Yr Median P/E | C17: =MEDIAN(C11:G11)
B18: Current P/E | C18: =G11
B20: FORWARD EPS PROJECTION
B21: FY2026 EPS (Base) | C21: =G8
B22: EPS Growth Assumption (FY27E) | C22: 0.1
B23: FY2027E EPS | C23: =C21*(1+C22)
B25: P/E-BASED TARGET PRICE
B26: Scenario | C26: P/E (x) | D26: Target Price (₹) | E26: Upside %
B27: Bear (Min P/E) | C27: =C16 | D27: =C27*C23 | E27: =D27/G10-1
B28: Base (Median P/E) | C28: =C17 | D28: =C28*C23 | E28: =D28/G10-1
B29: Bull (Max P/E) | C29: =C15 | D29: =C29*C23 | E29: =D29/G10-1
B30: Average | C30: =C14 | D30: =C30*C23 | E30: =D30/G10-1
B32: CONCLUSION
B33: Current Price (₹) | C33: =G10
B34: Base Case Target (₹) | C34: =D28
B35: Implied Return % | C35: =C34/C33-1
B37: Source: HUL NSE Filings | Cross-sheet links to IS sheet | Generated: 22 May 2026
A50: ADDITIONAL VALUATION CROSS-CHECKS (multi-method)
A52: DIVIDEND DISCOUNT MODEL (H-model, 2-stage)
A53: FY26 dividend per share (₹) | B53: 41
A54: Cost of equity (Ke) | B54: 0.105
A55: Near-term dividend growth (gS, 5y) | B55: 0.09
A56: Terminal growth (gL) | B56: 0.06
A57: H (half of high-growth years) | B57: 2.5
A58: DDM value = [D0(1+gL)+D0·H·(gS−gL)]/(Ke−gL) (₹) | B58: =(B53*(1+B56)+B53*B57*(B55-B56))/(B54-B56)
A61: EV/EBITDA
A62: FY26 EBITDA (₹ Mn) | B62: =IS!G20
A63: Justified EV/EBITDA (x) — vs ~33x current | B63: 30
...

Sheet Football Field
B2: HINDUSTAN UNILEVER — FOOTBALL FIELD VALUATION CHART
B3: Implied share price range by valuation methodology | Current price: ₹2,140 | D3: Implied share price range by valuation methodology | Current price: ₹2,140
B5: Methodology | C5: Low (₹) | D5: Base (₹) | E5: High (₹) | F5: Width (High–Low) | H5: Reference
B6: DCF — Sensitivity Range | C6: =MIN('DCF Model'!C59:G63) | D6: ='DCF Model'!C47 | E6: =MAX('DCF Model'!C59:G63) | F6: =E6-C6 | H6: Current Price
B7: P/E — 5Y Min/Median/Max | C7: ='PE Valuation'!D27 | D7: ='PE Valuation'!D28 | E7: ='PE Valuation'!D29 | F7: =E7-C7 | H7: 2139.7
B8: P/E — ±1 Std Dev Band | C8: =('PE Valuation'!C14-STDEV('PE Valuation'!C11:G11))*'PE Valuation'!C23 | D8: ='PE Valuation'!C14*'PE Valuation'!C23 | E8: =('PE Valuation'!C14+STDEV('PE Valuation'!C11:G11))*'PE Valuation'!C23 | F8: =E8-C8 | H8: Bars above = upside
B9: Blended (70% P/E + 30% DCF) | C9: =0.7*C7+0.3*C6 | D9: =0.7*D7+0.3*D6 | E9: =0.7*E7+0.3*E6 | F9: =E9-C9 | H9: Bars below = downside
B10: 52-Week Trading Range (Indicative) | C10: 2023 | D10: 2139.7 | E10: 2750 | F10: =E10-C10 | H10: vs current price
B14: Methodology | C14: Low Spacer | D14: Range Width
B15: DCF Range | C15: =C6 | D15: =F6
B16: P/E (Min-Max) | C16: =C7 | D16: =F7
B17: P/E ±1σ | C17: =C8 | D17: =F8
B18: Blended | C18: =C9 | D18: =F9
B19: 52W Range | C19: =C10 | D19: =F10
