Workbook

Sheet Overview
A1: Larsen & Toubro Ltd (NSE: LT) — Sum-of-the-Parts Model & Valuation
A2: A conglomerate is valued by its parts. L&T holds controlling stakes in three separately listed companies whose market values are observable, so most of this model is arithmetic rather than assumption. The judgement sits in one place: what the unlisted core engineering business is worth.
A4: SNAPSHOT — 16 September 2026
A6: Live price (₹, close 16-Sep-2026) | B6: 3820 | C6: verified against the Screener session stamp (16 Sep 4:01 p.m.); ₹3,850 on 15-Sep | D6: verified against the Screener session stamp (16 Sep 4:01 p.m.); ₹3,850.7 on 15-Sep. Stock closed ₹3,819.50 on 17-Sep — our strike survives the next session to within ₹0.50.
A7: Shares outstanding (cr) | B7: 137.59 | D7: 1,375,768,535 shares outstanding (companiesmarketcap, 2026) = 137.58 cr — verified independently, not derived from mcap ÷ price. L&T allotted 28,903 ESOP shares on 15-Sep-2026; ESOP drift is immaterial.
A8: Market capitalisation (₹ cr) | B8: =B6*B7 -> 525593.8
A9: 52-week range (₹) | B9: 4,440 / 3,288 | D9: 13.3% below the 52-week high
A10: TTM EPS (₹) | B10: 120.59
A11: Trailing P/E, computed (x) | B11: =B6/B10 -> 31.677585 | D11: Screener prints 30.2x on a marginally different base
A12: Book value per share (₹) | B12: 794
A13: Price / book (x) | B13: =B6/B12 -> 4.8110831 | D13: against ROE of 15.9%
A14: TTM revenue (₹ cr) | B14: 290137
A15: TTM operating profit (₹ cr) | B15: 36272
A16: TTM operating margin (%) | B16: =B15/B14 -> 0.1250168 | D16: 17.3% in FY2021 — see the margin path below
A17: Return on capital employed (%) | B17: 14.6
A18: Return on equity (%) | B18: 15.9
A19: Dividend yield (%) | B19: 1 | D19: payout 33.1%
A20: India 10-yr G-sec (%, 11-Sep-2026) | B20: 7.02 | D20: three-month high; up from 6.95% on 3-Sep
A21: Promoter holding | B21: NONE — professionally managed | D21: FII 19.1%, DII 43.0%, public 37.6% (Jun-2026)
A23: ENTITY CHECK — corporate actions live at the valuation date
A24: Hyderabad Metro exit | B24: ₹1,461.47 cr, entire stake to Hyderabad Metro Rail Ltd (Telangana govt). Completion deadline 30-Sep-2026 — three days after publication, already extended once from FY26-end (revised 01-Jul-2026). Completion also deconsolidates about ₹13,000 cr of project debt from the balance sheet, which is materially larger than the cash consideration.
A25: Realty demerger | B25: Realty Undertaking to L&T Realty Properties Ltd, slump sale ₹6,296.63 cr, appointed date 01-Apr-2026. Shareholders approved on 04-Aug-2026 with 99.07% of votes cast in favour; NCLT second-motion hearing 06-Oct-2026.
A26: Acquisition | B26: International Green Scapes (Gurugram real estate), ₹1,123 cr, completed 13-Apr-2026.
A27: Order win | B27: Three Middle East BESS projects totalling 6 GWh, 25-Aug-2026.
A28: Credit | B28: CRISIL reaffirmed AAA (04-Sep); India Ratings IND AAA Stable (01-Sep).
A29: Realty slump-sale consideration (₹ cr) | B29: 6296.63 | C29: L&T Realty Properties Ltd, appointed date 01-Apr-2026
A30: No transformational M&A, demerger out of the group, or capital raise. The realty move is internal and the Metro exit removes a chronic loss-maker for cash. Unlike the Sun Pharma case that prompted this check, the entity being valued here is the entity that will exist.
A31: Metro project debt deconsolidated on completion (₹ cr) | B31: 13000 | D31: L&T disclosed Hyderabad Metro debt of ~₹130bn taken over by the buyer (Q2FY26 call). A bull point we carry explicitly.
A32: Q1 FY2027 — WHERE THE PROFIT GROWTH CAME FROM
A33: (₹ cr) | B33: Q1 FY2027 | C33: Q1 FY2026 | D33: change
A34: Revenue | B34: 67942 | C34: 63679 | D34: =B34/C34-1 -> 0.066945147
A35: Operating profit | B35: 8149 | C35: 8024 | D35: =B35/C35-1 -> 0.015578265
A36: Operating margin | B36: =B35/B34 -> 0.11994054 | C36: =C35/C34 -> 0.126007 | D36: =B36-C36 -> -0.0060664664
A37: Other income | B37: 2377 | C37: 1357 | D37: =B37/C37-1 -> 0.75165807
A38: Interest | B38: 2571 | C38: 2488 | D38: =B38/C38-1 -> 0.033360129
A39: Profit before tax | B39: 6922 | C39: 5860 | D39: =B39/C39-1 -> 0.18122867
A40: Net profit (incl. minority) | B40: 4988 | C40: 4318 | D40: =B40/C40-1 -> 0.15516443
A41: Revenue increase, Q1 FY2027 (₹ cr) | B41: =B34-C34 -> 4263 | D41: the ₹4,263 cr of extra revenue that produced ₹125 cr of extra operating profit
A42: Other income as % of PBT | B42: =B37/B39 -> 0.34339786 | C42: =C37/C39 -> 0.23156997
A43: Other income share of the PBT increase | B43: =(B37-C37)/(B39-C39) -> 0.96045198
...

Sheet The Parts
A1: What the market is actually paying for the unlisted core
A2: L&T's headline P/E blends three listed companies you can buy directly with an unlisted engineering business you cannot. Strip the listed stakes out at their own market prices and the residual is what the market pays for the core. Every market value below is taken at the SAME verified close — 16 September 2026, Screener session stamp 16 Sep 4:01 p.m. — because a sum-of-the-parts built from prices struck on different days is not a sum-of-the-parts.
A4: LISTED SUBSIDIARIES — market values and reported TTM earnings (Screener, 15-Sep-2026)
A5: Company | B5: Market cap (₹ cr) | C5: L&T stake | D5: Stake value (₹ cr) | E5: TTM revenue (₹ cr) | F5: TTM operating profit | G5: TTM net profit | H5: L&T share of profit
A6: LTM Ltd (formerly LTIMindtree) | B6: 125767 | C6: 0.6866 | D6: =B6*C6 -> 86351.622 | E6: 44075 | F6: 7966 | G6: 5197 | H6: =G6*C6 -> 3568.2602
A7: L&T Technology Services | B7: 35476 | C7: 0.7352 | D7: =B7*C7 -> 26081.955 | E7: 11565 | F7: 2059 | G7: 1322 | H7: =G7*C7 -> 971.9344
A8: L&T Finance | B8: 74628 | C8: 0.6596 | D8: =B8*C8 -> 49224.629 | E8: 18898 | F8: 4518 | G8: 3198 | H8: =G8*C8 -> 2109.4008
A9: TOTAL LISTED | D9: =SUM(D6:D8) -> 161658.21 | E9: =SUM(E6:E8) -> 74538 | F9: =SUM(F6:F8) -> 14543 | G9: =SUM(G6:G8) -> 9717 | H9: =SUM(H6:H8) -> 6649.5954
A11: THE RECONCILIATION
A12: L&T consolidated TTM revenue (₹ cr) | B12: 290137
A13: less listed subsidiaries | B13: =-E9 -> -74538
A14: = CORE revenue | B14: =B12+B13 -> 215599 | D14: engineering, construction, defence, hydrocarbon, realty, development projects
A15: L&T consolidated TTM operating profit (₹ cr) | B15: 36272
A16: less listed subsidiaries | B16: =-F9 -> -14543
A17: = CORE operating profit | B17: =B15+B16 -> 21729
A18: CORE operating margin | B18: =B17/B14 -> 0.10078433 | D18: against 12.5% consolidated — the core is the thinner business
A19: L&T consolidated TTM attributable profit (₹ cr) | B19: =Overview!B10*Overview!B7 -> 16591.978 | D19: EPS ₹120.59 x shares
A20: less L&T's share of listed subsidiary profit | B20: =-H9 -> -6649.5954
A21: = CORE attributable profit | B21: =B19+B20 -> 9942.3827
A23: WHAT THAT IMPLIES
A24: L&T market capitalisation (₹ cr) | B24: =Overview!B8 -> 525593.8
A25: less listed stakes at market | B25: =-D9 -> -161658.21
A26: = market value of the CORE | B26: =B24+B25 -> 363935.59
A27: CORE implied trailing P/E (x) | B27: =B26/B21 -> 36.604464 | D27: this is the number the note is about
A28: memo: headline consolidated P/E (x) | B28: =Overview!B11 -> 31.677585
A29: Core as share of market capitalisation | B29: =B26/B24 -> 0.69242749
A30: Core as share of attributable profit | B30: =B21/B19 -> 0.59922829
A32: The core is 69% of the market capitalisation and 60% of the profit, and it trades on 36.6 times trailing earnings — roughly five turns above the headline multiple — while running a 10.1% operating margin against the group’s 12.5%. That is the whole argument. A reader who thinks 36.6 times is the right price for Indian engineering and construction should own the shares; this note argues it is not.
A34: ON A FORWARD BASIS — the comparison the note actually makes
A35: Core market value ÷ FY2028E core attributable (x) | B35: =B26/Forecast!C11 -> 29.180855 | D35: THIS is the number to set against our 25x. The trailing 36.6x above is not comparable to a forward target multiple.
A36: memo: consolidated, FY2028E basis (x) | B36: =Overview!B6/Forecast!C15 -> 25.434389
A37: memo: listed subsidiaries at market ÷ their FY2028E attributable (x) | B37: =D9/Forecast!C12 -> 19.73134
A38: Core multiple if the stakes are marked after our 20% holdco discount (x) | B38: =(B24-D9*(1-Valuation!B14))/Forecast!C11 -> 31.77325 | D38: higher, because haircutting the stakes leaves more of the market capitalisation attributable to the core
A40: A caution on the residual: it is arithmetic, not a market quote. Marking the stakes at full value the core is 29.2x FY2028E; haircut them 20% and the same core is 31.8x. We quote the 29.2x — the more conservative of the two for our argument — whenever we compare the market against our 25x, because the market does not apply our discount.

Sheet Forecast
A1: Forecast — grown off reported profit, not a reconstructed P&L
A2: An earlier build of this model constructed a full core income statement and produced a core profit roughly 40% above what L&T actually reports, because a core P&L cannot be reconciled from consolidated disclosure without allocating corporate costs, minorities and the loss-making development projects. It was discarded. The core and the subsidiaries are instead grown off their REPORTED trailing attributable profit, which ties out exactly.
A4: ASSUMPTIONS
A5: Core attributable profit growth | B5: 0.12 | C5: 0.12 | D5: 0.11 | E5: 0.1 | F5: 0.1 | H5: core: revenue ~9% with the margin roughly flat; below management's 10-12% revenue guidance, above the 6.7% delivered in Q1
A6: Subsidiary attributable profit growth | B6: 0.11 | C6: 0.11 | D6: 0.105 | E6: 0.1 | F6: 0.095 | H6: subsidiaries: IT services high single to low double digit, L&T Finance mid-teens
A8: EARNINGS BUILD (₹ cr)
B9: FY2027E | C9: FY2028E | D9: FY2029E | E9: FY2030E | F9: FY2031E
A10: CORE attributable — reported TTM base | B10: ='The Parts'!B21 -> 9942.3827
A11: Core attributable | B11: ='The Parts'!$B$21*(1+B5) -> 11135.469 | C11: =B11*(1+C5) -> 12471.725 | D11: =C11*(1+D5) -> 13843.615 | E11: =D11*(1+E5) -> 15227.976 | F11: =E11*(1+F5) -> 16750.774
A12: Subsidiary attributable | B12: ='The Parts'!$H$9*(1+B6) -> 7381.0509 | C12: =B12*(1+C6) -> 8192.9665 | D12: =C12*(1+D6) -> 9053.228 | E12: =D12*(1+E6) -> 9958.5508 | F12: =E12*(1+F6) -> 10904.613
A13: CONSOLIDATED attributable | B13: =B11+B12 -> 18516.52 | C13: =C11+C12 -> 20664.691 | D13: =D11+D12 -> 22896.843 | E13: =E11+E12 -> 25186.527 | F13: =F11+F12 -> 27655.387
A14: Shares (cr) | B14: =Overview!$B$7 -> 137.59 | C14: =Overview!$B$7 -> 137.59 | D14: =Overview!$B$7 -> 137.59 | E14: =Overview!$B$7 -> 137.59 | F14: =Overview!$B$7 -> 137.59
A15: CONSOLIDATED EPS (₹) | B15: =B13/B14 -> 134.57751 | C15: =C13/C14 -> 150.19036 | D15: =D13/D14 -> 166.41357 | E15: =E13/E14 -> 183.05492 | F15: =F13/F14 -> 200.99852
A16: Core EPS (₹) | B16: =B11/B14 -> 80.932253 | C16: =C11/C14 -> 90.644123 | D16: =D11/D14 -> 100.61498 | E16: =E11/E14 -> 110.67647 | F16: =F11/F14 -> 121.74412
A18: SANITY CHECKS
A19: Core profit CAGR, TTM to FY2028E | B19: =(C11/'The Parts'!B21)^0.5-1 -> 0.12 | D19: the core is where the operating leverage is, and where the margin pressure is
A20: Consolidated EPS CAGR, TTM to FY2028E | B20: =(C15/Overview!B10)^0.5-1 -> 0.11600304 | D20: against management's 10-12% revenue guidance — earnings grow faster than revenue only if the margin stops falling
A21: Implied consolidated revenue growth needed | B21: ~9%
A23: The honest weakness in this forecast is the margin. We assume the operating margin stops falling and stabilises around 10.2-10.5% at the core. It has fallen in six of the last eight years. If it keeps compressing at the recent pace, the bear case below is the right case.

Sheet Valuation
A1: Valuation — three methods, sum-of-the-parts led. All three state value in TODAY’S money.
A3: COST OF EQUITY AND HURDLES
A4: Risk-free — India 10-yr G-sec, 11-Sep-2026 | B4: 0.0702 | D4: three-month high; 6.95% on 3-Sep
A5: Beta | B5: 1.1 | D5: a cyclical EPC conglomerate; we do not use a defensive beta for a business whose margin swings with the order mix
A6: Equity risk premium | B6: 0.065 | D6: bottom of Incwert's published 6.5-7.5% band; Damodaran India total 7.31%
A7: COST OF EQUITY | B7: =B4+B5*B6 -> 0.1417
A8: ACCUMULATE hurdle (G-sec + 2pp) | B8: =B4+0.02 -> 0.0902
A10: KEY INPUTS
A11: Live price (₹) | B11: =Overview!B6 -> 3820
A12: Shares (cr) | B12: =Overview!B7 -> 137.59
A13: Listed stakes at market (₹ cr) | B13: ='The Parts'!D9 -> 161658.21
A14: Holding-company discount | B14: 0.2 | D14: Indian holdcos trade at 20-50% discounts; L&T is an operating company with stakes, not a pure holdco, so we use the low end
A15: Core attributable FY2028E (₹ cr) | B15: =Forecast!C11 -> 12471.725
A16: Consolidated EPS FY2028E (₹) | B16: =Forecast!C15 -> 150.19036
A17: Hyderabad Metro proceeds (₹ cr) | B17: 1461.47
A18: Years to FY2028 year end (memo only) | B18: 1.539 | C18: 16-Sep-2026 to 31-Mar-2028 | D18: Methods 1 and 2 apply today’s fair multiple to FY2028E earnings and therefore do NOT discount — the same basis on which the market’s own 29.2x FY2028E core multiple is computed. Only Method 3, a present value, discounts. Earlier drafts claimed a 1.54-year discount that Method 1 never applied; the claim was wrong, not the method.
A19: Dividend yield | B19: =Overview!B19/100 -> 0.01
A21: METHOD 1 — SUM-OF-THE-PARTS (45% weight) — today’s multiple on FY2028E core, not discounted
A22: Listed stakes at market (₹ cr) | B22: =B13 -> 161658.21
A23: less holding-company discount | B23: =-B13*B14 -> -32331.641
A24: core target multiple (x) | B24: 25 | D24: the multiple Nuvama applies to the core; we adopt it rather than invent our own
A25: Core: FY2028E attributable × that multiple (today’s value) | B25: =B24*B15 -> 311793.12 | D25: 25x is what we would pay TODAY for FY2028E core earnings. The market pays 29.2x on the identical basis.
A26: Hyderabad Metro proceeds | B26: =B17 -> 1461.47
A27: TOTAL EQUITY VALUE (₹ cr) | B27: =B22+B23+B25+B26 -> 442581.16
A28: METHOD 1 — VALUE PER SHARE (₹) | B28: =B27/B12 -> 3216.6666
A31: METHOD 2 — P/E ON CONSOLIDATED FY2028E (30% weight) — consolidated lens; carries NO holdco discount
A32: Target multiple (x) | B32: 24 | D32: against the 25.4x FY2028E the market pays on consolidated earnings today, and 31.7x trailing
A33: Value per share, 24x applied today to FY2028E EPS (₹) | B33: =B32*B16 -> 3604.5686
A34: METHOD 2 — VALUE PER SHARE (₹) | B34: =B33 -> 3604.5686 | D34: Not discounted, for consistency with Method 1. And no holding-company discount: this method values the group as a single consolidated earnings stream, so a discount on stakes it never separates out would be an invention. The consequence is disclosed at row 99.
A36: METHOD 3 — CORE FCFE DISCOUNTED AT COST OF EQUITY, PLUS LISTED STAKES (25% weight)
A37: A consolidated enterprise DCF is not meaningful for a group containing a large NBFC: L&T Finance's borrowings are its funding, not corporate leverage, so subtracting them from an enterprise value while including their cash flows double-counts. We discount the CORE's equity cash flow at the cost of equity and add the listed stakes separately.
A38: FCFE conversion = 1 − g ÷ ROE (derived from terminal growth, not assumed) | B38: =1-B44/(Overview!B18/100) -> 0.55849057 | D38: A firm cannot pay out 78% of earnings and simultaneously grow at 10%: with ROE 15.9%, g = ROE × retention. Tying the two is the correction to an earlier draft in which they contradicted each other.
A39: Core FCFE (₹ cr) | B39: FY2027E | C39: FY2028E | D39: FY2029E | E39: FY2030E | F39: FY2031E
A40: Core FCFE | B40: =Forecast!B11*$B$38 -> 6219.0542 | C40: =Forecast!C11*$B$38 -> 6965.3407 | D40: =Forecast!D11*$B$38 -> 7731.5282 | E40: =Forecast!E11*$B$38 -> 8504.681 | F40: =Forecast!F11*$B$38 -> 9355.1491
A41: Years from 16-Sep-2026 | B41: 0.537 | C41: 1.54 | D41: 2.54 | E41: 3.54 | F41: 4.54
A42: PV of FCFE | B42: =B40/(1+$B$7)^B41 -> 5791.8715 | C42: =C40/(1+$B$7)^C41 -> 5679.5285 | D42: =D40/(1+$B$7)^D41 -> 5521.8329 | E42: =E40/(1+$B$7)^E41 -> 5320.1508 | F42: =F40/(1+$B$7)^F41 -> 5125.8351
A43: PV of explicit period | B43: =SUM(B42:F42) -> 27439.219
A44: Terminal growth, capped at the risk-free rate | B44: =B4 -> 0.0702 | D44: A perpetual growth rate above the risk-free rate implies the firm eventually exceeds the economy. Capping at the G-sec is the discipline.
A45: Terminal value — Gordon (₹ cr) | B45: =F40*(1+B44)/(B7-B44) -> 140026.3
A46: PV of terminal value | B46: =B45/(1+B7)^F41 -> 76722.639
...

Sheet Peers & Street
A1: Peers and the Street
A3: INDIAN CONSTRUCTION AND ENGINEERING PEERS (Screener, 15-Sep-2026 — one day before our valuation date) | H3: The peer screen is a 15-Sep pull and we have not restruck it, because a one-day move in six peers does not change a relative-value observation. The L&T row below therefore shows ₹3,850 / 30.99x as at 15-Sep; every figure used in the valuation is the verified 16-Sep close of ₹3,820 / 31.7x. The two are labelled separately rather than silently blended.
A4: Company | B4: CMP (₹) | C4: P/E (x) | D4: Market cap (₹ cr) | E4: Div yield (%) | F4: Qtr sales var (%) | G4: ROCE (%)
A5: Larsen & Toubro | B5: 3850 | C5: 30.99 | D5: 531833 | E5: 0.99 | F5: 6.69 | G5: 14.57
A6: Rail Vikas Nigam | B6: 207.5 | C6: 47.99 | D6: 43172 | E6: 0.82 | F6: 10.55 | G6: 10.8
A7: Kalpataru Projects | B7: 1394.3 | C7: 21.44 | D7: 23828 | E7: 0.79 | F7: 3.84 | G7: 18.28
A8: IRB Infrastructure | B8: 19.27 | C8: 23.66 | D8: 23274 | E8: 0.81 | F8: 1.82 | G8: 7.47
A9: NBCC (India) | B9: 86.03 | C9: 34 | D9: 23271 | E9: 1.16 | F9: -5.51 | G9: 29.32
A10: Cemindia Projects | B10: 1285 | C10: 36.73 | D10: 22097 | E10: 0.23 | F10: 5.61 | G10: 32.76
A11: Median, 117 listed construction cos. | B11: 144.95 | C11: 15.74 | D11: 739.79 | E11: 0 | F11: 10.59 | G11: 15.78
A12: The peer table is of limited use and we should say so. Kalpataru and IRB are pure EPC at 21-24x; Rail Vikas and NBCC are government-linked at 34-48x; the 117-company median is 15.7x. None of them owns a listed IT services business or an NBFC, so none of them is comparable to L&T at the consolidated level. The comparison that matters is not L&T against these companies — it is L&T’s CORE against these companies, and on that basis the core at 36.6x trailing is above every pure EPC name in the table.
A14: BROKER TARGETS — every one dated; undated figures are no longer carried
A15: House | B15: Target (₹) | C15: Rating | D15: Date | E15: Basis / source | F15: vs our price
A16: Nuvama Institutional Equities | B16: 4065 | C16: constructive | D16: 21-Aug-2026 | E16: sector note via Business Today; L&T "attractive for long-term growth" but NOT a preferred pick — Nuvama prefers Voltamp and BHEL | F16: =B16/Valuation!$B$11-1 -> 0.064136126
A17: Nuvama — previous target | B17: 4680 | C17: BUY | D17: 30-Oct-2025 | E17: Q2FY26 Result Update (primary PDF). SOTP: core EPC 25x Sept-27 EPS = ₹3,637/sh; IT&TS at 20% disc to CMP = ₹804; Financial services at 20% disc = ₹240 | F17: =B17/Valuation!$B$11-1 -> 0.22513089
A18: Nomura | B18: 3940 | C18: NEUTRAL (cut from Buy) | D18: 07-May-2026 | E18: downgraded from Buy; PT cut from ₹4,510 | F18: =B18/Valuation!$B$11-1 -> 0.031413613
A19: ICICI Securities | B19: 4300 | C19: ADD (cut from Buy) | D19: 06-May-2026 | E19: downgraded from Buy; PT cut from ₹5,000 (Mohit Kumar) | F19: =B19/Valuation!$B$11-1 -> 0.12565445
A20: Jefferies | B20: 4885 | C20: BUY | D20: 06-May-2026 | E20: raised on 06-May-2026; prior target is listed in the evidence block below | F20: =B20/Valuation!$B$11-1 -> 0.27879581
A21: BofA Securities | B21: 3700 | C21: UNDERPERFORM | D21: 29-Sep-2025 | E21: cut from Buy; "key positive catalysts now behind it". Dated — we cannot confirm it is still live | F21: =B21/Valuation!$B$11-1 -> -0.031413613
A23: What the dated record actually shows: the street has been CUTTING L&T through 2026, not defending it. Nuvama is ₹615 below its October target; Nomura downgraded to Neutral in May and ICICI Securities to Add, cutting ₹700. The two most cautious dated targets — BofA ₹3,700 and Nomura ₹3,940 — sit at or below today’s ₹3,820. Our ₹2,956 is well below all of them, so we are the outlier on MAGNITUDE. We are not the outlier on DIRECTION — and an earlier draft of this note implied we were, by quoting an eleven-month-old ₹4,680 as if it were current. That is the error this desk made once before on a stale vendor consensus. The rule stands: a target carries a date or it does not appear.
A25: WHERE WE DIFFER, AND WHY THE GAP IS NOT THE MULTIPLE
A26: Nuvama’s 30-Oct-2025 SOTP is public, so the disagreement decomposes exactly rather than by guesswork. MULTIPLE: they apply 25x to the core; so do we — zero gap. HOLDCO DISCOUNT: they apply 20% to the listed subsidiaries; so do we — zero gap, and our 20% is now sourced to the very house whose multiple we adopt rather than asserted. EARNINGS: they model FY28E core E&C PAT of ₹20,021 cr and consolidated EPS of ₹218.3; we model core attributable of ₹12,472 cr and consolidated EPS of ₹150.19 — they sit 45% above us. The entire gap is the earnings line. One caveat we state rather than bury: their "core E&C" and our residual core are not the same perimeter. Nuvama strips services and E&A to model the EPC business alone; our core is the residual after removing three listed stakes, so it still carries realty, development projects and the Hyderabad Metro losses. Applying the same 25x to two different bases is not the like-for-like comparison it appears to be.
A28: THE EVIDENCE THAT THE STREET OVER-FORECASTS THIS COMPANY
A29: Nuvama’s Oct-2025 note modelled FY26E revenue of ₹2,92,547 cr and FY26E EPS of ₹152.9, and expected core operating margins of 8.3–8.5% through FY27/28E on the view that they had "bottomed out at ~8.2%". L&T then delivered FY2026 revenue of ₹2,85,874 cr — short of the estimate and of management’s own 15% growth guidance, at roughly 11.8% — and guided FY27 core P&M margins FLAT at about 7.8%, not 8.3–8.5%. The margin recovery the ₹4,680 was built on did not arrive. That is why the target is now ₹4,065 and why two houses downgraded in May. This note is not forecasting a break from consensus; it is pricing a deterioration consensus has already started to concede.
A31: SOURCED EXTERNAL EVIDENCE — third-party figures used in the note, each dated so it can be audited
A32: Figure | B32: Value | C32: Date | D32: Source
A33: Nuvama SOTP: core EPC, 25x Sept-27 EPS (₹/share) | B33: 3637 | C33: 30-Oct-2025 | D33: Nuvama Q2FY26 Result Update, SotP summary
A34: Nuvama SOTP: IT & Tech Services at 20% disc to CMP (₹/share) | B34: 804 | C34: 30-Oct-2025 | D34: same
A35: Nuvama SOTP: Financial services at 20% disc to CMP (₹/share) | B35: 240 | C35: 30-Oct-2025 | D35: same — this is the source of our 20% holdco discount
A36: Nuvama FY26E revenue (₹ cr) | B36: 292547 | C36: 30-Oct-2025 | D36: vs L&T actual FY2026 ₹2,85,874 cr — a miss
A37: Nuvama FY26E diluted EPS (₹) | B37: 152.9 | C37: 30-Oct-2025 | D37: set before FY2026 actuals
A38: Nuvama FY28E core E&C adjusted PAT (₹ cr) | B38: 20021 | C38: 30-Oct-2025 | D38: vs our core attributable ₹12,472 cr — different perimeter, see A26
A39: Nuvama FY28E consolidated diluted EPS (₹) | B39: 218.3 | C39: 30-Oct-2025 | D39: vs our ₹150.19 — they sit 45% above us
A40: Nuvama view: core OPM had "bottomed out at" (%) | B40: 8.2 | C40: 30-Oct-2025 | D40: expected 8.3-8.5% through FY27/28E
A41: MANAGEMENT guidance: FY27 core P&M margin, flat (%) | B41: 7.8 | C41: Q4FY26 | D41: the recovery guided away — this is the thesis
A42: Group EBITDA margin, Q4FY26 (%) | B42: 10.4 | C42: Q4FY26 | D42: contracted 62bp YoY (PL Capital Q4FY26 result update)
A43: Consolidated operating margin, FY2019 (%) | B43: 16.9 | C43: FY2019 | D43: pre-COVID base: decline to FY2026 is 450bp, not a cherry-picked 490bp
A44: E&A business revenue divested to Schneider (₹ cr) | B44: 5038 | C44: FY2017 | D44: sale completed 31-Aug-2020; ~3.7% of FY2021 revenue — a step, not the slide
... A47: Shares outstanding | B47: 1375768535 | C47: 2026 | D47: companiesmarketcap — 137.58 cr, sourced not derived
A49: Every figure above is third-party and dated. None of it feeds the valuation — the model is built only from L&T’s reported numbers and our own assumptions. These sit here so a reader can check the evidence the narrative rests on without taking our word for any of it.
